{
  "version": 8,
  "blockIdVersion": 10,
  "anchorX": 1,
  "anchorY": 8,
  "anchorZ": 0,
  "blocks": [
    {
      "x": -20,
      "y": 7,
      "z": 9,
      "name": "Deco_Salty_Bone_Full"
    },
    {
      "x": -20,
      "y": 8,
      "z": 9,
      "name": "Deco_Salty_Bone_Full"
    },
    {
      "x": -20,
      "y": 9,
      "z": 9,
      "name": "Deco_Salty_Bone_Full"
    },
    {
      "x": -20,
      "y": 10,
      "z": 9,
      "name": "Deco_Salty_Bone_Full"
    },
    {
      "x": -20,
      "y": 11,
      "z": 9,
      "name": "Deco_Salty_Bone_Full"
    },
    {
      "x": -20,
      "y": 12,
      "z": 9,
      "name": "Deco_Salty_Bone_Full"
    },
    {
      "x": -20,
      "y": 12,
      "z": 10,
      "name": "Deco_Salty_Bone_Full"
    },
    {
      "x": -20,
      "y": 13,
      "z": 10,
      "name": "Deco_Salty_Bone_Full"
    },
    {
      "x": -19,
      "y": 12,
      "z": 9,
      "name": "Deco_Salty_Bone_Full"
    },
    {
      "x": -19,
      "y": 13,
      "z": 9,
      "name": "Deco_Salty_Bone_Full"
    },
    {
      "x": -19,
      "y": 4,
      "z": 10,
      "name": "Deco_Salty_Bone_Full"
    },
    {
      "x": -19,
      "y": 5,
      "z": 10,
      "name": "Deco_Salty_Bone_Full"
    },
    {
      "x": -19,
      "y": 6,
      "z": 10,
      "name": "Deco_Salty_Bone_Full"
    },
    {
      "x": -19,
      "y": 7,
      "z": 10,
      "name": "Deco_Salty_Bone_Full"
    },
    {
      "x": -19,
      "y": 11,
      "z": 10,
      "name": "Deco_Salty_Bone_Full"
    },
    {
      "x": -19,
      "y": 12,
      "z": 10,
      "name": "Deco_Salty_Bone_Full"
    },
    {
      "x": -19,
      "y": 13,
      "z": 10,
      "name": "Deco_Salty_Bone_Full"
    },
    {
      "x": -19,
      "y": 14,
      "z": 10,
      "name": "Deco_Salty_Bone_Full"
    },
    {
      "x": -19,
      "y": 15,
      "z": 10,
      "name": "Deco_Salty_Bone_Full"
    },
    {
      "x": -19,
      "y": 13,
      "z": 11,
      "name": "Deco_Salty_Bone_Full"
    },
    {
      "x": -19,
      "y": 14,
      "z": 11,
      "name": "Deco_Salty_Bone_Full"
    },
    {
      "x": -18,
      "y": 13,
      "z": 10,
      "name": "Deco_Salty_Bone_Full"
    },
    {
      "x": -18,
      "y": 14,
      "z": 10,
      "name": "Deco_Salty_Bone_Full"
    },
    {
      "x": -18,
      "y": 3,
      "z": 11,
      "name": "Deco_Salty_Bone_Full"
    },
    {
      "x": -18,
      "y": 4,
      "z": 11,
      "name": "Deco_Salty_Bone_Full"
    },
    {
      "x": -18,
      "y": 14,
      "z": 11,
      "name": "Deco_Salty_Bone_Full"
    },
    {
      "x": -18,
      "y": 15,
      "z": 11,
      "name": "Deco_Salty_Bone_Full"
    },
    {
      "x": -18,
      "y": 16,
      "z": 11,
      "name": "Deco_Salty_Bone_Full"
    },
    {
      "x": -18,
      "y": 15,
      "z": 12,
      "name": "Deco_Salty_Bone_Full"
    },
    {
      "x": -18,
      "y": 16,
      "z": 18,
      "name": "Deco_Salty_Bone_Full"
    },
    {
      "x": -18,
      "y": 17,
      "z": 18,
      "name": "Deco_Salty_Bone_Full"
    },
    {
      "x": -18,
      "y": 16,
      "z": 19,
      "name": "Deco_Salty_Bone_Full"
    },
    {
      "x": -18,
      "y": 17,
      "z": 19,
      "name": "Deco_Salty_Bone_Full"
    },
    {
      "x": -17,
      "y": 15,
      "z": 11,
      "name": "Deco_Salty_Bone_Full"
    },
    {
      "x": -17,
      "y": 2,
      "z": 12,
      "name": "Deco_Salty_Bone_Full"
    },
    {
      "x": -17,
      "y": 3,
      "z": 12,
      "name": "Deco_Salty_Bone_Full"
    },
    {
      "x": -17,
      "y": 15,
      "z": 12,
      "name": "Deco_Salty_Bone_Full"
    },
    {
      "x": -17,
      "y": 16,
      "z": 12,
      "name": "Deco_Salty_Bone_Full"
    },
    {
      "x": -17,
      "y": 17,
      "z": 12,
      "name": "Deco_Salty_Bone_Full"
    },
    {
      "x": -17,
      "y": 16,
      "z": 13,
      "name": "Deco_Salty_Bone_Full"
    },
    {
      "x": -17,
      "y": 16,
      "z": 17,
      "name": "Deco_Salty_Bone_Full"
    },
    {
      "x": -17,
      "y": 17,
      "z": 17,
      "name": "Deco_Salty_Bone_Full"
    },
    {
      "x": -17,
      "y": 16,
      "z": 18,
      "name": "Deco_Salty_Bone_Full"
    },
    {
      "x": -17,
      "y": 17,
      "z": 18,
      "name": "Deco_Salty_Bone_Full"
    },
    {
      "x": -17,
      "y": 18,
      "z": 18,
      "name": "Deco_Salty_Bone_Spike"
    },
    {
      "x": -17,
      "y": 16,
      "z": 19,
      "name": "Deco_Salty_Bone_Full"
    },
    {
      "x": -17,
      "y": 17,
      "z": 19,
      "name": "Deco_Salty_Bone_Full"
    },
    {
      "x": -16,
      "y": 16,
      "z": 12,
      "name": "Deco_Salty_Bone_Full"
    },
    {
      "x": -16,
      "y": 16,
      "z": 13,
      "name": "Deco_Salty_Bone_Full"
    },
    {
      "x": -16,
      "y": 17,
      "z": 13,
      "name": "Deco_Salty_Bone_Full"
    },
    {
      "x": -16,
      "y": 17,
      "z": 14,
      "name": "Deco_Salty_Bone_Full"
    },
    {
      "x": -16,
      "y": 18,
      "z": 15,
      "name": "Deco_Salty_Bone_Full"
    },
    {
      "x": -16,
      "y": 18,
      "z": 16,
      "name": "Deco_Salty_Bone_Full"
    },
    {
      "x": -16,
      "y": 18,
      "z": 17,
      "name": "Deco_Salty_Bone_Full"
    },
    {
      "x": -16,
      "y": 16,
      "z": 18,
      "name": "Deco_Salty_Bone_Full"
    },
    {
      "x": -16,
      "y": 17,
      "z": 18,
      "name": "Deco_Salty_Bone_Full"
    },
    {
      "x": -15,
      "y": 6,
      "z": 4,
      "name": "Deco_Salty_Bone_Full"
    },
    {
      "x": -15,
      "y": 7,
      "z": 4,
      "name": "Deco_Salty_Bone_Full"
    },
    {
      "x": -15,
      "y": 8,
      "z": 4,
      "name": "Deco_Salty_Bone_Full"
    },
    {
      "x": -15,
      "y": 9,
      "z": 4,
      "name": "Deco_Salty_Bone_Full"
    },
    {
      "x": -15,
      "y": 10,
      "z": 4,
      "name": "Deco_Salty_Bone_Full"
    },
    {
      "x": -15,
      "y": 11,
      "z": 4,
      "name": "Deco_Salty_Bone_Full"
    },
    {
      "x": -15,
      "y": 12,
      "z": 4,
      "name": "Deco_Salty_Bone_Full"
    },
    {
      "x": -15,
      "y": 13,
      "z": 4,
      "name": "Deco_Salty_Bone_Full"
    },
    {
      "x": -15,
      "y": 13,
      "z": 5,
      "name": "Deco_Salty_Bone_Full"
    },
    {
      "x": -15,
      "y": 14,
      "z": 5,
      "name": "Deco_Salty_Bone_Full"
    },
    {
      "x": -15,
      "y": 17,
      "z": 13,
      "name": "Deco_Salty_Bone_Full"
    },
    {
      "x": -15,
      "y": 18,
      "z": 13,
      "name": "Deco_Salty_Bone_Full"
    },
    {
      "x": -15,
      "y": 17,
      "z": 14,
      "name": "Deco_Salty_Bone_Full"
    },
    {
      "x": -15,
      "y": 18,
      "z": 14,
      "name": "Deco_Salty_Bone_Full"
    },
    {
      "x": -15,
      "y": 17,
      "z": 15,
      "name": "Deco_Salty_Bone_Full"
    },
    {
      "x": -15,
      "y": 18,
      "z": 15,
      "name": "Deco_Salty_Bone_Full"
    },
    {
      "x": -15,
      "y": 19,
      "z": 15,
      "name": "Deco_Salty_Bone_Full"
    },
    {
      "x": -15,
      "y": 17,
      "z": 16,
      "name": "Deco_Salty_Bone_Full"
    },
    {
      "x": -15,
      "y": 18,
      "z": 16,
      "name": "Deco_Salty_Bone_Full"
    },
    {
      "x": -15,
      "y": 19,
      "z": 16,
      "name": "Deco_Salty_Bone_Full"
    },
    {
      "x": -15,
      "y": 20,
      "z": 16,
      "name": "Deco_Salty_Bone_Full"
    },
    {
      "x": -15,
      "y": 18,
      "z": 17,
      "name": "Deco_Salty_Bone_Full"
    },
    {
      "x": -14,
      "y": 13,
      "z": 4,
      "name": "Deco_Salty_Bone_Full"
    },
    {
      "x": -14,
      "y": 14,
      "z": 4,
      "name": "Deco_Salty_Bone_Full"
    },
    {
      "x": -14,
      "y": 3,
      "z": 5,
      "name": "Deco_Salty_Bone_Full"
    },
    {
      "x": -14,
      "y": 4,
      "z": 5,
      "name": "Deco_Salty_Bone_Full"
    },
    {
      "x": -14,
      "y": 5,
      "z": 5,
      "name": "Deco_Salty_Bone_Full"
    },
    {
      "x": -14,
      "y": 6,
      "z": 5,
      "name": "Deco_Salty_Bone_Full"
    },
    {
      "x": -14,
      "y": 12,
      "z": 5,
      "name": "Deco_Salty_Bone_Full"
    },
    {
      "x": -14,
      "y": 13,
      "z": 5,
      "name": "Deco_Salty_Bone_Full"
    },
    {
      "x": -14,
      "y": 14,
      "z": 5,
      "name": "Deco_Salty_Bone_Full"
    },
    {
      "x": -14,
      "y": 15,
      "z": 5,
      "name": "Deco_Salty_Bone_Full"
    },
    {
      "x": -14,
      "y": 16,
      "z": 5,
      "name": "Deco_Salty_Bone_Full"
    },
    {
      "x": -14,
      "y": 14,
      "z": 6,
      "name": "Deco_Salty_Bone_Full"
    },
    {
      "x": -14,
      "y": 15,
      "z": 6,
      "name": "Deco_Salty_Bone_Full"
    },
    {
      "x": -14,
      "y": 18,
      "z": 13,
      "name": "Deco_Salty_Bone_Full"
    },
    {
      "x": -14,
      "y": 17,
      "z": 14,
      "name": "Deco_Salty_Bone_Full"
    },
    {
      "x": -14,
      "y": 18,
      "z": 14,
      "name": "Deco_Salty_Bone_Full"
    },
    {
      "x": -14,
      "y": 19,
      "z": 14,
      "name": "Deco_Salty_Bone_Full"
    },
    {
      "x": -14,
      "y": 20,
      "z": 14,
      "name": "Deco_Salty_Bone_Full"
    },
    {
      "x": -14,
      "y": 17,
      "z": 15,
      "name": "Deco_Salty_Bone_Full"
    },
    {
      "x": -14,
      "y": 18,
      "z": 15,
      "name": "Deco_Salty_Bone_Full"
    },
    {
      "x": -14,
      "y": 19,
      "z": 15,
      "name": "Deco_Salty_Bone_Full"
    },
    {
      "x": -14,
      "y": 20,
      "z": 15,
      "name": "Deco_Salty_Bone_Full"
    },
    {
      "x": -14,
      "y": 21,
      "z": 15,
      "name": "Deco_Salty_Bone_Full"
    },
    {
      "x": -14,
      "y": 17,
      "z": 16,
      "name": "Deco_Salty_Bone_Full"
    },
    {
      "x": -14,
      "y": 18,
      "z": 16,
      "name": "Deco_Salty_Bone_Full"
    },
    {
      "x": -14,
      "y": 19,
      "z": 16,
      "name": "Deco_Salty_Bone_Full"
    },
    {
      "x": -14,
      "y": 18,
      "z": 17,
      "name": "Deco_Salty_Bone_Full"
    },
    {
      "x": -13,
      "y": 14,
      "z": 5,
      "name": "Deco_Salty_Bone_Full"
    },
    {
      "x": -13,
      "y": 15,
      "z": 5,
      "name": "Deco_Salty_Bone_Full"
    },
    {
      "x": -13,
      "y": 1,
      "z": 6,
      "name": "Deco_Salty_Bone_Full"
    },
    {
      "x": -13,
      "y": 2,
      "z": 6,
      "name": "Deco_Salty_Bone_Full"
    },
    {
      "x": -13,
      "y": 3,
      "z": 6,
      "name": "Deco_Salty_Bone_Full"
    },
    {
      "x": -13,
      "y": 15,
      "z": 6,
      "name": "Deco_Salty_Bone_Full"
    },
    {
      "x": -13,
      "y": 16,
      "z": 6,
      "name": "Deco_Salty_Bone_Full"
    },
    {
      "x": -13,
      "y": 17,
      "z": 6,
      "name": "Deco_Salty_Bone_Full"
    },
    {
      "x": -13,
      "y": 16,
      "z": 7,
      "name": "Deco_Salty_Bone_Full"
    },
    {
      "x": -13,
      "y": 18,
      "z": 13,
      "name": "Deco_Salty_Bone_Full"
    },
    {
      "x": -13,
      "y": 19,
      "z": 13,
      "name": "Deco_Salty_Bone_Full"
    },
    {
      "x": -13,
      "y": 17,
      "z": 14,
      "name": "Deco_Salty_Bone_Full"
    },
    {
      "x": -13,
      "y": 18,
      "z": 14,
      "name": "Deco_Salty_Bone_Full"
    },
    {
      "x": -13,
      "y": 19,
      "z": 14,
      "name": "Deco_Salty_Bone_Full"
    },
    {
      "x": -13,
      "y": 20,
      "z": 14,
      "name": "Deco_Salty_Bone_Full"
    },
    {
      "x": -13,
      "y": 21,
      "z": 14,
      "name": "Deco_Salty_Bone_Full"
    },
    {
      "x": -13,
      "y": 22,
      "z": 14,
      "name": "Deco_Salty_Bone_Spike"
    },
    {
      "x": -13,
      "y": 17,
      "z": 15,
      "name": "Deco_Salty_Bone_Full"
    },
    {
      "x": -13,
      "y": 18,
      "z": 15,
      "name": "Deco_Salty_Bone_Full"
    },
    {
      "x": -13,
      "y": 19,
      "z": 15,
      "name": "Deco_Salty_Bone_Full"
    },
    {
      "x": -13,
      "y": 20,
      "z": 15,
      "name": "Deco_Salty_Bone_Full"
    },
    {
      "x": -13,
      "y": 17,
      "z": 16,
      "name": "Deco_Salty_Bone_Full"
    },
    {
      "x": -13,
      "y": 18,
      "z": 16,
      "name": "Deco_Salty_Bone_Full"
    },
    {
      "x": -13,
      "y": 17,
      "z": 17,
      "name": "Deco_Salty_Bone_Full"
    },
    {
      "x": -12,
      "y": 16,
      "z": 6,
      "name": "Deco_Salty_Bone_Full"
    },
    {
      "x": -12,
      "y": 0,
      "z": 7,
      "name": "Deco_Salty_Bone_Full"
    },
    {
      "x": -12,
      "y": 1,
      "z": 7,
      "name": "Deco_Salty_Bone_Full"
    },
    {
      "x": -12,
      "y": 16,
      "z": 7,
      "name": "Deco_Salty_Bone_Full"
    },
    {
      "x": -12,
      "y": 17,
      "z": 7,
      "name": "Deco_Salty_Bone_Full"
    },
    {
      "x": -12,
      "y": 18,
      "z": 7,
      "name": "Deco_Salty_Bone_Full"
    },
    {
      "x": -12,
      "y": 17,
      "z": 8,
      "name": "Deco_Salty_Bone_Full"
    },
    {
      "x": -12,
      "y": 17,
      "z": 12,
      "name": "Deco_Salty_Bone_Full"
    },
    {
      "x": -12,
      "y": 18,
      "z": 12,
      "name": "Deco_Salty_Bone_Full"
    },
    {
      "x": -12,
      "y": 17,
      "z": 13,
      "name": "Deco_Salty_Bone_Full"
    },
    {
      "x": -12,
      "y": 18,
      "z": 13,
      "name": "Deco_Salty_Bone_Full"
    },
    {
      "x": -12,
      "y": 18,
      "z": 14,
      "name": "Deco_Salty_Bone_Full"
    },
    {
      "x": -12,
      "y": 19,
      "z": 14,
      "name": "Deco_Salty_Bone_Full"
    },
    {
      "x": -12,
      "y": 18,
      "z": 15,
      "name": "Deco_Salty_Bone_Full"
    },
    {
      "x": -12,
      "y": 17,
      "z": 16,
      "name": "Deco_Salty_Bone_Full"
    },
    {
      "x": -12,
      "y": 18,
      "z": 16,
      "name": "Deco_Salty_Bone_Full"
    },
    {
      "x": -12,
      "y": 16,
      "z": 17,
      "name": "Deco_Salty_Bone_Full"
    },
    {
      "x": -12,
      "y": 17,
      "z": 17,
      "name": "Deco_Salty_Bone_Full"
    },
    {
      "x": -12,
      "y": 16,
      "z": 18,
      "name": "Deco_Salty_Bone_Full"
    },
    {
      "x": -11,
      "y": 17,
      "z": 7,
      "name": "Deco_Salty_Bone_Full"
    },
    {
      "x": -11,
      "y": 17,
      "z": 8,
      "name": "Deco_Salty_Bone_Full"
    },
    {
      "x": -11,
      "y": 18,
      "z": 8,
      "name": "Deco_Salty_Bone_Full"
    },
    {
      "x": -11,
      "y": 18,
      "z": 9,
      "name": "Deco_Salty_Bone_Full"
    },
    {
      "x": -11,
      "y": 19,
      "z": 10,
      "name": "Deco_Salty_Bone_Full"
    },
    {
      "x": -11,
      "y": 19,
      "z": 11,
      "name": "Deco_Salty_Bone_Full"
    },
    {
      "x": -11,
      "y": 19,
      "z": 12,
      "name": "Deco_Salty_Bone_Full"
    },
    {
      "x": -11,
      "y": 17,
      "z": 13,
      "name": "Deco_Salty_Bone_Full"
    },
    {
      "x": -11,
      "y": 18,
      "z": 13,
      "name": "Deco_Salty_Bone_Full"
    },
    {
      "x": -11,
      "y": 16,
      "z": 17,
      "name": "Deco_Salty_Bone_Full"
    },
    {
      "x": -11,
      "y": 2,
      "z": 18,
      "name": "Deco_Salty_Bone_Full"
    },
    {
      "x": -11,
      "y": 3,
      "z": 18,
      "name": "Deco_Salty_Bone_Full"
    },
    {
      "x": -11,
      "y": 15,
      "z": 18,
      "name": "Deco_Salty_Bone_Full"
    },
    {
      "x": -11,
      "y": 16,
      "z": 18,
      "name": "Deco_Salty_Bone_Full"
    },
    {
      "x": -11,
      "y": 17,
      "z": 18,
      "name": "Deco_Salty_Bone_Full"
    },
    {
      "x": -11,
      "y": 15,
      "z": 19,
      "name": "Deco_Salty_Bone_Full"
    },
    {
      "x": -10,
      "y": 6,
      "z": -1,
      "name": "Deco_Salty_Bone_Full"
    },
    {
      "x": -10,
      "y": 7,
      "z": -1,
      "name": "Deco_Salty_Bone_Full"
    },
    {
      "x": -10,
      "y": 8,
      "z": -1,
      "name": "Deco_Salty_Bone_Full"
    },
    {
      "x": -10,
      "y": 9,
      "z": -1,
      "name": "Deco_Salty_Bone_Full"
    },
    {
      "x": -10,
      "y": 10,
      "z": -1,
      "name": "Deco_Salty_Bone_Full"
    },
    {
      "x": -10,
      "y": 11,
      "z": -1,
      "name": "Deco_Salty_Bone_Full"
    },
    {
      "x": -10,
      "y": 12,
      "z": -1,
      "name": "Deco_Salty_Bone_Full"
    },
    {
      "x": -10,
      "y": 13,
      "z": -1,
      "name": "Deco_Salty_Bone_Full"
    },
    {
      "x": -10,
      "y": 13,
      "z": 0,
      "name": "Deco_Salty_Bone_Full"
    },
    {
      "x": -10,
      "y": 14,
      "z": 0,
      "name": "Deco_Salty_Bone_Full"
    },
    {
      "x": -10,
      "y": 18,
      "z": 8,
      "name": "Deco_Salty_Bone_Full"
    },
    {
      "x": -10,
      "y": 19,
      "z": 8,
      "name": "Deco_Salty_Bone_Full"
    },
    {
      "x": -10,
      "y": 18,
      "z": 9,
      "name": "Deco_Salty_Bone_Full"
    },
    {
      "x": -10,
      "y": 19,
      "z": 9,
      "name": "Deco_Salty_Bone_Full"
    },
    {
      "x": -10,
      "y": 18,
      "z": 10,
      "name": "Deco_Salty_Bone_Full"
    },
    {
      "x": -10,
      "y": 19,
      "z": 10,
      "name": "Deco_Salty_Bone_Full"
    },
    {
      "x": -10,
      "y": 20,
      "z": 10,
      "name": "Deco_Salty_Bone_Full"
    },
    {
      "x": -10,
      "y": 18,
      "z": 11,
      "name": "Deco_Salty_Bone_Full"
    },
    {
      "x": -10,
      "y": 19,
      "z": 11,
      "name": "Deco_Salty_Bone_Full"
    },
    {
      "x": -10,
      "y": 20,
      "z": 11,
      "name": "Deco_Salty_Bone_Full"
    },
    {
      "x": -10,
      "y": 21,
      "z": 11,
      "name": "Deco_Salty_Bone_Full"
    },
    {
      "x": -10,
      "y": 19,
      "z": 12,
      "name": "Deco_Salty_Bone_Full"
    },
    {
      "x": -10,
      "y": 15,
      "z": 18,
      "name": "Deco_Salty_Bone_Full"
    },
    {
      "x": -10,
      "y": 3,
      "z": 19,
      "name": "Deco_Salty_Bone_Full"
    },
    {
      "x": -10,
      "y": 4,
      "z": 19,
      "name": "Deco_Salty_Bone_Full"
    },
    {
      "x": -10,
      "y": 14,
      "z": 19,
      "name": "Deco_Salty_Bone_Full"
    },
    {
      "x": -10,
      "y": 15,
      "z": 19,
      "name": "Deco_Salty_Bone_Full"
    },
    {
      "x": -10,
      "y": 16,
      "z": 19,
      "name": "Deco_Salty_Bone_Full"
    },
    {
      "x": -10,
      "y": 13,
      "z": 20,
      "name": "Deco_Salty_Bone_Full"
    },
    {
      "x": -10,
      "y": 14,
      "z": 20,
      "name": "Deco_Salty_Bone_Full"
    },
    {
      "x": -9,
      "y": 13,
      "z": -1,
      "name": "Deco_Salty_Bone_Full"
    },
    {
      "x": -9,
      "y": 14,
      "z": -1,
      "name": "Deco_Salty_Bone_Full"
    },
    {
      "x": -9,
      "y": 3,
      "z": 0,
      "name": "Deco_Salty_Bone_Full"
    },
    {
      "x": -9,
      "y": 4,
      "z": 0,
      "name": "Deco_Salty_Bone_Full"
    },
    {
      "x": -9,
      "y": 5,
      "z": 0,
      "name": "Deco_Salty_Bone_Full"
    },
    {
      "x": -9,
      "y": 6,
      "z": 0,
      "name": "Deco_Salty_Bone_Full"
    },
    {
      "x": -9,
      "y": 12,
      "z": 0,
      "name": "Deco_Salty_Bone_Full"
    },
    {
      "x": -9,
      "y": 13,
      "z": 0,
      "name": "Deco_Salty_Bone_Full"
    },
    {
      "x": -9,
      "y": 14,
      "z": 0,
      "name": "Deco_Salty_Bone_Full"
    },
    {
      "x": -9,
      "y": 15,
      "z": 0,
      "name": "Deco_Salty_Bone_Full"
    },
    {
      "x": -9,
      "y": 16,
      "z": 0,
      "name": "Deco_Salty_Bone_Full"
    },
    {
      "x": -9,
      "y": 14,
      "z": 1,
      "name": "Deco_Salty_Bone_Full"
    },
    {
      "x": -9,
      "y": 15,
      "z": 1,
      "name": "Deco_Salty_Bone_Full"
    },
    {
      "x": -9,
      "y": 19,
      "z": 8,
      "name": "Deco_Salty_Bone_Full"
    },
    {
      "x": -9,
      "y": 18,
      "z": 9,
      "name": "Deco_Salty_Bone_Full"
    },
    {
      "x": -9,
      "y": 19,
      "z": 9,
      "name": "Deco_Salty_Bone_Full"
    },
    {
      "x": -9,
      "y": 20,
      "z": 9,
      "name": "Deco_Salty_Bone_Full"
    },
    {
      "x": -9,
      "y": 21,
      "z": 9,
      "name": "Deco_Salty_Bone_Full"
    },
    {
      "x": -9,
      "y": 18,
      "z": 10,
      "name": "Deco_Salty_Bone_Full"
    },
    {
      "x": -9,
      "y": 19,
      "z": 10,
      "name": "Deco_Salty_Bone_Full"
    },
    {
      "x": -9,
      "y": 20,
      "z": 10,
      "name": "Deco_Salty_Bone_Full"
    },
    {
      "x": -9,
      "y": 21,
      "z": 10,
      "name": "Deco_Salty_Bone_Full"
    },
    {
      "x": -9,
      "y": 22,
      "z": 10,
      "name": "Deco_Salty_Bone_Full"
    },
    {
      "x": -9,
      "y": 18,
      "z": 11,
      "name": "Deco_Salty_Bone_Full"
    },
    {
      "x": -9,
      "y": 19,
      "z": 11,
      "name": "Deco_Salty_Bone_Full"
    },
    {
      "x": -9,
      "y": 20,
      "z": 11,
      "name": "Deco_Salty_Bone_Full"
    },
    {
      "x": -9,
      "y": 19,
      "z": 12,
      "name": "Deco_Salty_Bone_Full"
    },
    {
      "x": -9,
      "y": 13,
      "z": 19,
      "name": "Deco_Salty_Bone_Full"
    },
    {
      "x": -9,
      "y": 14,
      "z": 19,
      "name": "Deco_Salty_Bone_Full"
    },
    {
      "x": -9,
      "y": 4,
      "z": 20,
      "name": "Deco_Salty_Bone_Full"
    },
    {
      "x": -9,
      "y": 5,
      "z": 20,
      "name": "Deco_Salty_Bone_Full"
    },
    {
      "x": -9,
      "y": 6,
      "z": 20,
      "name": "Deco_Salty_Bone_Full"
    },
    {
      "x": -9,
      "y": 7,
      "z": 20,
      "name": "Deco_Salty_Bone_Full"
    },
    {
      "x": -9,
      "y": 11,
      "z": 20,
      "name": "Deco_Salty_Bone_Full"
    },
    {
      "x": -9,
      "y": 12,
      "z": 20,
      "name": "Deco_Salty_Bone_Full"
    },
    {
      "x": -9,
      "y": 13,
      "z": 20,
      "name": "Deco_Salty_Bone_Full"
    },
    {
      "x": -9,
      "y": 14,
      "z": 20,
      "name": "Deco_Salty_Bone_Full"
    },
    {
      "x": -9,
      "y": 15,
      "z": 20,
      "name": "Deco_Salty_Bone_Full"
    },
    {
      "x": -9,
      "y": 12,
      "z": 21,
      "name": "Deco_Salty_Bone_Full"
    },
    {
      "x": -9,
      "y": 13,
      "z": 21,
      "name": "Deco_Salty_Bone_Full"
    },
    {
      "x": -8,
      "y": 14,
      "z": 0,
      "name": "Deco_Salty_Bone_Full"
    },
    {
      "x": -8,
      "y": 15,
      "z": 0,
      "name": "Deco_Salty_Bone_Full"
    },
    {
      "x": -8,
      "y": 1,
      "z": 1,
      "name": "Deco_Salty_Bone_Full"
    },
    {
      "x": -8,
      "y": 2,
      "z": 1,
      "name": "Deco_Salty_Bone_Full"
    },
    {
      "x": -8,
      "y": 3,
      "z": 1,
      "name": "Deco_Salty_Bone_Full"
    },
    {
      "x": -8,
      "y": 15,
      "z": 1,
      "name": "Deco_Salty_Bone_Full"
    },
    {
      "x": -8,
      "y": 16,
      "z": 1,
      "name": "Deco_Salty_Bone_Full"
    },
    {
      "x": -8,
      "y": 17,
      "z": 1,
      "name": "Deco_Salty_Bone_Full"
    },
    {
      "x": -8,
      "y": 16,
      "z": 2,
      "name": "Deco_Salty_Bone_Full"
    },
    {
      "x": -8,
      "y": 19,
      "z": 8,
      "name": "Deco_Salty_Bone_Full"
    },
    {
      "x": -8,
      "y": 20,
      "z": 8,
      "name": "Deco_Salty_Bone_Full"
    },
    {
      "x": -8,
      "y": 18,
      "z": 9,
      "name": "Deco_Salty_Bone_Full"
    },
    {
      "x": -8,
      "y": 19,
      "z": 9,
      "name": "Deco_Salty_Bone_Full"
    },
    {
      "x": -8,
      "y": 20,
      "z": 9,
      "name": "Deco_Salty_Bone_Full"
    },
    {
      "x": -8,
      "y": 21,
      "z": 9,
      "name": "Deco_Salty_Bone_Full"
    },
    {
      "x": -8,
      "y": 22,
      "z": 9,
      "name": "Deco_Salty_Bone_Full"
    },
    {
      "x": -8,
      "y": 23,
      "z": 9,
      "name": "Deco_Salty_Bone_Spike"
    },
    {
      "x": -8,
      "y": 18,
      "z": 10,
      "name": "Deco_Salty_Bone_Full"
    },
    {
      "x": -8,
      "y": 19,
      "z": 10,
      "name": "Deco_Salty_Bone_Full"
    },
    {
      "x": -8,
      "y": 20,
      "z": 10,
      "name": "Deco_Salty_Bone_Full"
    },
    {
      "x": -8,
      "y": 21,
      "z": 10,
      "name": "Deco_Salty_Bone_Full"
    },
    {
      "x": -8,
      "y": 18,
      "z": 11,
      "name": "Deco_Salty_Bone_Full"
    },
    {
      "x": -8,
      "y": 19,
      "z": 11,
      "name": "Deco_Salty_Bone_Full"
    },
    {
      "x": -8,
      "y": 18,
      "z": 12,
      "name": "Deco_Salty_Bone_Full"
    },
    {
      "x": -8,
      "y": 12,
      "z": 20,
      "name": "Deco_Salty_Bone_Full"
    },
    {
      "x": -8,
      "y": 13,
      "z": 20,
      "name": "Deco_Salty_Bone_Full"
    },
    {
      "x": -8,
      "y": 7,
      "z": 21,
      "name": "Deco_Salty_Bone_Full"
    },
    {
      "x": -8,
      "y": 8,
      "z": 21,
      "name": "Deco_Salty_Bone_Full"
    },
    {
      "x": -8,
      "y": 9,
      "z": 21,
      "name": "Deco_Salty_Bone_Full"
    },
    {
      "x": -8,
      "y": 10,
      "z": 21,
      "name": "Deco_Salty_Bone_Full"
    },
    {
      "x": -8,
      "y": 11,
      "z": 21,
      "name": "Deco_Salty_Bone_Full"
    },
    {
      "x": -8,
      "y": 12,
      "z": 21,
      "name": "Deco_Salty_Bone_Full"
    },
    {
      "x": -7,
      "y": 16,
      "z": 1,
      "name": "Deco_Salty_Bone_Full"
    },
    {
      "x": -7,
      "y": 0,
      "z": 2,
      "name": "Deco_Salty_Bone_Full"
    },
    {
      "x": -7,
      "y": 1,
      "z": 2,
      "name": "Deco_Salty_Bone_Full"
    },
    {
      "x": -7,
      "y": 16,
      "z": 2,
      "name": "Deco_Salty_Bone_Full"
    },
    {
      "x": -7,
      "y": 17,
      "z": 2,
      "name": "Deco_Salty_Bone_Full"
    },
    {
      "x": -7,
      "y": 18,
      "z": 2,
      "name": "Deco_Salty_Bone_Full"
    },
    {
      "x": -7,
      "y": 17,
      "z": 3,
      "name": "Deco_Salty_Bone_Full"
    },
    {
      "x": -7,
      "y": 18,
      "z": 7,
      "name": "Deco_Salty_Bone_Full"
    },
    {
      "x": -7,
      "y": 19,
      "z": 7,
      "name": "Deco_Salty_Bone_Full"
    },
    {
      "x": -7,
      "y": 18,
      "z": 8,
      "name": "Deco_Salty_Bone_Full"
    },
    {
      "x": -7,
      "y": 19,
      "z": 8,
      "name": "Deco_Salty_Bone_Full"
    },
    {
      "x": -7,
      "y": 19,
      "z": 9,
      "name": "Deco_Salty_Bone_Full"
    },
    {
      "x": -7,
      "y": 20,
      "z": 9,
      "name": "Deco_Salty_Bone_Full"
    },
    {
      "x": -7,
      "y": 19,
      "z": 10,
      "name": "Deco_Salty_Bone_Full"
    },
    {
      "x": -7,
      "y": 18,
      "z": 11,
      "name": "Deco_Salty_Bone_Full"
    },
    {
      "x": -7,
      "y": 19,
      "z": 11,
      "name": "Deco_Salty_Bone_Full"
    },
    {
      "x": -7,
      "y": 17,
      "z": 12,
      "name": "Deco_Salty_Bone_Full"
    },
    {
      "x": -7,
      "y": 18,
      "z": 12,
      "name": "Deco_Salty_Bone_Full"
    },
    {
      "x": -7,
      "y": 17,
      "z": 13,
      "name": "Deco_Salty_Bone_Full"
    },
    {
      "x": -6,
      "y": 17,
      "z": 2,
      "name": "Deco_Salty_Bone_Full"
    },
    {
      "x": -6,
      "y": 17,
      "z": 3,
      "name": "Deco_Salty_Bone_Full"
    },
    {
      "x": -6,
      "y": 18,
      "z": 3,
      "name": "Deco_Salty_Bone_Full"
    },
    {
      "x": -6,
      "y": 18,
      "z": 4,
      "name": "Deco_Salty_Bone_Full"
    },
    {
      "x": -6,
      "y": 19,
      "z": 5,
      "name": "Deco_Salty_Bone_Full"
    },
    {
      "x": -6,
      "y": 19,
      "z": 6,
      "name": "Deco_Salty_Bone_Full"
    },
    {
      "x": -6,
      "y": 19,
      "z": 7,
      "name": "Deco_Salty_Bone_Full"
    },
    {
      "x": -6,
      "y": 18,
      "z": 8,
      "name": "Deco_Salty_Bone_Full"
    },
    {
      "x": -6,
      "y": 19,
      "z": 8,
      "name": "Deco_Salty_Bone_Full"
    },
    {
      "x": -6,
      "y": 17,
      "z": 12,
      "name": "Deco_Salty_Bone_Full"
    },
    {
      "x": -6,
      "y": 0,
      "z": 13,
      "name": "Deco_Salty_Bone_Full"
    },
    {
      "x": -6,
      "y": 1,
      "z": 13,
      "name": "Deco_Salty_Bone_Full"
    },
    {
      "x": -6,
      "y": 16,
      "z": 13,
      "name": "Deco_Salty_Bone_Full"
    },
    {
      "x": -6,
      "y": 17,
      "z": 13,
      "name": "Deco_Salty_Bone_Full"
    },
    {
      "x": -6,
      "y": 18,
      "z": 13,
      "name": "Deco_Salty_Bone_Full"
    },
    {
      "x": -6,
      "y": 16,
      "z": 14,
      "name": "Deco_Salty_Bone_Full"
    },
    {
      "x": -5,
      "y": 7,
      "z": -6,
      "name": "Deco_Salty_Bone_Full"
    },
    {
      "x": -5,
      "y": 8,
      "z": -6,
      "name": "Deco_Salty_Bone_Full"
    },
    {
      "x": -5,
      "y": 9,
      "z": -6,
      "name": "Deco_Salty_Bone_Full"
    },
    {
      "x": -5,
      "y": 10,
      "z": -6,
      "name": "Deco_Salty_Bone_Full"
    },
    {
      "x": -5,
      "y": 11,
      "z": -6,
      "name": "Deco_Salty_Bone_Full"
    },
    {
      "x": -5,
      "y": 12,
      "z": -6,
      "name": "Deco_Salty_Bone_Full"
    },
    {
      "x": -5,
      "y": 13,
      "z": -6,
      "name": "Deco_Salty_Bone_Full"
    },
    {
      "x": -5,
      "y": 14,
      "z": -6,
      "name": "Deco_Salty_Bone_Full"
    },
    {
      "x": -5,
      "y": 14,
      "z": -5,
      "name": "Deco_Salty_Bone_Full"
    },
    {
      "x": -5,
      "y": 15,
      "z": -5,
      "name": "Deco_Salty_Bone_Full"
    },
    {
      "x": -5,
      "y": 18,
      "z": 3,
      "name": "Deco_Salty_Bone_Full"
    },
    {
      "x": -5,
      "y": 19,
      "z": 3,
      "name": "Deco_Salty_Bone_Full"
    },
    {
      "x": -5,
      "y": 18,
      "z": 4,
      "name": "Deco_Salty_Bone_Full"
    },
    {
      "x": -5,
      "y": 19,
      "z": 4,
      "name": "Deco_Salty_Bone_Full"
    },
    {
      "x": -5,
      "y": 18,
      "z": 5,
      "name": "Deco_Salty_Bone_Full"
    },
    {
      "x": -5,
      "y": 19,
      "z": 5,
      "name": "Deco_Salty_Bone_Full"
    },
    {
      "x": -5,
      "y": 20,
      "z": 5,
      "name": "Deco_Salty_Bone_Full"
    },
    {
      "x": -5,
      "y": 18,
      "z": 6,
      "name": "Deco_Salty_Bone_Full"
    },
    {
      "x": -5,
      "y": 19,
      "z": 6,
      "name": "Deco_Salty_Bone_Full"
    },
    {
      "x": -5,
      "y": 20,
      "z": 6,
      "name": "Deco_Salty_Bone_Full"
    },
    {
      "x": -5,
      "y": 21,
      "z": 6,
      "name": "Deco_Salty_Bone_Full"
    },
    {
      "x": -5,
      "y": 19,
      "z": 7,
      "name": "Deco_Salty_Bone_Full"
    },
    {
      "x": -5,
      "y": 16,
      "z": 13,
      "name": "Deco_Salty_Bone_Full"
    },
    {
      "x": -5,
      "y": 1,
      "z": 14,
      "name": "Deco_Salty_Bone_Full"
    },
    {
      "x": -5,
      "y": 2,
      "z": 14,
      "name": "Deco_Salty_Bone_Full"
    },
    {
      "x": -5,
      "y": 3,
      "z": 14,
      "name": "Deco_Salty_Bone_Full"
    },
    {
      "x": -5,
      "y": 15,
      "z": 14,
      "name": "Deco_Salty_Bone_Full"
    },
    {
      "x": -5,
      "y": 16,
      "z": 14,
      "name": "Deco_Salty_Bone_Full"
    },
    {
      "x": -5,
      "y": 17,
      "z": 14,
      "name": "Deco_Salty_Bone_Full"
    },
    {
      "x": -5,
      "y": 14,
      "z": 15,
      "name": "Deco_Salty_Bone_Full"
    },
    {
      "x": -5,
      "y": 15,
      "z": 15,
      "name": "Deco_Salty_Bone_Full"
    },
    {
      "x": -4,
      "y": 14,
      "z": -6,
      "name": "Deco_Salty_Bone_Full"
    },
    {
      "x": -4,
      "y": 15,
      "z": -6,
      "name": "Deco_Salty_Bone_Full"
    },
    {
      "x": -4,
      "y": 4,
      "z": -5,
      "name": "Deco_Salty_Bone_Full"
    },
    {
      "x": -4,
      "y": 5,
      "z": -5,
      "name": "Deco_Salty_Bone_Full"
    },
    {
      "x": -4,
      "y": 6,
      "z": -5,
      "name": "Deco_Salty_Bone_Full"
    },
    {
      "x": -4,
      "y": 7,
      "z": -5,
      "name": "Deco_Salty_Bone_Full"
    },
    {
      "x": -4,
      "y": 13,
      "z": -5,
      "name": "Deco_Salty_Bone_Full"
    },
    {
      "x": -4,
      "y": 14,
      "z": -5,
      "name": "Deco_Salty_Bone_Full"
    },
    {
      "x": -4,
      "y": 15,
      "z": -5,
      "name": "Deco_Salty_Bone_Full"
    },
    {
      "x": -4,
      "y": 16,
      "z": -5,
      "name": "Deco_Salty_Bone_Full"
    },
    {
      "x": -4,
      "y": 17,
      "z": -5,
      "name": "Deco_Salty_Bone_Full"
    },
    {
      "x": -4,
      "y": 15,
      "z": -4,
      "name": "Deco_Salty_Bone_Full"
    },
    {
      "x": -4,
      "y": 16,
      "z": -4,
      "name": "Deco_Salty_Bone_Full"
    },
    {
      "x": -4,
      "y": 19,
      "z": 3,
      "name": "Deco_Salty_Bone_Full"
    },
    {
      "x": -4,
      "y": 18,
      "z": 4,
      "name": "Deco_Salty_Bone_Full"
    },
    {
      "x": -4,
      "y": 19,
      "z": 4,
      "name": "Deco_Salty_Bone_Full"
    },
    {
      "x": -4,
      "y": 20,
      "z": 4,
      "name": "Deco_Salty_Bone_Full"
    },
    {
      "x": -4,
      "y": 21,
      "z": 4,
      "name": "Deco_Salty_Bone_Full"
    },
    {
      "x": -4,
      "y": 18,
      "z": 5,
      "name": "Deco_Salty_Bone_Full"
    },
    {
      "x": -4,
      "y": 19,
      "z": 5,
      "name": "Deco_Salty_Bone_Full"
    },
    {
      "x": -4,
      "y": 20,
      "z": 5,
      "name": "Deco_Salty_Bone_Full"
    },
    {
      "x": -4,
      "y": 21,
      "z": 5,
      "name": "Deco_Salty_Bone_Full"
    },
    {
      "x": -4,
      "y": 22,
      "z": 5,
      "name": "Deco_Salty_Bone_Full"
    },
    {
      "x": -4,
      "y": 18,
      "z": 6,
      "name": "Deco_Salty_Bone_Full"
    },
    {
      "x": -4,
      "y": 19,
      "z": 6,
      "name": "Deco_Salty_Bone_Full"
    },
    {
      "x": -4,
      "y": 20,
      "z": 6,
      "name": "Deco_Salty_Bone_Full"
    },
    {
      "x": -4,
      "y": 19,
      "z": 7,
      "name": "Deco_Salty_Bone_Full"
    },
    {
      "x": -4,
      "y": 14,
      "z": 14,
      "name": "Deco_Salty_Bone_Full"
    },
    {
      "x": -4,
      "y": 15,
      "z": 14,
      "name": "Deco_Salty_Bone_Full"
    },
    {
      "x": -4,
      "y": 3,
      "z": 15,
      "name": "Deco_Salty_Bone_Full"
    },
    {
      "x": -4,
      "y": 4,
      "z": 15,
      "name": "Deco_Salty_Bone_Full"
    },
    {
      "x": -4,
      "y": 5,
      "z": 15,
      "name": "Deco_Salty_Bone_Full"
    },
    {
      "x": -4,
      "y": 6,
      "z": 15,
      "name": "Deco_Salty_Bone_Full"
    },
    {
      "x": -4,
      "y": 12,
      "z": 15,
      "name": "Deco_Salty_Bone_Full"
    },
    {
      "x": -4,
      "y": 13,
      "z": 15,
      "name": "Deco_Salty_Bone_Full"
    },
    {
      "x": -4,
      "y": 14,
      "z": 15,
      "name": "Deco_Salty_Bone_Full"
    },
    {
      "x": -4,
      "y": 15,
      "z": 15,
      "name": "Deco_Salty_Bone_Full"
    },
    {
      "x": -4,
      "y": 16,
      "z": 15,
      "name": "Deco_Salty_Bone_Full"
    },
    {
      "x": -4,
      "y": 13,
      "z": 16,
      "name": "Deco_Salty_Bone_Full"
    },
    {
      "x": -4,
      "y": 14,
      "z": 16,
      "name": "Deco_Salty_Bone_Full"
    },
    {
      "x": -3,
      "y": 15,
      "z": -5,
      "name": "Deco_Salty_Bone_Full"
    },
    {
      "x": -3,
      "y": 16,
      "z": -5,
      "name": "Deco_Salty_Bone_Full"
    },
    {
      "x": -3,
      "y": 2,
      "z": -4,
      "name": "Deco_Salty_Bone_Full"
    },
    {
      "x": -3,
      "y": 3,
      "z": -4,
      "name": "Deco_Salty_Bone_Full"
    },
    {
      "x": -3,
      "y": 4,
      "z": -4,
      "name": "Deco_Salty_Bone_Full"
    },
    {
      "x": -3,
      "y": 16,
      "z": -4,
      "name": "Deco_Salty_Bone_Full"
    },
    {
      "x": -3,
      "y": 17,
      "z": -4,
      "name": "Deco_Salty_Bone_Full"
    },
    {
      "x": -3,
      "y": 18,
      "z": -4,
      "name": "Deco_Salty_Bone_Full"
    },
    {
      "x": -3,
      "y": 17,
      "z": -3,
      "name": "Deco_Salty_Bone_Full"
    },
    {
      "x": -3,
      "y": 19,
      "z": 3,
      "name": "Deco_Salty_Bone_Full"
    },
    {
      "x": -3,
      "y": 20,
      "z": 3,
      "name": "Deco_Salty_Bone_Full"
    },
    {
      "x": -3,
      "y": 18,
      "z": 4,
      "name": "Deco_Salty_Bone_Full"
    },
    {
      "x": -3,
      "y": 19,
      "z": 4,
      "name": "Deco_Salty_Bone_Full"
    },
    {
      "x": -3,
      "y": 20,
      "z": 4,
      "name": "Deco_Salty_Bone_Full"
    },
    {
      "x": -3,
      "y": 21,
      "z": 4,
      "name": "Deco_Salty_Bone_Full"
    },
    {
      "x": -3,
      "y": 22,
      "z": 4,
      "name": "Deco_Salty_Bone_Full"
    },
    {
      "x": -3,
      "y": 23,
      "z": 4,
      "name": "Deco_Salty_Bone_Spike"
    },
    {
      "x": -3,
      "y": 18,
      "z": 5,
      "name": "Deco_Salty_Bone_Full"
    },
    {
      "x": -3,
      "y": 19,
      "z": 5,
      "name": "Deco_Salty_Bone_Full"
    },
    {
      "x": -3,
      "y": 20,
      "z": 5,
      "name": "Deco_Salty_Bone_Full"
    },
    {
      "x": -3,
      "y": 21,
      "z": 5,
      "name": "Deco_Salty_Bone_Full"
    },
    {
      "x": -3,
      "y": 18,
      "z": 6,
      "name": "Deco_Salty_Bone_Full"
    },
    {
      "x": -3,
      "y": 19,
      "z": 6,
      "name": "Deco_Salty_Bone_Full"
    },
    {
      "x": -3,
      "y": 18,
      "z": 7,
      "name": "Deco_Salty_Bone_Full"
    },
    {
      "x": -3,
      "y": 13,
      "z": 15,
      "name": "Deco_Salty_Bone_Full"
    },
    {
      "x": -3,
      "y": 14,
      "z": 15,
      "name": "Deco_Salty_Bone_Full"
    },
    {
      "x": -3,
      "y": 6,
      "z": 16,
      "name": "Deco_Salty_Bone_Full"
    },
    {
      "x": -3,
      "y": 7,
      "z": 16,
      "name": "Deco_Salty_Bone_Full"
    },
    {
      "x": -3,
      "y": 8,
      "z": 16,
      "name": "Deco_Salty_Bone_Full"
    },
    {
      "x": -3,
      "y": 9,
      "z": 16,
      "name": "Deco_Salty_Bone_Full"
    },
    {
      "x": -3,
      "y": 10,
      "z": 16,
      "name": "Deco_Salty_Bone_Full"
    },
    {
      "x": -3,
      "y": 11,
      "z": 16,
      "name": "Deco_Salty_Bone_Full"
    },
    {
      "x": -3,
      "y": 12,
      "z": 16,
      "name": "Deco_Salty_Bone_Full"
    },
    {
      "x": -3,
      "y": 13,
      "z": 16,
      "name": "Deco_Salty_Bone_Full"
    },
    {
      "x": -2,
      "y": 17,
      "z": -4,
      "name": "Deco_Salty_Bone_Full"
    },
    {
      "x": -2,
      "y": 1,
      "z": -3,
      "name": "Deco_Salty_Bone_Full"
    },
    {
      "x": -2,
      "y": 2,
      "z": -3,
      "name": "Deco_Salty_Bone_Full"
    },
    {
      "x": -2,
      "y": 17,
      "z": -3,
      "name": "Deco_Salty_Bone_Full"
    },
    {
      "x": -2,
      "y": 18,
      "z": -3,
      "name": "Deco_Salty_Bone_Full"
    },
    {
      "x": -2,
      "y": 19,
      "z": -3,
      "name": "Deco_Salty_Bone_Full"
    },
    {
      "x": -2,
      "y": 18,
      "z": -2,
      "name": "Deco_Salty_Bone_Full"
    },
    {
      "x": -2,
      "y": 18,
      "z": 2,
      "name": "Deco_Salty_Bone_Full"
    },
    {
      "x": -2,
      "y": 19,
      "z": 2,
      "name": "Deco_Salty_Bone_Full"
    },
    {
      "x": -2,
      "y": 18,
      "z": 3,
      "name": "Deco_Salty_Bone_Full"
    },
    {
      "x": -2,
      "y": 19,
      "z": 3,
      "name": "Deco_Salty_Bone_Full"
    },
    {
      "x": -2,
      "y": 19,
      "z": 4,
      "name": "Deco_Salty_Bone_Full"
    },
    {
      "x": -2,
      "y": 20,
      "z": 4,
      "name": "Deco_Salty_Bone_Full"
    },
    {
      "x": -2,
      "y": 19,
      "z": 5,
      "name": "Deco_Salty_Bone_Full"
    },
    {
      "x": -2,
      "y": 18,
      "z": 6,
      "name": "Deco_Salty_Bone_Full"
    },
    {
      "x": -2,
      "y": 19,
      "z": 6,
      "name": "Deco_Salty_Bone_Full"
    },
    {
      "x": -2,
      "y": 17,
      "z": 7,
      "name": "Deco_Salty_Bone_Full"
    },
    {
      "x": -2,
      "y": 18,
      "z": 7,
      "name": "Deco_Salty_Bone_Full"
    },
    {
      "x": -2,
      "y": 17,
      "z": 8,
      "name": "Deco_Salty_Bone_Full"
    },
    {
      "x": -1,
      "y": 18,
      "z": -3,
      "name": "Deco_Salty_Bone_Full"
    },
    {
      "x": -1,
      "y": 18,
      "z": -2,
      "name": "Deco_Salty_Bone_Full"
    },
    {
      "x": -1,
      "y": 19,
      "z": -2,
      "name": "Deco_Salty_Bone_Full"
    },
    {
      "x": -1,
      "y": 19,
      "z": -1,
      "name": "Deco_Salty_Bone_Full"
    },
    {
      "x": -1,
      "y": 20,
      "z": 0,
      "name": "Deco_Salty_Bone_Full"
    },
    {
      "x": -1,
      "y": 20,
      "z": 1,
      "name": "Deco_Salty_Bone_Full"
    },
    {
      "x": -1,
      "y": 20,
      "z": 2,
      "name": "Deco_Salty_Bone_Full"
    },
    {
      "x": -1,
      "y": 18,
      "z": 3,
      "name": "Deco_Salty_Bone_Full"
    },
    {
      "x": -1,
      "y": 19,
      "z": 3,
      "name": "Deco_Salty_Bone_Full"
    },
    {
      "x": -1,
      "y": 17,
      "z": 7,
      "name": "Deco_Salty_Bone_Full"
    },
    {
      "x": -1,
      "y": 0,
      "z": 8,
      "name": "Deco_Salty_Bone_Full"
    },
    {
      "x": -1,
      "y": 1,
      "z": 8,
      "name": "Deco_Salty_Bone_Full"
    },
    {
      "x": -1,
      "y": 16,
      "z": 8,
      "name": "Deco_Salty_Bone_Full"
    },
    {
      "x": -1,
      "y": 17,
      "z": 8,
      "name": "Deco_Salty_Bone_Full"
    },
    {
      "x": -1,
      "y": 18,
      "z": 8,
      "name": "Deco_Salty_Bone_Full"
    },
    {
      "x": -1,
      "y": 16,
      "z": 9,
      "name": "Deco_Salty_Bone_Full"
    },
    {
      "x": 0,
      "y": 6,
      "z": -11,
      "name": "Deco_Salty_Bone_Full"
    },
    {
      "x": 0,
      "y": 7,
      "z": -11,
      "name": "Deco_Salty_Bone_Full"
    },
    {
      "x": 0,
      "y": 8,
      "z": -11,
      "name": "Deco_Salty_Bone_Full"
    },
    {
      "x": 0,
      "y": 9,
      "z": -11,
      "name": "Deco_Salty_Bone_Full"
    },
    {
      "x": 0,
      "y": 10,
      "z": -11,
      "name": "Deco_Salty_Bone_Full"
    },
    {
      "x": 0,
      "y": 11,
      "z": -11,
      "name": "Deco_Salty_Bone_Full"
    },
    {
      "x": 0,
      "y": 12,
      "z": -11,
      "name": "Deco_Salty_Bone_Full"
    },
    {
      "x": 0,
      "y": 13,
      "z": -11,
      "name": "Deco_Salty_Bone_Full"
    },
    {
      "x": 0,
      "y": 13,
      "z": -10,
      "name": "Deco_Salty_Bone_Full"
    },
    {
      "x": 0,
      "y": 14,
      "z": -10,
      "name": "Deco_Salty_Bone_Full"
    },
    {
      "x": 0,
      "y": 19,
      "z": -2,
      "name": "Deco_Salty_Bone_Full"
    },
    {
      "x": 0,
      "y": 20,
      "z": -2,
      "name": "Deco_Salty_Bone_Full"
    },
    {
      "x": 0,
      "y": 19,
      "z": -1,
      "name": "Deco_Salty_Bone_Full"
    },
    {
      "x": 0,
      "y": 20,
      "z": -1,
      "name": "Deco_Salty_Bone_Full"
    },
    {
      "x": 0,
      "y": 19,
      "z": 0,
      "name": "Deco_Salty_Bone_Full"
    },
    {
      "x": 0,
      "y": 20,
      "z": 0,
      "name": "Deco_Salty_Bone_Full"
    },
    {
      "x": 0,
      "y": 21,
      "z": 0,
      "name": "Deco_Salty_Bone_Full"
    },
    {
      "x": 0,
      "y": 19,
      "z": 1,
      "name": "Deco_Salty_Bone_Full"
    },
    {
      "x": 0,
      "y": 20,
      "z": 1,
      "name": "Deco_Salty_Bone_Full"
    },
    {
      "x": 0,
      "y": 21,
      "z": 1,
      "name": "Deco_Salty_Bone_Full"
    },
    {
      "x": 0,
      "y": 22,
      "z": 1,
      "name": "Deco_Salty_Bone_Full"
    },
    {
      "x": 0,
      "y": 20,
      "z": 2,
      "name": "Deco_Salty_Bone_Full"
    },
    {
      "x": 0,
      "y": 16,
      "z": 8,
      "name": "Deco_Salty_Bone_Full"
    },
    {
      "x": 0,
      "y": 1,
      "z": 9,
      "name": "Deco_Salty_Bone_Full"
    },
    {
      "x": 0,
      "y": 2,
      "z": 9,
      "name": "Deco_Salty_Bone_Full"
    },
    {
      "x": 0,
      "y": 3,
      "z": 9,
      "name": "Deco_Salty_Bone_Full"
    },
    {
      "x": 0,
      "y": 15,
      "z": 9,
      "name": "Deco_Salty_Bone_Full"
    },
    {
      "x": 0,
      "y": 16,
      "z": 9,
      "name": "Deco_Salty_Bone_Full"
    },
    {
      "x": 0,
      "y": 17,
      "z": 9,
      "name": "Deco_Salty_Bone_Full"
    },
    {
      "x": 0,
      "y": 14,
      "z": 10,
      "name": "Deco_Salty_Bone_Full"
    },
    {
      "x": 0,
      "y": 15,
      "z": 10,
      "name": "Deco_Salty_Bone_Full"
    },
    {
      "x": 1,
      "y": 13,
      "z": -11,
      "name": "Deco_Salty_Bone_Full"
    },
    {
      "x": 1,
      "y": 14,
      "z": -11,
      "name": "Deco_Salty_Bone_Full"
    },
    {
      "x": 1,
      "y": 3,
      "z": -10,
      "name": "Deco_Salty_Bone_Full"
    },
    {
      "x": 1,
      "y": 4,
      "z": -10,
      "name": "Deco_Salty_Bone_Full"
    },
    {
      "x": 1,
      "y": 5,
      "z": -10,
      "name": "Deco_Salty_Bone_Full"
    },
    {
      "x": 1,
      "y": 6,
      "z": -10,
      "name": "Deco_Salty_Bone_Full"
    },
    {
      "x": 1,
      "y": 12,
      "z": -10,
      "name": "Deco_Salty_Bone_Full"
    },
    {
      "x": 1,
      "y": 13,
      "z": -10,
      "name": "Deco_Salty_Bone_Full"
    },
    {
      "x": 1,
      "y": 14,
      "z": -10,
      "name": "Deco_Salty_Bone_Full"
    },
    {
      "x": 1,
      "y": 15,
      "z": -10,
      "name": "Deco_Salty_Bone_Full"
    },
    {
      "x": 1,
      "y": 16,
      "z": -10,
      "name": "Deco_Salty_Bone_Full"
    },
    {
      "x": 1,
      "y": 14,
      "z": -9,
      "name": "Deco_Salty_Bone_Full"
    },
    {
      "x": 1,
      "y": 15,
      "z": -9,
      "name": "Deco_Salty_Bone_Full"
    },
    {
      "x": 1,
      "y": 20,
      "z": -2,
      "name": "Deco_Salty_Bone_Full"
    },
    {
      "x": 1,
      "y": 19,
      "z": -1,
      "name": "Deco_Salty_Bone_Full"
    },
    {
      "x": 1,
      "y": 20,
      "z": -1,
      "name": "Deco_Salty_Bone_Full"
    },
    {
      "x": 1,
      "y": 21,
      "z": -1,
      "name": "Deco_Salty_Bone_Full"
    },
    {
      "x": 1,
      "y": 22,
      "z": -1,
      "name": "Deco_Salty_Bone_Full"
    },
    {
      "x": 1,
      "y": 19,
      "z": 0,
      "name": "Deco_Salty_Bone_Full"
    },
    {
      "x": 1,
      "y": 20,
      "z": 0,
      "name": "Deco_Salty_Bone_Full"
    },
    {
      "x": 1,
      "y": 21,
      "z": 0,
      "name": "Deco_Salty_Bone_Full"
    },
    {
      "x": 1,
      "y": 22,
      "z": 0,
      "name": "Deco_Salty_Bone_Full"
    },
    {
      "x": 1,
      "y": 23,
      "z": 0,
      "name": "Deco_Salty_Bone_Full"
    },
    {
      "x": 1,
      "y": 19,
      "z": 1,
      "name": "Deco_Salty_Bone_Full"
    },
    {
      "x": 1,
      "y": 20,
      "z": 1,
      "name": "Deco_Salty_Bone_Full"
    },
    {
      "x": 1,
      "y": 21,
      "z": 1,
      "name": "Deco_Salty_Bone_Full"
    },
    {
      "x": 1,
      "y": 20,
      "z": 2,
      "name": "Deco_Salty_Bone_Full"
    },
    {
      "x": 1,
      "y": 14,
      "z": 9,
      "name": "Deco_Salty_Bone_Full"
    },
    {
      "x": 1,
      "y": 15,
      "z": 9,
      "name": "Deco_Salty_Bone_Full"
    },
    {
      "x": 1,
      "y": 3,
      "z": 10,
      "name": "Deco_Salty_Bone_Full"
    },
    {
      "x": 1,
      "y": 4,
      "z": 10,
      "name": "Deco_Salty_Bone_Full"
    },
    {
      "x": 1,
      "y": 5,
      "z": 10,
      "name": "Deco_Salty_Bone_Full"
    },
    {
      "x": 1,
      "y": 6,
      "z": 10,
      "name": "Deco_Salty_Bone_Full"
    },
    {
      "x": 1,
      "y": 12,
      "z": 10,
      "name": "Deco_Salty_Bone_Full"
    },
    {
      "x": 1,
      "y": 13,
      "z": 10,
      "name": "Deco_Salty_Bone_Full"
    },
    {
      "x": 1,
      "y": 14,
      "z": 10,
      "name": "Deco_Salty_Bone_Full"
    },
    {
      "x": 1,
      "y": 15,
      "z": 10,
      "name": "Deco_Salty_Bone_Full"
    },
    {
      "x": 1,
      "y": 16,
      "z": 10,
      "name": "Deco_Salty_Bone_Full"
    },
    {
      "x": 1,
      "y": 13,
      "z": 11,
      "name": "Deco_Salty_Bone_Full"
    },
    {
      "x": 1,
      "y": 14,
      "z": 11,
      "name": "Deco_Salty_Bone_Full"
    },
    {
      "x": 2,
      "y": 14,
      "z": -10,
      "name": "Deco_Salty_Bone_Full"
    },
    {
      "x": 2,
      "y": 15,
      "z": -10,
      "name": "Deco_Salty_Bone_Full"
    },
    {
      "x": 2,
      "y": 1,
      "z": -9,
      "name": "Deco_Salty_Bone_Full"
    },
    {
      "x": 2,
      "y": 2,
      "z": -9,
      "name": "Deco_Salty_Bone_Full"
    },
    {
      "x": 2,
      "y": 3,
      "z": -9,
      "name": "Deco_Salty_Bone_Full"
    },
    {
      "x": 2,
      "y": 15,
      "z": -9,
      "name": "Deco_Salty_Bone_Full"
    },
    {
      "x": 2,
      "y": 16,
      "z": -9,
      "name": "Deco_Salty_Bone_Full"
    },
    {
      "x": 2,
      "y": 17,
      "z": -9,
      "name": "Deco_Salty_Bone_Full"
    },
    {
      "x": 2,
      "y": 16,
      "z": -8,
      "name": "Deco_Salty_Bone_Full"
    },
    {
      "x": 2,
      "y": 20,
      "z": -2,
      "name": "Deco_Salty_Bone_Full"
    },
    {
      "x": 2,
      "y": 21,
      "z": -2,
      "name": "Deco_Salty_Bone_Full"
    },
    {
      "x": 2,
      "y": 19,
      "z": -1,
      "name": "Deco_Salty_Bone_Full"
    },
    {
      "x": 2,
      "y": 20,
      "z": -1,
      "name": "Deco_Salty_Bone_Full"
    },
    {
      "x": 2,
      "y": 21,
      "z": -1,
      "name": "Deco_Salty_Bone_Full"
    },
    {
      "x": 2,
      "y": 22,
      "z": -1,
      "name": "Deco_Salty_Bone_Full"
    },
    {
      "x": 2,
      "y": 23,
      "z": -1,
      "name": "Deco_Salty_Bone_Full"
    },
    {
      "x": 2,
      "y": 24,
      "z": -1,
      "name": "Deco_Salty_Bone_Spike_Large"
    },
    {
      "x": 2,
      "y": 19,
      "z": 0,
      "name": "Deco_Salty_Bone_Full"
    },
    {
      "x": 2,
      "y": 20,
      "z": 0,
      "name": "Deco_Salty_Bone_Full"
    },
    {
      "x": 2,
      "y": 21,
      "z": 0,
      "name": "Deco_Salty_Bone_Full"
    },
    {
      "x": 2,
      "y": 22,
      "z": 0,
      "name": "Deco_Salty_Bone_Full"
    },
    {
      "x": 2,
      "y": 19,
      "z": 1,
      "name": "Deco_Salty_Bone_Full"
    },
    {
      "x": 2,
      "y": 20,
      "z": 1,
      "name": "Deco_Salty_Bone_Full"
    },
    {
      "x": 2,
      "y": 19,
      "z": 2,
      "name": "Deco_Salty_Bone_Full"
    },
    {
      "x": 2,
      "y": 13,
      "z": 10,
      "name": "Deco_Salty_Bone_Full"
    },
    {
      "x": 2,
      "y": 14,
      "z": 10,
      "name": "Deco_Salty_Bone_Full"
    },
    {
      "x": 2,
      "y": 6,
      "z": 11,
      "name": "Deco_Salty_Bone_Full"
    },
    {
      "x": 2,
      "y": 7,
      "z": 11,
      "name": "Deco_Salty_Bone_Full"
    },
    {
      "x": 2,
      "y": 8,
      "z": 11,
      "name": "Deco_Salty_Bone_Full"
    },
    {
      "x": 2,
      "y": 9,
      "z": 11,
      "name": "Deco_Salty_Bone_Full"
    },
    {
      "x": 2,
      "y": 10,
      "z": 11,
      "name": "Deco_Salty_Bone_Full"
    },
    {
      "x": 2,
      "y": 11,
      "z": 11,
      "name": "Deco_Salty_Bone_Full"
    },
    {
      "x": 2,
      "y": 12,
      "z": 11,
      "name": "Deco_Salty_Bone_Full"
    },
    {
      "x": 2,
      "y": 13,
      "z": 11,
      "name": "Deco_Salty_Bone_Full"
    },
    {
      "x": 3,
      "y": 16,
      "z": -9,
      "name": "Deco_Salty_Bone_Full"
    },
    {
      "x": 3,
      "y": 0,
      "z": -8,
      "name": "Deco_Salty_Bone_Full"
    },
    {
      "x": 3,
      "y": 1,
      "z": -8,
      "name": "Deco_Salty_Bone_Full"
    },
    {
      "x": 3,
      "y": 16,
      "z": -8,
      "name": "Deco_Salty_Bone_Full"
    },
    {
      "x": 3,
      "y": 17,
      "z": -8,
      "name": "Deco_Salty_Bone_Full"
    },
    {
      "x": 3,
      "y": 18,
      "z": -8,
      "name": "Deco_Salty_Bone_Full"
    },
    {
      "x": 3,
      "y": 17,
      "z": -7,
      "name": "Deco_Salty_Bone_Full"
    },
    {
      "x": 3,
      "y": 19,
      "z": -3,
      "name": "Deco_Salty_Bone_Full"
    },
    {
      "x": 3,
      "y": 20,
      "z": -3,
      "name": "Deco_Salty_Bone_Full"
    },
    {
      "x": 3,
      "y": 19,
      "z": -2,
      "name": "Deco_Salty_Bone_Full"
    },
    {
      "x": 3,
      "y": 20,
      "z": -2,
      "name": "Deco_Salty_Bone_Full"
    },
    {
      "x": 3,
      "y": 20,
      "z": -1,
      "name": "Deco_Salty_Bone_Full"
    },
    {
      "x": 3,
      "y": 21,
      "z": -1,
      "name": "Deco_Salty_Bone_Full"
    },
    {
      "x": 3,
      "y": 20,
      "z": 0,
      "name": "Deco_Salty_Bone_Full"
    },
    {
      "x": 3,
      "y": 19,
      "z": 1,
      "name": "Deco_Salty_Bone_Full"
    },
    {
      "x": 3,
      "y": 20,
      "z": 1,
      "name": "Deco_Salty_Bone_Full"
    },
    {
      "x": 3,
      "y": 18,
      "z": 2,
      "name": "Deco_Salty_Bone_Full"
    },
    {
      "x": 3,
      "y": 19,
      "z": 2,
      "name": "Deco_Salty_Bone_Full"
    },
    {
      "x": 3,
      "y": 18,
      "z": 3,
      "name": "Deco_Salty_Bone_Full"
    },
    {
      "x": 4,
      "y": 17,
      "z": -8,
      "name": "Deco_Salty_Bone_Full"
    },
    {
      "x": 4,
      "y": 17,
      "z": -7,
      "name": "Deco_Salty_Bone_Full"
    },
    {
      "x": 4,
      "y": 18,
      "z": -7,
      "name": "Deco_Salty_Bone_Full"
    },
    {
      "x": 4,
      "y": 18,
      "z": -6,
      "name": "Deco_Salty_Bone_Full"
    },
    {
      "x": 4,
      "y": 19,
      "z": -5,
      "name": "Deco_Salty_Bone_Full"
    },
    {
      "x": 4,
      "y": 19,
      "z": -4,
      "name": "Deco_Salty_Bone_Full"
    },
    {
      "x": 4,
      "y": 19,
      "z": -3,
      "name": "Deco_Salty_Bone_Full"
    },
    {
      "x": 4,
      "y": 19,
      "z": -2,
      "name": "Deco_Salty_Bone_Full"
    },
    {
      "x": 4,
      "y": 20,
      "z": -2,
      "name": "Deco_Salty_Bone_Full"
    },
    {
      "x": 4,
      "y": 18,
      "z": 2,
      "name": "Deco_Salty_Bone_Full"
    },
    {
      "x": 4,
      "y": 1,
      "z": 3,
      "name": "Deco_Salty_Bone_Full"
    },
    {
      "x": 4,
      "y": 2,
      "z": 3,
      "name": "Deco_Salty_Bone_Full"
    },
    {
      "x": 4,
      "y": 17,
      "z": 3,
      "name": "Deco_Salty_Bone_Full"
    },
    {
      "x": 4,
      "y": 18,
      "z": 3,
      "name": "Deco_Salty_Bone_Full"
    },
    {
      "x": 4,
      "y": 19,
      "z": 3,
      "name": "Deco_Salty_Bone_Full"
    },
    {
      "x": 4,
      "y": 17,
      "z": 4,
      "name": "Deco_Salty_Bone_Full"
    },
    {
      "x": 5,
      "y": 18,
      "z": -7,
      "name": "Deco_Salty_Bone_Full"
    },
    {
      "x": 5,
      "y": 19,
      "z": -7,
      "name": "Deco_Salty_Bone_Full"
    },
    {
      "x": 5,
      "y": 18,
      "z": -6,
      "name": "Deco_Salty_Bone_Full"
    },
    {
      "x": 5,
      "y": 19,
      "z": -6,
      "name": "Deco_Salty_Bone_Full"
    },
    {
      "x": 5,
      "y": 18,
      "z": -5,
      "name": "Deco_Salty_Bone_Full"
    },
    {
      "x": 5,
      "y": 19,
      "z": -5,
      "name": "Deco_Salty_Bone_Full"
    },
    {
      "x": 5,
      "y": 20,
      "z": -5,
      "name": "Deco_Salty_Bone_Full"
    },
    {
      "x": 5,
      "y": 18,
      "z": -4,
      "name": "Deco_Salty_Bone_Full"
    },
    {
      "x": 5,
      "y": 19,
      "z": -4,
      "name": "Deco_Salty_Bone_Full"
    },
    {
      "x": 5,
      "y": 20,
      "z": -4,
      "name": "Deco_Salty_Bone_Full"
    },
    {
      "x": 5,
      "y": 21,
      "z": -4,
      "name": "Deco_Salty_Bone_Full"
    },
    {
      "x": 5,
      "y": 19,
      "z": -3,
      "name": "Deco_Salty_Bone_Full"
    },
    {
      "x": 5,
      "y": 17,
      "z": 3,
      "name": "Deco_Salty_Bone_Full"
    },
    {
      "x": 5,
      "y": 2,
      "z": 4,
      "name": "Deco_Salty_Bone_Full"
    },
    {
      "x": 5,
      "y": 3,
      "z": 4,
      "name": "Deco_Salty_Bone_Full"
    },
    {
      "x": 5,
      "y": 4,
      "z": 4,
      "name": "Deco_Salty_Bone_Full"
    },
    {
      "x": 5,
      "y": 16,
      "z": 4,
      "name": "Deco_Salty_Bone_Full"
    },
    {
      "x": 5,
      "y": 17,
      "z": 4,
      "name": "Deco_Salty_Bone_Full"
    },
    {
      "x": 5,
      "y": 18,
      "z": 4,
      "name": "Deco_Salty_Bone_Full"
    },
    {
      "x": 5,
      "y": 15,
      "z": 5,
      "name": "Deco_Salty_Bone_Full"
    },
    {
      "x": 5,
      "y": 16,
      "z": 5,
      "name": "Deco_Salty_Bone_Full"
    },
    {
      "x": 6,
      "y": 8,
      "z": -15,
      "name": "Deco_Salty_Bone_Full"
    },
    {
      "x": 6,
      "y": 9,
      "z": -15,
      "name": "Deco_Salty_Bone_Full"
    },
    {
      "x": 6,
      "y": 10,
      "z": -15,
      "name": "Deco_Salty_Bone_Full"
    },
    {
      "x": 6,
      "y": 11,
      "z": -15,
      "name": "Deco_Salty_Bone_Full"
    },
    {
      "x": 6,
      "y": 12,
      "z": -15,
      "name": "Deco_Salty_Bone_Full"
    },
    {
      "x": 6,
      "y": 13,
      "z": -15,
      "name": "Deco_Salty_Bone_Full"
    },
    {
      "x": 6,
      "y": 14,
      "z": -15,
      "name": "Deco_Salty_Bone_Full"
    },
    {
      "x": 6,
      "y": 14,
      "z": -14,
      "name": "Deco_Salty_Bone_Full"
    },
    {
      "x": 6,
      "y": 15,
      "z": -14,
      "name": "Deco_Salty_Bone_Full"
    },
    {
      "x": 6,
      "y": 19,
      "z": -7,
      "name": "Deco_Salty_Bone_Full"
    },
    {
      "x": 6,
      "y": 18,
      "z": -6,
      "name": "Deco_Salty_Bone_Full"
    },
    {
      "x": 6,
      "y": 19,
      "z": -6,
      "name": "Deco_Salty_Bone_Full"
    },
    {
      "x": 6,
      "y": 20,
      "z": -6,
      "name": "Deco_Salty_Bone_Full"
    },
    {
      "x": 6,
      "y": 21,
      "z": -6,
      "name": "Deco_Salty_Bone_Full"
    },
    {
      "x": 6,
      "y": 18,
      "z": -5,
      "name": "Deco_Salty_Bone_Full"
    },
    {
      "x": 6,
      "y": 19,
      "z": -5,
      "name": "Deco_Salty_Bone_Full"
    },
    {
      "x": 6,
      "y": 20,
      "z": -5,
      "name": "Deco_Salty_Bone_Full"
    },
    {
      "x": 6,
      "y": 21,
      "z": -5,
      "name": "Deco_Salty_Bone_Full"
    },
    {
      "x": 6,
      "y": 22,
      "z": -5,
      "name": "Deco_Salty_Bone_Full"
    },
    {
      "x": 6,
      "y": 18,
      "z": -4,
      "name": "Deco_Salty_Bone_Full"
    },
    {
      "x": 6,
      "y": 19,
      "z": -4,
      "name": "Deco_Salty_Bone_Full"
    },
    {
      "x": 6,
      "y": 20,
      "z": -4,
      "name": "Deco_Salty_Bone_Full"
    },
    {
      "x": 6,
      "y": 19,
      "z": -3,
      "name": "Deco_Salty_Bone_Full"
    },
    {
      "x": 6,
      "y": 15,
      "z": 4,
      "name": "Deco_Salty_Bone_Full"
    },
    {
      "x": 6,
      "y": 16,
      "z": 4,
      "name": "Deco_Salty_Bone_Full"
    },
    {
      "x": 6,
      "y": 4,
      "z": 5,
      "name": "Deco_Salty_Bone_Full"
    },
    {
      "x": 6,
      "y": 5,
      "z": 5,
      "name": "Deco_Salty_Bone_Full"
    },
    {
      "x": 6,
      "y": 6,
      "z": 5,
      "name": "Deco_Salty_Bone_Full"
    },
    {
      "x": 6,
      "y": 7,
      "z": 5,
      "name": "Deco_Salty_Bone_Full"
    },
    {
      "x": 6,
      "y": 13,
      "z": 5,
      "name": "Deco_Salty_Bone_Full"
    },
    {
      "x": 6,
      "y": 14,
      "z": 5,
      "name": "Deco_Salty_Bone_Full"
    },
    {
      "x": 6,
      "y": 15,
      "z": 5,
      "name": "Deco_Salty_Bone_Full"
    },
    {
      "x": 6,
      "y": 16,
      "z": 5,
      "name": "Deco_Salty_Bone_Full"
    },
    {
      "x": 6,
      "y": 17,
      "z": 5,
      "name": "Deco_Salty_Bone_Full"
    },
    {
      "x": 6,
      "y": 14,
      "z": 6,
      "name": "Deco_Salty_Bone_Full"
    },
    {
      "x": 6,
      "y": 15,
      "z": 6,
      "name": "Deco_Salty_Bone_Full"
    },
    {
      "x": 7,
      "y": 14,
      "z": -15,
      "name": "Deco_Salty_Bone_Full"
    },
    {
      "x": 7,
      "y": 15,
      "z": -15,
      "name": "Deco_Salty_Bone_Full"
    },
    {
      "x": 7,
      "y": 6,
      "z": -14,
      "name": "Deco_Salty_Bone_Full"
    },
    {
      "x": 7,
      "y": 7,
      "z": -14,
      "name": "Deco_Salty_Bone_Full"
    },
    {
      "x": 7,
      "y": 8,
      "z": -14,
      "name": "Deco_Salty_Bone_Full"
    },
    {
      "x": 7,
      "y": 9,
      "z": -14,
      "name": "Deco_Salty_Bone_Full"
    },
    {
      "x": 7,
      "y": 15,
      "z": -14,
      "name": "Deco_Salty_Bone_Full"
    },
    {
      "x": 7,
      "y": 16,
      "z": -14,
      "name": "Deco_Salty_Bone_Full"
    },
    {
      "x": 7,
      "y": 17,
      "z": -14,
      "name": "Deco_Salty_Bone_Full"
    },
    {
      "x": 7,
      "y": 16,
      "z": -13,
      "name": "Deco_Salty_Bone_Full"
    },
    {
      "x": 7,
      "y": 19,
      "z": -7,
      "name": "Deco_Salty_Bone_Full"
    },
    {
      "x": 7,
      "y": 20,
      "z": -7,
      "name": "Deco_Salty_Bone_Full"
    },
    {
      "x": 7,
      "y": 18,
      "z": -6,
      "name": "Deco_Salty_Bone_Full"
    },
    {
      "x": 7,
      "y": 19,
      "z": -6,
      "name": "Deco_Salty_Bone_Full"
    },
    {
      "x": 7,
      "y": 20,
      "z": -6,
      "name": "Deco_Salty_Bone_Full"
    },
    {
      "x": 7,
      "y": 21,
      "z": -6,
      "name": "Deco_Salty_Bone_Full"
    },
    {
      "x": 7,
      "y": 22,
      "z": -6,
      "name": "Deco_Salty_Bone_Full"
    },
    {
      "x": 7,
      "y": 23,
      "z": -6,
      "name": "Deco_Salty_Bone_Spike_Large"
    },
    {
      "x": 7,
      "y": 18,
      "z": -5,
      "name": "Deco_Salty_Bone_Full"
    },
    {
      "x": 7,
      "y": 19,
      "z": -5,
      "name": "Deco_Salty_Bone_Full"
    },
    {
      "x": 7,
      "y": 20,
      "z": -5,
      "name": "Deco_Salty_Bone_Full"
    },
    {
      "x": 7,
      "y": 21,
      "z": -5,
      "name": "Deco_Salty_Bone_Full"
    },
    {
      "x": 7,
      "y": 18,
      "z": -4,
      "name": "Deco_Salty_Bone_Full"
    },
    {
      "x": 7,
      "y": 19,
      "z": -4,
      "name": "Deco_Salty_Bone_Full"
    },
    {
      "x": 7,
      "y": 18,
      "z": -3,
      "name": "Deco_Salty_Bone_Full"
    },
    {
      "x": 7,
      "y": 14,
      "z": 5,
      "name": "Deco_Salty_Bone_Full"
    },
    {
      "x": 7,
      "y": 15,
      "z": 5,
      "name": "Deco_Salty_Bone_Full"
    },
    {
      "x": 7,
      "y": 7,
      "z": 6,
      "name": "Deco_Salty_Bone_Full"
    },
    {
      "x": 7,
      "y": 8,
      "z": 6,
      "name": "Deco_Salty_Bone_Full"
    },
    {
      "x": 7,
      "y": 9,
      "z": 6,
      "name": "Deco_Salty_Bone_Full"
    },
    {
      "x": 7,
      "y": 10,
      "z": 6,
      "name": "Deco_Salty_Bone_Full"
    },
    {
      "x": 7,
      "y": 11,
      "z": 6,
      "name": "Deco_Salty_Bone_Full"
    },
    {
      "x": 7,
      "y": 12,
      "z": 6,
      "name": "Deco_Salty_Bone_Full"
    },
    {
      "x": 7,
      "y": 13,
      "z": 6,
      "name": "Deco_Salty_Bone_Full"
    },
    {
      "x": 7,
      "y": 14,
      "z": 6,
      "name": "Deco_Salty_Bone_Full"
    },
    {
      "x": 8,
      "y": 16,
      "z": -14,
      "name": "Deco_Salty_Bone_Full"
    },
    {
      "x": 8,
      "y": 5,
      "z": -13,
      "name": "Deco_Salty_Bone_Full"
    },
    {
      "x": 8,
      "y": 6,
      "z": -13,
      "name": "Deco_Salty_Bone_Full"
    },
    {
      "x": 8,
      "y": 16,
      "z": -13,
      "name": "Deco_Salty_Bone_Full"
    },
    {
      "x": 8,
      "y": 17,
      "z": -13,
      "name": "Deco_Salty_Bone_Full"
    },
    {
      "x": 8,
      "y": 18,
      "z": -13,
      "name": "Deco_Salty_Bone_Full"
    },
    {
      "x": 8,
      "y": 17,
      "z": -12,
      "name": "Deco_Salty_Bone_Full"
    },
    {
      "x": 8,
      "y": 18,
      "z": -8,
      "name": "Deco_Salty_Bone_Full"
    },
    {
      "x": 8,
      "y": 19,
      "z": -8,
      "name": "Deco_Salty_Bone_Full"
    },
    {
      "x": 8,
      "y": 18,
      "z": -7,
      "name": "Deco_Salty_Bone_Full"
    },
    {
      "x": 8,
      "y": 19,
      "z": -7,
      "name": "Deco_Salty_Bone_Full"
    },
    {
      "x": 8,
      "y": 19,
      "z": -6,
      "name": "Deco_Salty_Bone_Full"
    },
    {
      "x": 8,
      "y": 20,
      "z": -6,
      "name": "Deco_Salty_Bone_Full"
    },
    {
      "x": 8,
      "y": 19,
      "z": -5,
      "name": "Deco_Salty_Bone_Full"
    },
    {
      "x": 8,
      "y": 18,
      "z": -4,
      "name": "Deco_Salty_Bone_Full"
    },
    {
      "x": 8,
      "y": 19,
      "z": -4,
      "name": "Deco_Salty_Bone_Full"
    },
    {
      "x": 8,
      "y": 17,
      "z": -3,
      "name": "Deco_Salty_Bone_Full"
    },
    {
      "x": 8,
      "y": 18,
      "z": -3,
      "name": "Deco_Salty_Bone_Full"
    },
    {
      "x": 8,
      "y": 17,
      "z": -2,
      "name": "Deco_Salty_Bone_Full"
    },
    {
      "x": 9,
      "y": 17,
      "z": -13,
      "name": "Deco_Salty_Bone_Full"
    },
    {
      "x": 9,
      "y": 17,
      "z": -12,
      "name": "Deco_Salty_Bone_Full"
    },
    {
      "x": 9,
      "y": 18,
      "z": -12,
      "name": "Deco_Salty_Bone_Full"
    },
    {
      "x": 9,
      "y": 18,
      "z": -11,
      "name": "Deco_Salty_Bone_Full"
    },
    {
      "x": 9,
      "y": 19,
      "z": -10,
      "name": "Deco_Salty_Bone_Full"
    },
    {
      "x": 9,
      "y": 19,
      "z": -9,
      "name": "Deco_Salty_Bone_Full"
    },
    {
      "x": 9,
      "y": 19,
      "z": -8,
      "name": "Deco_Salty_Bone_Full"
    },
    {
      "x": 9,
      "y": 18,
      "z": -7,
      "name": "Deco_Salty_Bone_Full"
    },
    {
      "x": 9,
      "y": 19,
      "z": -7,
      "name": "Deco_Salty_Bone_Full"
    },
    {
      "x": 9,
      "y": 17,
      "z": -3,
      "name": "Deco_Salty_Bone_Full"
    },
    {
      "x": 9,
      "y": 0,
      "z": -2,
      "name": "Deco_Salty_Bone_Full"
    },
    {
      "x": 9,
      "y": 1,
      "z": -2,
      "name": "Deco_Salty_Bone_Full"
    },
    {
      "x": 9,
      "y": 16,
      "z": -2,
      "name": "Deco_Salty_Bone_Full"
    },
    {
      "x": 9,
      "y": 17,
      "z": -2,
      "name": "Deco_Salty_Bone_Full"
    },
    {
      "x": 9,
      "y": 18,
      "z": -2,
      "name": "Deco_Salty_Bone_Full"
    },
    {
      "x": 9,
      "y": 16,
      "z": -1,
      "name": "Deco_Salty_Bone_Full"
    },
    {
      "x": 10,
      "y": 18,
      "z": -12,
      "name": "Deco_Salty_Bone_Full"
    },
    {
      "x": 10,
      "y": 19,
      "z": -12,
      "name": "Deco_Salty_Bone_Full"
    },
    {
      "x": 10,
      "y": 18,
      "z": -11,
      "name": "Deco_Salty_Bone_Full"
    },
    {
      "x": 10,
      "y": 19,
      "z": -11,
      "name": "Deco_Salty_Bone_Full"
    },
    {
      "x": 10,
      "y": 18,
      "z": -10,
      "name": "Deco_Salty_Bone_Full"
    },
    {
      "x": 10,
      "y": 19,
      "z": -10,
      "name": "Deco_Salty_Bone_Full"
    },
    {
      "x": 10,
      "y": 20,
      "z": -10,
      "name": "Deco_Salty_Bone_Full"
    },
    {
      "x": 10,
      "y": 18,
      "z": -9,
      "name": "Deco_Salty_Bone_Full"
    },
    {
      "x": 10,
      "y": 19,
      "z": -9,
      "name": "Deco_Salty_Bone_Full"
    },
    {
      "x": 10,
      "y": 20,
      "z": -9,
      "name": "Deco_Salty_Bone_Full"
    },
    {
      "x": 10,
      "y": 21,
      "z": -9,
      "name": "Deco_Salty_Bone_Full"
    },
    {
      "x": 10,
      "y": 19,
      "z": -8,
      "name": "Deco_Salty_Bone_Full"
    },
    {
      "x": 10,
      "y": 16,
      "z": -2,
      "name": "Deco_Salty_Bone_Full"
    },
    {
      "x": 10,
      "y": 1,
      "z": -1,
      "name": "Deco_Salty_Bone_Full"
    },
    {
      "x": 10,
      "y": 2,
      "z": -1,
      "name": "Deco_Salty_Bone_Full"
    },
    {
      "x": 10,
      "y": 3,
      "z": -1,
      "name": "Deco_Salty_Bone_Full"
    },
    {
      "x": 10,
      "y": 15,
      "z": -1,
      "name": "Deco_Salty_Bone_Full"
    },
    {
      "x": 10,
      "y": 16,
      "z": -1,
      "name": "Deco_Salty_Bone_Full"
    },
    {
      "x": 10,
      "y": 17,
      "z": -1,
      "name": "Deco_Salty_Bone_Full"
    },
    {
      "x": 10,
      "y": 14,
      "z": 0,
      "name": "Deco_Salty_Bone_Full"
    },
    {
      "x": 10,
      "y": 15,
      "z": 0,
      "name": "Deco_Salty_Bone_Full"
    },
    {
      "x": 11,
      "y": 10,
      "z": -20,
      "name": "Deco_Salty_Bone_Full"
    },
    {
      "x": 11,
      "y": 11,
      "z": -20,
      "name": "Deco_Salty_Bone_Full"
    },
    {
      "x": 11,
      "y": 12,
      "z": -20,
      "name": "Deco_Salty_Bone_Full"
    },
    {
      "x": 11,
      "y": 13,
      "z": -20,
      "name": "Deco_Salty_Bone_Full"
    },
    {
      "x": 11,
      "y": 14,
      "z": -20,
      "name": "Deco_Salty_Bone_Full"
    },
    {
      "x": 11,
      "y": 13,
      "z": -19,
      "name": "Deco_Salty_Bone_Full"
    },
    {
      "x": 11,
      "y": 14,
      "z": -19,
      "name": "Deco_Salty_Bone_Full"
    },
    {
      "x": 11,
      "y": 19,
      "z": -12,
      "name": "Deco_Salty_Bone_Full"
    },
    {
      "x": 11,
      "y": 18,
      "z": -11,
      "name": "Deco_Salty_Bone_Full"
    },
    {
      "x": 11,
      "y": 19,
      "z": -11,
      "name": "Deco_Salty_Bone_Full"
    },
    {
      "x": 11,
      "y": 20,
      "z": -11,
      "name": "Deco_Salty_Bone_Full"
    },
    {
      "x": 11,
      "y": 21,
      "z": -11,
      "name": "Deco_Salty_Bone_Full"
    },
    {
      "x": 11,
      "y": 18,
      "z": -10,
      "name": "Deco_Salty_Bone_Full"
    },
    {
      "x": 11,
      "y": 19,
      "z": -10,
      "name": "Deco_Salty_Bone_Full"
    },
    {
      "x": 11,
      "y": 20,
      "z": -10,
      "name": "Deco_Salty_Bone_Full"
    },
    {
      "x": 11,
      "y": 21,
      "z": -10,
      "name": "Deco_Salty_Bone_Full"
    },
    {
      "x": 11,
      "y": 22,
      "z": -10,
      "name": "Deco_Salty_Bone_Full"
    },
    {
      "x": 11,
      "y": 23,
      "z": -10,
      "name": "Deco_Salty_Bone_Spike"
    },
    {
      "x": 11,
      "y": 18,
      "z": -9,
      "name": "Deco_Salty_Bone_Full"
    },
    {
      "x": 11,
      "y": 19,
      "z": -9,
      "name": "Deco_Salty_Bone_Full"
    },
    {
      "x": 11,
      "y": 20,
      "z": -9,
      "name": "Deco_Salty_Bone_Full"
    },
    {
      "x": 11,
      "y": 19,
      "z": -8,
      "name": "Deco_Salty_Bone_Full"
    },
    {
      "x": 11,
      "y": 14,
      "z": -1,
      "name": "Deco_Salty_Bone_Full"
    },
    {
      "x": 11,
      "y": 15,
      "z": -1,
      "name": "Deco_Salty_Bone_Full"
    },
    {
      "x": 11,
      "y": 3,
      "z": 0,
      "name": "Deco_Salty_Bone_Full"
    },
    {
      "x": 11,
      "y": 4,
      "z": 0,
      "name": "Deco_Salty_Bone_Full"
    },
    {
      "x": 11,
      "y": 5,
      "z": 0,
      "name": "Deco_Salty_Bone_Full"
    },
    {
      "x": 11,
      "y": 6,
      "z": 0,
      "name": "Deco_Salty_Bone_Full"
    },
    {
      "x": 11,
      "y": 12,
      "z": 0,
      "name": "Deco_Salty_Bone_Full"
    },
    {
      "x": 11,
      "y": 13,
      "z": 0,
      "name": "Deco_Salty_Bone_Full"
    },
    {
      "x": 11,
      "y": 14,
      "z": 0,
      "name": "Deco_Salty_Bone_Full"
    },
    {
      "x": 11,
      "y": 15,
      "z": 0,
      "name": "Deco_Salty_Bone_Full"
    },
    {
      "x": 11,
      "y": 16,
      "z": 0,
      "name": "Deco_Salty_Bone_Full"
    },
    {
      "x": 11,
      "y": 13,
      "z": 1,
      "name": "Deco_Salty_Bone_Full"
    },
    {
      "x": 11,
      "y": 14,
      "z": 1,
      "name": "Deco_Salty_Bone_Full"
    },
    {
      "x": 12,
      "y": 13,
      "z": -20,
      "name": "Deco_Salty_Bone_Full"
    },
    {
      "x": 12,
      "y": 14,
      "z": -20,
      "name": "Deco_Salty_Bone_Full"
    },
    {
      "x": 12,
      "y": 8,
      "z": -19,
      "name": "Deco_Salty_Bone_Full"
    },
    {
      "x": 12,
      "y": 9,
      "z": -19,
      "name": "Deco_Salty_Bone_Full"
    },
    {
      "x": 12,
      "y": 10,
      "z": -19,
      "name": "Deco_Salty_Bone_Full"
    },
    {
      "x": 12,
      "y": 14,
      "z": -19,
      "name": "Deco_Salty_Bone_Full"
    },
    {
      "x": 12,
      "y": 15,
      "z": -19,
      "name": "Deco_Salty_Bone_Full"
    },
    {
      "x": 12,
      "y": 16,
      "z": -19,
      "name": "Deco_Salty_Bone_Full"
    },
    {
      "x": 12,
      "y": 15,
      "z": -18,
      "name": "Deco_Salty_Bone_Full"
    },
    {
      "x": 12,
      "y": 19,
      "z": -12,
      "name": "Deco_Salty_Bone_Full"
    },
    {
      "x": 12,
      "y": 20,
      "z": -12,
      "name": "Deco_Salty_Bone_Full"
    },
    {
      "x": 12,
      "y": 18,
      "z": -11,
      "name": "Deco_Salty_Bone_Full"
    },
    {
      "x": 12,
      "y": 19,
      "z": -11,
      "name": "Deco_Salty_Bone_Full"
    },
    {
      "x": 12,
      "y": 20,
      "z": -11,
      "name": "Deco_Salty_Bone_Full"
    },
    {
      "x": 12,
      "y": 21,
      "z": -11,
      "name": "Deco_Salty_Bone_Full"
    },
    {
      "x": 12,
      "y": 22,
      "z": -11,
      "name": "Deco_Salty_Bone_Full"
    },
    {
      "x": 12,
      "y": 18,
      "z": -10,
      "name": "Deco_Salty_Bone_Full"
    },
    {
      "x": 12,
      "y": 19,
      "z": -10,
      "name": "Deco_Salty_Bone_Full"
    },
    {
      "x": 12,
      "y": 20,
      "z": -10,
      "name": "Deco_Salty_Bone_Full"
    },
    {
      "x": 12,
      "y": 21,
      "z": -10,
      "name": "Deco_Salty_Bone_Full"
    },
    {
      "x": 12,
      "y": 18,
      "z": -9,
      "name": "Deco_Salty_Bone_Full"
    },
    {
      "x": 12,
      "y": 19,
      "z": -9,
      "name": "Deco_Salty_Bone_Full"
    },
    {
      "x": 12,
      "y": 18,
      "z": -8,
      "name": "Deco_Salty_Bone_Full"
    },
    {
      "x": 12,
      "y": 13,
      "z": 0,
      "name": "Deco_Salty_Bone_Full"
    },
    {
      "x": 12,
      "y": 14,
      "z": 0,
      "name": "Deco_Salty_Bone_Full"
    },
    {
      "x": 12,
      "y": 6,
      "z": 1,
      "name": "Deco_Salty_Bone_Full"
    },
    {
      "x": 12,
      "y": 7,
      "z": 1,
      "name": "Deco_Salty_Bone_Full"
    },
    {
      "x": 12,
      "y": 8,
      "z": 1,
      "name": "Deco_Salty_Bone_Full"
    },
    {
      "x": 12,
      "y": 9,
      "z": 1,
      "name": "Deco_Salty_Bone_Full"
    },
    {
      "x": 12,
      "y": 10,
      "z": 1,
      "name": "Deco_Salty_Bone_Full"
    },
    {
      "x": 12,
      "y": 11,
      "z": 1,
      "name": "Deco_Salty_Bone_Full"
    },
    {
      "x": 12,
      "y": 12,
      "z": 1,
      "name": "Deco_Salty_Bone_Full"
    },
    {
      "x": 12,
      "y": 13,
      "z": 1,
      "name": "Deco_Salty_Bone_Full"
    },
    {
      "x": 13,
      "y": 15,
      "z": -19,
      "name": "Deco_Salty_Bone_Full"
    },
    {
      "x": 13,
      "y": 7,
      "z": -18,
      "name": "Deco_Salty_Bone_Full"
    },
    {
      "x": 13,
      "y": 8,
      "z": -18,
      "name": "Deco_Salty_Bone_Full"
    },
    {
      "x": 13,
      "y": 15,
      "z": -18,
      "name": "Deco_Salty_Bone_Full"
    },
    {
      "x": 13,
      "y": 16,
      "z": -18,
      "name": "Deco_Salty_Bone_Full"
    },
    {
      "x": 13,
      "y": 17,
      "z": -18,
      "name": "Deco_Salty_Bone_Full"
    },
    {
      "x": 13,
      "y": 16,
      "z": -17,
      "name": "Deco_Salty_Bone_Full"
    },
    {
      "x": 13,
      "y": 17,
      "z": -13,
      "name": "Deco_Salty_Bone_Full"
    },
    {
      "x": 13,
      "y": 18,
      "z": -13,
      "name": "Deco_Salty_Bone_Full"
    },
    {
      "x": 13,
      "y": 17,
      "z": -12,
      "name": "Deco_Salty_Bone_Full"
    },
    {
      "x": 13,
      "y": 18,
      "z": -12,
      "name": "Deco_Salty_Bone_Full"
    },
    {
      "x": 13,
      "y": 19,
      "z": -11,
      "name": "Deco_Salty_Bone_Full"
    },
    {
      "x": 13,
      "y": 20,
      "z": -11,
      "name": "Deco_Salty_Bone_Full"
    },
    {
      "x": 13,
      "y": 19,
      "z": -10,
      "name": "Deco_Salty_Bone_Full"
    },
    {
      "x": 13,
      "y": 18,
      "z": -9,
      "name": "Deco_Salty_Bone_Full"
    },
    {
      "x": 13,
      "y": 19,
      "z": -9,
      "name": "Deco_Salty_Bone_Full"
    },
    {
      "x": 13,
      "y": 17,
      "z": -8,
      "name": "Deco_Salty_Bone_Full"
    },
    {
      "x": 13,
      "y": 18,
      "z": -8,
      "name": "Deco_Salty_Bone_Full"
    },
    {
      "x": 13,
      "y": 17,
      "z": -7,
      "name": "Deco_Salty_Bone_Full"
    },
    {
      "x": 14,
      "y": 16,
      "z": -18,
      "name": "Deco_Salty_Bone_Full"
    },
    {
      "x": 14,
      "y": 7,
      "z": -17,
      "name": "Deco_Salty_Bone_Full"
    },
    {
      "x": 14,
      "y": 16,
      "z": -17,
      "name": "Deco_Salty_Bone_Full"
    },
    {
      "x": 14,
      "y": 17,
      "z": -17,
      "name": "Deco_Salty_Bone_Full"
    },
    {
      "x": 14,
      "y": 17,
      "z": -16,
      "name": "Deco_Salty_Bone_Full"
    },
    {
      "x": 14,
      "y": 18,
      "z": -15,
      "name": "Deco_Salty_Bone_Full"
    },
    {
      "x": 14,
      "y": 18,
      "z": -14,
      "name": "Deco_Salty_Bone_Full"
    },
    {
      "x": 14,
      "y": 18,
      "z": -13,
      "name": "Deco_Salty_Bone_Full"
    },
    {
      "x": 14,
      "y": 17,
      "z": -12,
      "name": "Deco_Salty_Bone_Full"
    },
    {
      "x": 14,
      "y": 18,
      "z": -12,
      "name": "Deco_Salty_Bone_Full"
    },
    {
      "x": 14,
      "y": 17,
      "z": -8,
      "name": "Deco_Salty_Bone_Full"
    },
    {
      "x": 14,
      "y": 5,
      "z": -7,
      "name": "Deco_Salty_Bone_Full"
    },
    {
      "x": 14,
      "y": 6,
      "z": -7,
      "name": "Deco_Salty_Bone_Full"
    },
    {
      "x": 14,
      "y": 16,
      "z": -7,
      "name": "Deco_Salty_Bone_Full"
    },
    {
      "x": 14,
      "y": 17,
      "z": -7,
      "name": "Deco_Salty_Bone_Full"
    },
    {
      "x": 14,
      "y": 18,
      "z": -7,
      "name": "Deco_Salty_Bone_Full"
    },
    {
      "x": 14,
      "y": 16,
      "z": -6,
      "name": "Deco_Salty_Bone_Full"
    },
    {
      "x": 15,
      "y": 17,
      "z": -17,
      "name": "Deco_Salty_Bone_Full"
    },
    {
      "x": 15,
      "y": 18,
      "z": -17,
      "name": "Deco_Salty_Bone_Full"
    },
    {
      "x": 15,
      "y": 17,
      "z": -16,
      "name": "Deco_Salty_Bone_Full"
    },
    {
      "x": 15,
      "y": 18,
      "z": -16,
      "name": "Deco_Salty_Bone_Full"
    },
    {
      "x": 15,
      "y": 17,
      "z": -15,
      "name": "Deco_Salty_Bone_Full"
    },
    {
      "x": 15,
      "y": 18,
      "z": -15,
      "name": "Deco_Salty_Bone_Full"
    },
    {
      "x": 15,
      "y": 19,
      "z": -15,
      "name": "Deco_Salty_Bone_Full"
    },
    {
      "x": 15,
      "y": 17,
      "z": -14,
      "name": "Deco_Salty_Bone_Full"
    },
    {
      "x": 15,
      "y": 18,
      "z": -14,
      "name": "Deco_Salty_Bone_Full"
    },
    {
      "x": 15,
      "y": 19,
      "z": -14,
      "name": "Deco_Salty_Bone_Full"
    },
    {
      "x": 15,
      "y": 20,
      "z": -14,
      "name": "Deco_Salty_Bone_Full"
    },
    {
      "x": 15,
      "y": 18,
      "z": -13,
      "name": "Deco_Salty_Bone_Full"
    },
    {
      "x": 15,
      "y": 16,
      "z": -7,
      "name": "Deco_Salty_Bone_Full"
    },
    {
      "x": 15,
      "y": 6,
      "z": -6,
      "name": "Deco_Salty_Bone_Full"
    },
    {
      "x": 15,
      "y": 7,
      "z": -6,
      "name": "Deco_Salty_Bone_Full"
    },
    {
      "x": 15,
      "y": 8,
      "z": -6,
      "name": "Deco_Salty_Bone_Full"
    },
    {
      "x": 15,
      "y": 9,
      "z": -6,
      "name": "Deco_Salty_Bone_Full"
    },
    {
      "x": 15,
      "y": 15,
      "z": -6,
      "name": "Deco_Salty_Bone_Full"
    },
    {
      "x": 15,
      "y": 16,
      "z": -6,
      "name": "Deco_Salty_Bone_Full"
    },
    {
      "x": 15,
      "y": 17,
      "z": -6,
      "name": "Deco_Salty_Bone_Full"
    },
    {
      "x": 15,
      "y": 14,
      "z": -5,
      "name": "Deco_Salty_Bone_Full"
    },
    {
      "x": 15,
      "y": 15,
      "z": -5,
      "name": "Deco_Salty_Bone_Full"
    },
    {
      "x": 16,
      "y": 18,
      "z": -17,
      "name": "Deco_Salty_Bone_Full"
    },
    {
      "x": 16,
      "y": 17,
      "z": -16,
      "name": "Deco_Salty_Bone_Full"
    },
    {
      "x": 16,
      "y": 18,
      "z": -16,
      "name": "Deco_Salty_Bone_Full"
    },
    {
      "x": 16,
      "y": 19,
      "z": -16,
      "name": "Deco_Salty_Bone_Full"
    },
    {
      "x": 16,
      "y": 20,
      "z": -16,
      "name": "Deco_Salty_Bone_Full"
    },
    {
      "x": 16,
      "y": 17,
      "z": -15,
      "name": "Deco_Salty_Bone_Full"
    },
    {
      "x": 16,
      "y": 18,
      "z": -15,
      "name": "Deco_Salty_Bone_Full"
    },
    {
      "x": 16,
      "y": 19,
      "z": -15,
      "name": "Deco_Salty_Bone_Full"
    },
    {
      "x": 16,
      "y": 20,
      "z": -15,
      "name": "Deco_Salty_Bone_Full"
    },
    {
      "x": 16,
      "y": 21,
      "z": -15,
      "name": "Deco_Salty_Bone_Full"
    },
    {
      "x": 16,
      "y": 22,
      "z": -15,
      "name": "Deco_Salty_Bone_Spike"
    },
    {
      "x": 16,
      "y": 17,
      "z": -14,
      "name": "Deco_Salty_Bone_Full"
    },
    {
      "x": 16,
      "y": 18,
      "z": -14,
      "name": "Deco_Salty_Bone_Full"
    },
    {
      "x": 16,
      "y": 19,
      "z": -14,
      "name": "Deco_Salty_Bone_Full"
    },
    {
      "x": 16,
      "y": 18,
      "z": -13,
      "name": "Deco_Salty_Bone_Full"
    },
    {
      "x": 16,
      "y": 14,
      "z": -6,
      "name": "Deco_Salty_Bone_Full"
    },
    {
      "x": 16,
      "y": 15,
      "z": -6,
      "name": "Deco_Salty_Bone_Full"
    },
    {
      "x": 16,
      "y": 8,
      "z": -5,
      "name": "Deco_Salty_Bone_Full"
    },
    {
      "x": 16,
      "y": 9,
      "z": -5,
      "name": "Deco_Salty_Bone_Full"
    },
    {
      "x": 16,
      "y": 10,
      "z": -5,
      "name": "Deco_Salty_Bone_Full"
    },
    {
      "x": 16,
      "y": 11,
      "z": -5,
      "name": "Deco_Salty_Bone_Full"
    },
    {
      "x": 16,
      "y": 12,
      "z": -5,
      "name": "Deco_Salty_Bone_Full"
    },
    {
      "x": 16,
      "y": 13,
      "z": -5,
      "name": "Deco_Salty_Bone_Full"
    },
    {
      "x": 16,
      "y": 14,
      "z": -5,
      "name": "Deco_Salty_Bone_Full"
    },
    {
      "x": 17,
      "y": 18,
      "z": -17,
      "name": "Deco_Salty_Bone_Full"
    },
    {
      "x": 17,
      "y": 19,
      "z": -17,
      "name": "Deco_Salty_Bone_Full"
    },
    {
      "x": 17,
      "y": 17,
      "z": -16,
      "name": "Deco_Salty_Bone_Full"
    },
    {
      "x": 17,
      "y": 18,
      "z": -16,
      "name": "Deco_Salty_Bone_Full"
    },
    {
      "x": 17,
      "y": 19,
      "z": -16,
      "name": "Deco_Salty_Bone_Full"
    },
    {
      "x": 17,
      "y": 20,
      "z": -16,
      "name": "Deco_Salty_Bone_Full"
    },
    {
      "x": 17,
      "y": 21,
      "z": -16,
      "name": "Deco_Salty_Bone_Full"
    },
    {
      "x": 17,
      "y": 17,
      "z": -15,
      "name": "Deco_Salty_Bone_Full"
    },
    {
      "x": 17,
      "y": 18,
      "z": -15,
      "name": "Deco_Salty_Bone_Full"
    },
    {
      "x": 17,
      "y": 19,
      "z": -15,
      "name": "Deco_Salty_Bone_Full"
    },
    {
      "x": 17,
      "y": 20,
      "z": -15,
      "name": "Deco_Salty_Bone_Full"
    },
    {
      "x": 17,
      "y": 17,
      "z": -14,
      "name": "Deco_Salty_Bone_Full"
    },
    {
      "x": 17,
      "y": 18,
      "z": -14,
      "name": "Deco_Salty_Bone_Full"
    },
    {
      "x": 17,
      "y": 17,
      "z": -13,
      "name": "Deco_Salty_Bone_Full"
    },
    {
      "x": 18,
      "y": 16,
      "z": -18,
      "name": "Deco_Salty_Bone_Full"
    },
    {
      "x": 18,
      "y": 17,
      "z": -18,
      "name": "Deco_Salty_Bone_Full"
    },
    {
      "x": 18,
      "y": 16,
      "z": -17,
      "name": "Deco_Salty_Bone_Full"
    },
    {
      "x": 18,
      "y": 17,
      "z": -17,
      "name": "Deco_Salty_Bone_Full"
    },
    {
      "x": 18,
      "y": 18,
      "z": -16,
      "name": "Deco_Salty_Bone_Full"
    },
    {
      "x": 18,
      "y": 19,
      "z": -16,
      "name": "Deco_Salty_Bone_Full"
    },
    {
      "x": 18,
      "y": 18,
      "z": -15,
      "name": "Deco_Salty_Bone_Full"
    },
    {
      "x": 18,
      "y": 17,
      "z": -14,
      "name": "Deco_Salty_Bone_Full"
    },
    {
      "x": 18,
      "y": 18,
      "z": -14,
      "name": "Deco_Salty_Bone_Full"
    },
    {
      "x": 18,
      "y": 7,
      "z": -13,
      "name": "Deco_Salty_Bone_Full"
    },
    {
      "x": 18,
      "y": 16,
      "z": -13,
      "name": "Deco_Salty_Bone_Full"
    },
    {
      "x": 18,
      "y": 17,
      "z": -13,
      "name": "Deco_Salty_Bone_Full"
    },
    {
      "x": 18,
      "y": 16,
      "z": -12,
      "name": "Deco_Salty_Bone_Full"
    },
    {
      "x": 19,
      "y": 16,
      "z": -19,
      "name": "Deco_Salty_Bone_Full"
    },
    {
      "x": 19,
      "y": 17,
      "z": -19,
      "name": "Deco_Salty_Bone_Full"
    },
    {
      "x": 19,
      "y": 16,
      "z": -18,
      "name": "Deco_Salty_Bone_Full"
    },
    {
      "x": 19,
      "y": 17,
      "z": -18,
      "name": "Deco_Salty_Bone_Full"
    },
    {
      "x": 19,
      "y": 18,
      "z": -18,
      "name": "Deco_Salty_Bone_Spike"
    },
    {
      "x": 19,
      "y": 16,
      "z": -17,
      "name": "Deco_Salty_Bone_Full"
    },
    {
      "x": 19,
      "y": 17,
      "z": -17,
      "name": "Deco_Salty_Bone_Full"
    },
    {
      "x": 19,
      "y": 16,
      "z": -13,
      "name": "Deco_Salty_Bone_Full"
    },
    {
      "x": 19,
      "y": 7,
      "z": -12,
      "name": "Deco_Salty_Bone_Full"
    },
    {
      "x": 19,
      "y": 8,
      "z": -12,
      "name": "Deco_Salty_Bone_Full"
    },
    {
      "x": 19,
      "y": 15,
      "z": -12,
      "name": "Deco_Salty_Bone_Full"
    },
    {
      "x": 19,
      "y": 16,
      "z": -12,
      "name": "Deco_Salty_Bone_Full"
    },
    {
      "x": 19,
      "y": 17,
      "z": -12,
      "name": "Deco_Salty_Bone_Full"
    },
    {
      "x": 19,
      "y": 15,
      "z": -11,
      "name": "Deco_Salty_Bone_Full"
    },
    {
      "x": 20,
      "y": 16,
      "z": -19,
      "name": "Deco_Salty_Bone_Full"
    },
    {
      "x": 20,
      "y": 17,
      "z": -19,
      "name": "Deco_Salty_Bone_Full"
    },
    {
      "x": 20,
      "y": 16,
      "z": -18,
      "name": "Deco_Salty_Bone_Full"
    },
    {
      "x": 20,
      "y": 17,
      "z": -18,
      "name": "Deco_Salty_Bone_Full"
    },
    {
      "x": 20,
      "y": 15,
      "z": -12,
      "name": "Deco_Salty_Bone_Full"
    },
    {
      "x": 20,
      "y": 8,
      "z": -11,
      "name": "Deco_Salty_Bone_Full"
    },
    {
      "x": 20,
      "y": 9,
      "z": -11,
      "name": "Deco_Salty_Bone_Full"
    },
    {
      "x": 20,
      "y": 10,
      "z": -11,
      "name": "Deco_Salty_Bone_Full"
    },
    {
      "x": 20,
      "y": 14,
      "z": -11,
      "name": "Deco_Salty_Bone_Full"
    },
    {
      "x": 20,
      "y": 15,
      "z": -11,
      "name": "Deco_Salty_Bone_Full"
    },
    {
      "x": 20,
      "y": 16,
      "z": -11,
      "name": "Deco_Salty_Bone_Full"
    },
    {
      "x": 20,
      "y": 13,
      "z": -10,
      "name": "Deco_Salty_Bone_Full"
    },
    {
      "x": 20,
      "y": 14,
      "z": -10,
      "name": "Deco_Salty_Bone_Full"
    },
    {
      "x": 21,
      "y": 13,
      "z": -11,
      "name": "Deco_Salty_Bone_Full"
    },
    {
      "x": 21,
      "y": 14,
      "z": -11,
      "name": "Deco_Salty_Bone_Full"
    },
    {
      "x": 21,
      "y": 10,
      "z": -10,
      "name": "Deco_Salty_Bone_Full"
    },
    {
      "x": 21,
      "y": 11,
      "z": -10,
      "name": "Deco_Salty_Bone_Full"
    },
    {
      "x": 21,
      "y": 12,
      "z": -10,
      "name": "Deco_Salty_Bone_Full"
    },
    {
      "x": 21,
      "y": 13,
      "z": -10,
      "name": "Deco_Salty_Bone_Full"
    },
    {
      "x": 21,
      "y": 14,
      "z": -10,
      "name": "Deco_Salty_Bone_Full"
    }
  ]
}