{
  "version": 8,
  "blockIdVersion": 10,
  "anchorX": 2,
  "anchorY": 9,
  "anchorZ": 1,
  "blocks": [
    {
      "x": -25,
      "y": 13,
      "z": 25,
      "name": "Deco_Salty_Bone_Full"
    },
    {
      "x": -25,
      "y": 13,
      "z": 26,
      "name": "Deco_Salty_Bone_Full"
    },
    {
      "x": -24,
      "y": 7,
      "z": 19,
      "name": "Deco_Salty_Bone_Full"
    },
    {
      "x": -24,
      "y": 8,
      "z": 19,
      "name": "Deco_Salty_Bone_Full"
    },
    {
      "x": -24,
      "y": 9,
      "z": 19,
      "name": "Deco_Salty_Bone_Full"
    },
    {
      "x": -24,
      "y": 10,
      "z": 19,
      "name": "Deco_Salty_Bone_Full"
    },
    {
      "x": -24,
      "y": 11,
      "z": 19,
      "name": "Deco_Salty_Bone_Full"
    },
    {
      "x": -24,
      "y": 12,
      "z": 19,
      "name": "Deco_Salty_Bone_Full"
    },
    {
      "x": -24,
      "y": 12,
      "z": 20,
      "name": "Deco_Salty_Bone_Full"
    },
    {
      "x": -24,
      "y": 13,
      "z": 24,
      "name": "Deco_Salty_Bone_Full"
    },
    {
      "x": -24,
      "y": 13,
      "z": 25,
      "name": "Deco_Salty_Bone_Full"
    },
    {
      "x": -24,
      "y": 14,
      "z": 25,
      "name": "Deco_Salty_Bone_Full"
    },
    {
      "x": -24,
      "y": 15,
      "z": 25,
      "name": "Deco_Salty_Bone_Spike"
    },
    {
      "x": -24,
      "y": 13,
      "z": 26,
      "name": "Deco_Salty_Bone_Full"
    },
    {
      "x": -23,
      "y": 12,
      "z": 19,
      "name": "Deco_Salty_Bone_Full"
    },
    {
      "x": -23,
      "y": 6,
      "z": 20,
      "name": "Deco_Salty_Bone_Full"
    },
    {
      "x": -23,
      "y": 7,
      "z": 20,
      "name": "Deco_Salty_Bone_Full"
    },
    {
      "x": -23,
      "y": 12,
      "z": 20,
      "name": "Deco_Salty_Bone_Full"
    },
    {
      "x": -23,
      "y": 13,
      "z": 20,
      "name": "Deco_Salty_Bone_Full"
    },
    {
      "x": -23,
      "y": 13,
      "z": 21,
      "name": "Deco_Salty_Bone_Full"
    },
    {
      "x": -23,
      "y": 14,
      "z": 21,
      "name": "Deco_Salty_Bone_Full"
    },
    {
      "x": -23,
      "y": 14,
      "z": 23,
      "name": "Deco_Salty_Bone_Full"
    },
    {
      "x": -23,
      "y": 13,
      "z": 24,
      "name": "Deco_Salty_Bone_Full"
    },
    {
      "x": -23,
      "y": 14,
      "z": 24,
      "name": "Deco_Salty_Bone_Full"
    },
    {
      "x": -23,
      "y": 13,
      "z": 25,
      "name": "Deco_Salty_Bone_Full"
    },
    {
      "x": -22,
      "y": 6,
      "z": 13,
      "name": "Deco_Salty_Bone_Full"
    },
    {
      "x": -22,
      "y": 7,
      "z": 13,
      "name": "Deco_Salty_Bone_Full"
    },
    {
      "x": -22,
      "y": 8,
      "z": 13,
      "name": "Deco_Salty_Bone_Full"
    },
    {
      "x": -22,
      "y": 9,
      "z": 13,
      "name": "Deco_Salty_Bone_Full"
    },
    {
      "x": -22,
      "y": 10,
      "z": 13,
      "name": "Deco_Salty_Bone_Full"
    },
    {
      "x": -22,
      "y": 11,
      "z": 13,
      "name": "Deco_Salty_Bone_Full"
    },
    {
      "x": -22,
      "y": 12,
      "z": 13,
      "name": "Deco_Salty_Bone_Full"
    },
    {
      "x": -22,
      "y": 12,
      "z": 14,
      "name": "Deco_Salty_Bone_Full"
    },
    {
      "x": -22,
      "y": 13,
      "z": 20,
      "name": "Deco_Salty_Bone_Full"
    },
    {
      "x": -22,
      "y": 14,
      "z": 20,
      "name": "Deco_Salty_Bone_Full"
    },
    {
      "x": -22,
      "y": 13,
      "z": 21,
      "name": "Deco_Salty_Bone_Full"
    },
    {
      "x": -22,
      "y": 14,
      "z": 21,
      "name": "Deco_Salty_Bone_Full"
    },
    {
      "x": -22,
      "y": 15,
      "z": 21,
      "name": "Deco_Salty_Bone_Full"
    },
    {
      "x": -22,
      "y": 13,
      "z": 22,
      "name": "Deco_Salty_Bone_Full"
    },
    {
      "x": -22,
      "y": 14,
      "z": 22,
      "name": "Deco_Salty_Bone_Full"
    },
    {
      "x": -22,
      "y": 15,
      "z": 22,
      "name": "Deco_Salty_Bone_Full"
    },
    {
      "x": -22,
      "y": 16,
      "z": 22,
      "name": "Deco_Salty_Bone_Full"
    },
    {
      "x": -22,
      "y": 13,
      "z": 23,
      "name": "Deco_Salty_Bone_Full"
    },
    {
      "x": -22,
      "y": 14,
      "z": 23,
      "name": "Deco_Salty_Bone_Full"
    },
    {
      "x": -22,
      "y": 15,
      "z": 23,
      "name": "Deco_Salty_Bone_Full"
    },
    {
      "x": -22,
      "y": 16,
      "z": 23,
      "name": "Deco_Salty_Bone_Full"
    },
    {
      "x": -22,
      "y": 17,
      "z": 23,
      "name": "Deco_Salty_Bone_Full"
    },
    {
      "x": -22,
      "y": 14,
      "z": 24,
      "name": "Deco_Salty_Bone_Full"
    },
    {
      "x": -21,
      "y": 12,
      "z": 13,
      "name": "Deco_Salty_Bone_Full"
    },
    {
      "x": -21,
      "y": 4,
      "z": 14,
      "name": "Deco_Salty_Bone_Full"
    },
    {
      "x": -21,
      "y": 5,
      "z": 14,
      "name": "Deco_Salty_Bone_Full"
    },
    {
      "x": -21,
      "y": 6,
      "z": 14,
      "name": "Deco_Salty_Bone_Full"
    },
    {
      "x": -21,
      "y": 12,
      "z": 14,
      "name": "Deco_Salty_Bone_Full"
    },
    {
      "x": -21,
      "y": 13,
      "z": 14,
      "name": "Deco_Salty_Bone_Full"
    },
    {
      "x": -21,
      "y": 13,
      "z": 15,
      "name": "Deco_Salty_Bone_Full"
    },
    {
      "x": -21,
      "y": 14,
      "z": 20,
      "name": "Deco_Salty_Bone_Full"
    },
    {
      "x": -21,
      "y": 13,
      "z": 21,
      "name": "Deco_Salty_Bone_Full"
    },
    {
      "x": -21,
      "y": 14,
      "z": 21,
      "name": "Deco_Salty_Bone_Full"
    },
    {
      "x": -21,
      "y": 15,
      "z": 21,
      "name": "Deco_Salty_Bone_Full"
    },
    {
      "x": -21,
      "y": 16,
      "z": 21,
      "name": "Deco_Salty_Bone_Full"
    },
    {
      "x": -21,
      "y": 12,
      "z": 22,
      "name": "Deco_Salty_Bone_Full"
    },
    {
      "x": -21,
      "y": 13,
      "z": 22,
      "name": "Deco_Salty_Bone_Full"
    },
    {
      "x": -21,
      "y": 14,
      "z": 22,
      "name": "Deco_Salty_Bone_Full"
    },
    {
      "x": -21,
      "y": 15,
      "z": 22,
      "name": "Deco_Salty_Bone_Full"
    },
    {
      "x": -21,
      "y": 16,
      "z": 22,
      "name": "Deco_Salty_Bone_Full"
    },
    {
      "x": -21,
      "y": 17,
      "z": 22,
      "name": "Deco_Salty_Bone_Full"
    },
    {
      "x": -21,
      "y": 18,
      "z": 22,
      "name": "Deco_Salty_Bone_Full"
    },
    {
      "x": -21,
      "y": 19,
      "z": 22,
      "name": "Deco_Salty_Bone_Spike"
    },
    {
      "x": -21,
      "y": 13,
      "z": 23,
      "name": "Deco_Salty_Bone_Full"
    },
    {
      "x": -21,
      "y": 14,
      "z": 23,
      "name": "Deco_Salty_Bone_Full"
    },
    {
      "x": -21,
      "y": 15,
      "z": 23,
      "name": "Deco_Salty_Bone_Full"
    },
    {
      "x": -21,
      "y": 16,
      "z": 23,
      "name": "Deco_Salty_Bone_Full"
    },
    {
      "x": -20,
      "y": 13,
      "z": 14,
      "name": "Deco_Salty_Bone_Full"
    },
    {
      "x": -20,
      "y": 3,
      "z": 15,
      "name": "Deco_Salty_Bone_Full"
    },
    {
      "x": -20,
      "y": 4,
      "z": 15,
      "name": "Deco_Salty_Bone_Full"
    },
    {
      "x": -20,
      "y": 13,
      "z": 15,
      "name": "Deco_Salty_Bone_Full"
    },
    {
      "x": -20,
      "y": 14,
      "z": 15,
      "name": "Deco_Salty_Bone_Full"
    },
    {
      "x": -20,
      "y": 14,
      "z": 16,
      "name": "Deco_Salty_Bone_Full"
    },
    {
      "x": -20,
      "y": 15,
      "z": 20,
      "name": "Deco_Salty_Bone_Full"
    },
    {
      "x": -20,
      "y": 14,
      "z": 21,
      "name": "Deco_Salty_Bone_Full"
    },
    {
      "x": -20,
      "y": 15,
      "z": 21,
      "name": "Deco_Salty_Bone_Full"
    },
    {
      "x": -20,
      "y": 16,
      "z": 21,
      "name": "Deco_Salty_Bone_Full"
    },
    {
      "x": -20,
      "y": 17,
      "z": 21,
      "name": "Deco_Salty_Bone_Full"
    },
    {
      "x": -20,
      "y": 18,
      "z": 21,
      "name": "Deco_Salty_Bone_Full"
    },
    {
      "x": -20,
      "y": 13,
      "z": 22,
      "name": "Deco_Salty_Bone_Full"
    },
    {
      "x": -20,
      "y": 14,
      "z": 22,
      "name": "Deco_Salty_Bone_Full"
    },
    {
      "x": -20,
      "y": 15,
      "z": 22,
      "name": "Deco_Salty_Bone_Full"
    },
    {
      "x": -20,
      "y": 16,
      "z": 22,
      "name": "Deco_Salty_Bone_Full"
    },
    {
      "x": -20,
      "y": 13,
      "z": 23,
      "name": "Deco_Salty_Bone_Full"
    },
    {
      "x": -20,
      "y": 14,
      "z": 23,
      "name": "Deco_Salty_Bone_Full"
    },
    {
      "x": -20,
      "y": 15,
      "z": 23,
      "name": "Deco_Salty_Bone_Full"
    },
    {
      "x": -20,
      "y": 13,
      "z": 24,
      "name": "Deco_Salty_Bone_Full"
    },
    {
      "x": -20,
      "y": 14,
      "z": 24,
      "name": "Deco_Salty_Bone_Full"
    },
    {
      "x": -19,
      "y": 1,
      "z": 8,
      "name": "Deco_Salty_Bone_Full"
    },
    {
      "x": -19,
      "y": 2,
      "z": 8,
      "name": "Deco_Salty_Bone_Full"
    },
    {
      "x": -19,
      "y": 3,
      "z": 8,
      "name": "Deco_Salty_Bone_Full"
    },
    {
      "x": -19,
      "y": 4,
      "z": 8,
      "name": "Deco_Salty_Bone_Full"
    },
    {
      "x": -19,
      "y": 5,
      "z": 8,
      "name": "Deco_Salty_Bone_Full"
    },
    {
      "x": -19,
      "y": 6,
      "z": 8,
      "name": "Deco_Salty_Bone_Full"
    },
    {
      "x": -19,
      "y": 7,
      "z": 8,
      "name": "Deco_Salty_Bone_Full"
    },
    {
      "x": -19,
      "y": 8,
      "z": 8,
      "name": "Deco_Salty_Bone_Full"
    },
    {
      "x": -19,
      "y": 9,
      "z": 8,
      "name": "Deco_Salty_Bone_Full"
    },
    {
      "x": -19,
      "y": 10,
      "z": 8,
      "name": "Deco_Salty_Bone_Full"
    },
    {
      "x": -19,
      "y": 11,
      "z": 8,
      "name": "Deco_Salty_Bone_Full"
    },
    {
      "x": -19,
      "y": 14,
      "z": 15,
      "name": "Deco_Salty_Bone_Full"
    },
    {
      "x": -19,
      "y": 14,
      "z": 16,
      "name": "Deco_Salty_Bone_Full"
    },
    {
      "x": -19,
      "y": 15,
      "z": 16,
      "name": "Deco_Salty_Bone_Full"
    },
    {
      "x": -19,
      "y": 14,
      "z": 17,
      "name": "Deco_Salty_Bone_Full"
    },
    {
      "x": -19,
      "y": 15,
      "z": 17,
      "name": "Deco_Salty_Bone_Full"
    },
    {
      "x": -19,
      "y": 15,
      "z": 19,
      "name": "Deco_Salty_Bone_Full"
    },
    {
      "x": -19,
      "y": 15,
      "z": 20,
      "name": "Deco_Salty_Bone_Full"
    },
    {
      "x": -19,
      "y": 16,
      "z": 20,
      "name": "Deco_Salty_Bone_Full"
    },
    {
      "x": -19,
      "y": 15,
      "z": 21,
      "name": "Deco_Salty_Bone_Full"
    },
    {
      "x": -19,
      "y": 14,
      "z": 22,
      "name": "Deco_Salty_Bone_Full"
    },
    {
      "x": -19,
      "y": 13,
      "z": 23,
      "name": "Deco_Salty_Bone_Full"
    },
    {
      "x": -19,
      "y": 14,
      "z": 23,
      "name": "Deco_Salty_Bone_Full"
    },
    {
      "x": -19,
      "y": 12,
      "z": 24,
      "name": "Deco_Salty_Bone_Full"
    },
    {
      "x": -19,
      "y": 13,
      "z": 24,
      "name": "Deco_Salty_Bone_Full"
    },
    {
      "x": -19,
      "y": 12,
      "z": 25,
      "name": "Deco_Salty_Bone_Full"
    },
    {
      "x": -18,
      "y": 1,
      "z": 9,
      "name": "Deco_Salty_Bone_Full"
    },
    {
      "x": -18,
      "y": 11,
      "z": 9,
      "name": "Deco_Salty_Bone_Full"
    },
    {
      "x": -18,
      "y": 12,
      "z": 9,
      "name": "Deco_Salty_Bone_Full"
    },
    {
      "x": -18,
      "y": 13,
      "z": 9,
      "name": "Deco_Salty_Bone_Full"
    },
    {
      "x": -18,
      "y": 13,
      "z": 10,
      "name": "Deco_Salty_Bone_Full"
    },
    {
      "x": -18,
      "y": 14,
      "z": 16,
      "name": "Deco_Salty_Bone_Full"
    },
    {
      "x": -18,
      "y": 15,
      "z": 16,
      "name": "Deco_Salty_Bone_Full"
    },
    {
      "x": -18,
      "y": 14,
      "z": 17,
      "name": "Deco_Salty_Bone_Full"
    },
    {
      "x": -18,
      "y": 15,
      "z": 17,
      "name": "Deco_Salty_Bone_Full"
    },
    {
      "x": -18,
      "y": 16,
      "z": 17,
      "name": "Deco_Salty_Bone_Full"
    },
    {
      "x": -18,
      "y": 14,
      "z": 18,
      "name": "Deco_Salty_Bone_Full"
    },
    {
      "x": -18,
      "y": 15,
      "z": 18,
      "name": "Deco_Salty_Bone_Full"
    },
    {
      "x": -18,
      "y": 16,
      "z": 18,
      "name": "Deco_Salty_Bone_Full"
    },
    {
      "x": -18,
      "y": 17,
      "z": 18,
      "name": "Deco_Salty_Bone_Full"
    },
    {
      "x": -18,
      "y": 14,
      "z": 19,
      "name": "Deco_Salty_Bone_Full"
    },
    {
      "x": -18,
      "y": 15,
      "z": 19,
      "name": "Deco_Salty_Bone_Full"
    },
    {
      "x": -18,
      "y": 16,
      "z": 19,
      "name": "Deco_Salty_Bone_Full"
    },
    {
      "x": -18,
      "y": 17,
      "z": 19,
      "name": "Deco_Salty_Bone_Full"
    },
    {
      "x": -18,
      "y": 18,
      "z": 19,
      "name": "Deco_Salty_Bone_Full"
    },
    {
      "x": -18,
      "y": 15,
      "z": 20,
      "name": "Deco_Salty_Bone_Full"
    },
    {
      "x": -18,
      "y": 12,
      "z": 24,
      "name": "Deco_Salty_Bone_Full"
    },
    {
      "x": -18,
      "y": 11,
      "z": 25,
      "name": "Deco_Salty_Bone_Full"
    },
    {
      "x": -18,
      "y": 12,
      "z": 25,
      "name": "Deco_Salty_Bone_Full"
    },
    {
      "x": -17,
      "y": 13,
      "z": 9,
      "name": "Deco_Salty_Bone_Full"
    },
    {
      "x": -17,
      "y": 13,
      "z": 10,
      "name": "Deco_Salty_Bone_Full"
    },
    {
      "x": -17,
      "y": 14,
      "z": 10,
      "name": "Deco_Salty_Bone_Full"
    },
    {
      "x": -17,
      "y": 15,
      "z": 10,
      "name": "Deco_Salty_Bone_Full"
    },
    {
      "x": -17,
      "y": 14,
      "z": 11,
      "name": "Deco_Salty_Bone_Full"
    },
    {
      "x": -17,
      "y": 15,
      "z": 16,
      "name": "Deco_Salty_Bone_Full"
    },
    {
      "x": -17,
      "y": 14,
      "z": 17,
      "name": "Deco_Salty_Bone_Full"
    },
    {
      "x": -17,
      "y": 15,
      "z": 17,
      "name": "Deco_Salty_Bone_Full"
    },
    {
      "x": -17,
      "y": 16,
      "z": 17,
      "name": "Deco_Salty_Bone_Full"
    },
    {
      "x": -17,
      "y": 17,
      "z": 17,
      "name": "Deco_Salty_Bone_Full"
    },
    {
      "x": -17,
      "y": 13,
      "z": 18,
      "name": "Deco_Salty_Bone_Full"
    },
    {
      "x": -17,
      "y": 14,
      "z": 18,
      "name": "Deco_Salty_Bone_Full"
    },
    {
      "x": -17,
      "y": 15,
      "z": 18,
      "name": "Deco_Salty_Bone_Full"
    },
    {
      "x": -17,
      "y": 16,
      "z": 18,
      "name": "Deco_Salty_Bone_Full"
    },
    {
      "x": -17,
      "y": 17,
      "z": 18,
      "name": "Deco_Salty_Bone_Full"
    },
    {
      "x": -17,
      "y": 18,
      "z": 18,
      "name": "Deco_Salty_Bone_Full"
    },
    {
      "x": -17,
      "y": 19,
      "z": 18,
      "name": "Deco_Salty_Bone_Full"
    },
    {
      "x": -17,
      "y": 14,
      "z": 19,
      "name": "Deco_Salty_Bone_Full"
    },
    {
      "x": -17,
      "y": 15,
      "z": 19,
      "name": "Deco_Salty_Bone_Full"
    },
    {
      "x": -17,
      "y": 16,
      "z": 19,
      "name": "Deco_Salty_Bone_Full"
    },
    {
      "x": -17,
      "y": 17,
      "z": 19,
      "name": "Deco_Salty_Bone_Full"
    },
    {
      "x": -16,
      "y": 14,
      "z": 10,
      "name": "Deco_Salty_Bone_Full"
    },
    {
      "x": -16,
      "y": 14,
      "z": 11,
      "name": "Deco_Salty_Bone_Full"
    },
    {
      "x": -16,
      "y": 15,
      "z": 11,
      "name": "Deco_Salty_Bone_Full"
    },
    {
      "x": -16,
      "y": 15,
      "z": 12,
      "name": "Deco_Salty_Bone_Full"
    },
    {
      "x": -16,
      "y": 16,
      "z": 16,
      "name": "Deco_Salty_Bone_Full"
    },
    {
      "x": -16,
      "y": 15,
      "z": 17,
      "name": "Deco_Salty_Bone_Full"
    },
    {
      "x": -16,
      "y": 16,
      "z": 17,
      "name": "Deco_Salty_Bone_Full"
    },
    {
      "x": -16,
      "y": 17,
      "z": 17,
      "name": "Deco_Salty_Bone_Full"
    },
    {
      "x": -16,
      "y": 18,
      "z": 17,
      "name": "Deco_Salty_Bone_Full"
    },
    {
      "x": -16,
      "y": 19,
      "z": 17,
      "name": "Deco_Salty_Bone_Full"
    },
    {
      "x": -16,
      "y": 20,
      "z": 17,
      "name": "Deco_Salty_Bone_Full"
    },
    {
      "x": -16,
      "y": 21,
      "z": 17,
      "name": "Deco_Salty_Bone_Spike"
    },
    {
      "x": -16,
      "y": 14,
      "z": 18,
      "name": "Deco_Salty_Bone_Full"
    },
    {
      "x": -16,
      "y": 15,
      "z": 18,
      "name": "Deco_Salty_Bone_Full"
    },
    {
      "x": -16,
      "y": 16,
      "z": 18,
      "name": "Deco_Salty_Bone_Full"
    },
    {
      "x": -16,
      "y": 17,
      "z": 18,
      "name": "Deco_Salty_Bone_Full"
    },
    {
      "x": -16,
      "y": 14,
      "z": 19,
      "name": "Deco_Salty_Bone_Full"
    },
    {
      "x": -16,
      "y": 15,
      "z": 19,
      "name": "Deco_Salty_Bone_Full"
    },
    {
      "x": -16,
      "y": 16,
      "z": 19,
      "name": "Deco_Salty_Bone_Full"
    },
    {
      "x": -16,
      "y": 14,
      "z": 20,
      "name": "Deco_Salty_Bone_Full"
    },
    {
      "x": -16,
      "y": 15,
      "z": 20,
      "name": "Deco_Salty_Bone_Full"
    },
    {
      "x": -15,
      "y": 3,
      "z": 4,
      "name": "Deco_Salty_Bone_Full"
    },
    {
      "x": -15,
      "y": 4,
      "z": 4,
      "name": "Deco_Salty_Bone_Full"
    },
    {
      "x": -15,
      "y": 5,
      "z": 4,
      "name": "Deco_Salty_Bone_Full"
    },
    {
      "x": -15,
      "y": 6,
      "z": 4,
      "name": "Deco_Salty_Bone_Full"
    },
    {
      "x": -15,
      "y": 7,
      "z": 4,
      "name": "Deco_Salty_Bone_Full"
    },
    {
      "x": -15,
      "y": 8,
      "z": 4,
      "name": "Deco_Salty_Bone_Full"
    },
    {
      "x": -15,
      "y": 9,
      "z": 4,
      "name": "Deco_Salty_Bone_Full"
    },
    {
      "x": -15,
      "y": 10,
      "z": 4,
      "name": "Deco_Salty_Bone_Full"
    },
    {
      "x": -15,
      "y": 11,
      "z": 4,
      "name": "Deco_Salty_Bone_Full"
    },
    {
      "x": -15,
      "y": 12,
      "z": 4,
      "name": "Deco_Salty_Bone_Full"
    },
    {
      "x": -15,
      "y": 15,
      "z": 11,
      "name": "Deco_Salty_Bone_Full"
    },
    {
      "x": -15,
      "y": 15,
      "z": 12,
      "name": "Deco_Salty_Bone_Full"
    },
    {
      "x": -15,
      "y": 16,
      "z": 12,
      "name": "Deco_Salty_Bone_Full"
    },
    {
      "x": -15,
      "y": 15,
      "z": 13,
      "name": "Deco_Salty_Bone_Full"
    },
    {
      "x": -15,
      "y": 16,
      "z": 13,
      "name": "Deco_Salty_Bone_Full"
    },
    {
      "x": -15,
      "y": 16,
      "z": 15,
      "name": "Deco_Salty_Bone_Full"
    },
    {
      "x": -15,
      "y": 16,
      "z": 16,
      "name": "Deco_Salty_Bone_Full"
    },
    {
      "x": -15,
      "y": 17,
      "z": 16,
      "name": "Deco_Salty_Bone_Full"
    },
    {
      "x": -15,
      "y": 16,
      "z": 17,
      "name": "Deco_Salty_Bone_Full"
    },
    {
      "x": -15,
      "y": 15,
      "z": 18,
      "name": "Deco_Salty_Bone_Full"
    },
    {
      "x": -15,
      "y": 14,
      "z": 19,
      "name": "Deco_Salty_Bone_Full"
    },
    {
      "x": -15,
      "y": 15,
      "z": 19,
      "name": "Deco_Salty_Bone_Full"
    },
    {
      "x": -15,
      "y": 14,
      "z": 20,
      "name": "Deco_Salty_Bone_Full"
    },
    {
      "x": -15,
      "y": 15,
      "z": 20,
      "name": "Deco_Salty_Bone_Full"
    },
    {
      "x": -15,
      "y": 14,
      "z": 21,
      "name": "Deco_Salty_Bone_Full"
    },
    {
      "x": -14,
      "y": 2,
      "z": 5,
      "name": "Deco_Salty_Bone_Full"
    },
    {
      "x": -14,
      "y": 3,
      "z": 5,
      "name": "Deco_Salty_Bone_Full"
    },
    {
      "x": -14,
      "y": 12,
      "z": 5,
      "name": "Deco_Salty_Bone_Full"
    },
    {
      "x": -14,
      "y": 13,
      "z": 5,
      "name": "Deco_Salty_Bone_Full"
    },
    {
      "x": -14,
      "y": 14,
      "z": 5,
      "name": "Deco_Salty_Bone_Full"
    },
    {
      "x": -14,
      "y": 14,
      "z": 6,
      "name": "Deco_Salty_Bone_Full"
    },
    {
      "x": -14,
      "y": 15,
      "z": 12,
      "name": "Deco_Salty_Bone_Full"
    },
    {
      "x": -14,
      "y": 16,
      "z": 12,
      "name": "Deco_Salty_Bone_Full"
    },
    {
      "x": -14,
      "y": 15,
      "z": 13,
      "name": "Deco_Salty_Bone_Full"
    },
    {
      "x": -14,
      "y": 16,
      "z": 13,
      "name": "Deco_Salty_Bone_Full"
    },
    {
      "x": -14,
      "y": 17,
      "z": 13,
      "name": "Deco_Salty_Bone_Full"
    },
    {
      "x": -14,
      "y": 15,
      "z": 14,
      "name": "Deco_Salty_Bone_Full"
    },
    {
      "x": -14,
      "y": 16,
      "z": 14,
      "name": "Deco_Salty_Bone_Full"
    },
    {
      "x": -14,
      "y": 17,
      "z": 14,
      "name": "Deco_Salty_Bone_Full"
    },
    {
      "x": -14,
      "y": 18,
      "z": 14,
      "name": "Deco_Salty_Bone_Full"
    },
    {
      "x": -14,
      "y": 15,
      "z": 15,
      "name": "Deco_Salty_Bone_Full"
    },
    {
      "x": -14,
      "y": 16,
      "z": 15,
      "name": "Deco_Salty_Bone_Full"
    },
    {
      "x": -14,
      "y": 17,
      "z": 15,
      "name": "Deco_Salty_Bone_Full"
    },
    {
      "x": -14,
      "y": 18,
      "z": 15,
      "name": "Deco_Salty_Bone_Full"
    },
    {
      "x": -14,
      "y": 16,
      "z": 16,
      "name": "Deco_Salty_Bone_Full"
    },
    {
      "x": -14,
      "y": 14,
      "z": 20,
      "name": "Deco_Salty_Bone_Full"
    },
    {
      "x": -14,
      "y": 3,
      "z": 21,
      "name": "Deco_Salty_Bone_Full"
    },
    {
      "x": -14,
      "y": 4,
      "z": 21,
      "name": "Deco_Salty_Bone_Full"
    },
    {
      "x": -14,
      "y": 13,
      "z": 21,
      "name": "Deco_Salty_Bone_Full"
    },
    {
      "x": -14,
      "y": 14,
      "z": 21,
      "name": "Deco_Salty_Bone_Full"
    },
    {
      "x": -14,
      "y": 13,
      "z": 22,
      "name": "Deco_Salty_Bone_Full"
    },
    {
      "x": -13,
      "y": 14,
      "z": 5,
      "name": "Deco_Salty_Bone_Full"
    },
    {
      "x": -13,
      "y": 14,
      "z": 6,
      "name": "Deco_Salty_Bone_Full"
    },
    {
      "x": -13,
      "y": 15,
      "z": 6,
      "name": "Deco_Salty_Bone_Full"
    },
    {
      "x": -13,
      "y": 15,
      "z": 7,
      "name": "Deco_Salty_Bone_Full"
    },
    {
      "x": -13,
      "y": 16,
      "z": 12,
      "name": "Deco_Salty_Bone_Full"
    },
    {
      "x": -13,
      "y": 15,
      "z": 13,
      "name": "Deco_Salty_Bone_Full"
    },
    {
      "x": -13,
      "y": 16,
      "z": 13,
      "name": "Deco_Salty_Bone_Full"
    },
    {
      "x": -13,
      "y": 17,
      "z": 13,
      "name": "Deco_Salty_Bone_Full"
    },
    {
      "x": -13,
      "y": 14,
      "z": 14,
      "name": "Deco_Salty_Bone_Full"
    },
    {
      "x": -13,
      "y": 15,
      "z": 14,
      "name": "Deco_Salty_Bone_Full"
    },
    {
      "x": -13,
      "y": 16,
      "z": 14,
      "name": "Deco_Salty_Bone_Full"
    },
    {
      "x": -13,
      "y": 17,
      "z": 14,
      "name": "Deco_Salty_Bone_Full"
    },
    {
      "x": -13,
      "y": 18,
      "z": 14,
      "name": "Deco_Salty_Bone_Full"
    },
    {
      "x": -13,
      "y": 19,
      "z": 14,
      "name": "Deco_Salty_Bone_Full"
    },
    {
      "x": -13,
      "y": 20,
      "z": 14,
      "name": "Deco_Salty_Bone_Full"
    },
    {
      "x": -13,
      "y": 15,
      "z": 15,
      "name": "Deco_Salty_Bone_Full"
    },
    {
      "x": -13,
      "y": 16,
      "z": 15,
      "name": "Deco_Salty_Bone_Full"
    },
    {
      "x": -13,
      "y": 17,
      "z": 15,
      "name": "Deco_Salty_Bone_Full"
    },
    {
      "x": -13,
      "y": 18,
      "z": 15,
      "name": "Deco_Salty_Bone_Full"
    },
    {
      "x": -13,
      "y": 13,
      "z": 21,
      "name": "Deco_Salty_Bone_Full"
    },
    {
      "x": -13,
      "y": 4,
      "z": 22,
      "name": "Deco_Salty_Bone_Full"
    },
    {
      "x": -13,
      "y": 5,
      "z": 22,
      "name": "Deco_Salty_Bone_Full"
    },
    {
      "x": -13,
      "y": 6,
      "z": 22,
      "name": "Deco_Salty_Bone_Full"
    },
    {
      "x": -13,
      "y": 12,
      "z": 22,
      "name": "Deco_Salty_Bone_Full"
    },
    {
      "x": -13,
      "y": 13,
      "z": 22,
      "name": "Deco_Salty_Bone_Full"
    },
    {
      "x": -13,
      "y": 12,
      "z": 23,
      "name": "Deco_Salty_Bone_Full"
    },
    {
      "x": -12,
      "y": 15,
      "z": 6,
      "name": "Deco_Salty_Bone_Full"
    },
    {
      "x": -12,
      "y": 15,
      "z": 7,
      "name": "Deco_Salty_Bone_Full"
    },
    {
      "x": -12,
      "y": 16,
      "z": 7,
      "name": "Deco_Salty_Bone_Full"
    },
    {
      "x": -12,
      "y": 16,
      "z": 8,
      "name": "Deco_Salty_Bone_Full"
    },
    {
      "x": -12,
      "y": 17,
      "z": 12,
      "name": "Deco_Salty_Bone_Full"
    },
    {
      "x": -12,
      "y": 16,
      "z": 13,
      "name": "Deco_Salty_Bone_Full"
    },
    {
      "x": -12,
      "y": 17,
      "z": 13,
      "name": "Deco_Salty_Bone_Full"
    },
    {
      "x": -12,
      "y": 18,
      "z": 13,
      "name": "Deco_Salty_Bone_Full"
    },
    {
      "x": -12,
      "y": 19,
      "z": 13,
      "name": "Deco_Salty_Bone_Full"
    },
    {
      "x": -12,
      "y": 20,
      "z": 13,
      "name": "Deco_Salty_Bone_Full"
    },
    {
      "x": -12,
      "y": 21,
      "z": 13,
      "name": "Deco_Salty_Bone_Full"
    },
    {
      "x": -12,
      "y": 22,
      "z": 13,
      "name": "Deco_Salty_Bone_Spike"
    },
    {
      "x": -12,
      "y": 15,
      "z": 14,
      "name": "Deco_Salty_Bone_Full"
    },
    {
      "x": -12,
      "y": 16,
      "z": 14,
      "name": "Deco_Salty_Bone_Full"
    },
    {
      "x": -12,
      "y": 17,
      "z": 14,
      "name": "Deco_Salty_Bone_Full"
    },
    {
      "x": -12,
      "y": 15,
      "z": 15,
      "name": "Deco_Salty_Bone_Full"
    },
    {
      "x": -12,
      "y": 16,
      "z": 15,
      "name": "Deco_Salty_Bone_Full"
    },
    {
      "x": -12,
      "y": 17,
      "z": 15,
      "name": "Deco_Salty_Bone_Full"
    },
    {
      "x": -12,
      "y": 15,
      "z": 16,
      "name": "Deco_Salty_Bone_Full"
    },
    {
      "x": -12,
      "y": 16,
      "z": 16,
      "name": "Deco_Salty_Bone_Full"
    },
    {
      "x": -12,
      "y": 12,
      "z": 22,
      "name": "Deco_Salty_Bone_Full"
    },
    {
      "x": -12,
      "y": 6,
      "z": 23,
      "name": "Deco_Salty_Bone_Full"
    },
    {
      "x": -12,
      "y": 7,
      "z": 23,
      "name": "Deco_Salty_Bone_Full"
    },
    {
      "x": -12,
      "y": 8,
      "z": 23,
      "name": "Deco_Salty_Bone_Full"
    },
    {
      "x": -12,
      "y": 9,
      "z": 23,
      "name": "Deco_Salty_Bone_Full"
    },
    {
      "x": -12,
      "y": 10,
      "z": 23,
      "name": "Deco_Salty_Bone_Full"
    },
    {
      "x": -12,
      "y": 11,
      "z": 23,
      "name": "Deco_Salty_Bone_Full"
    },
    {
      "x": -12,
      "y": 12,
      "z": 23,
      "name": "Deco_Salty_Bone_Full"
    },
    {
      "x": -11,
      "y": 4,
      "z": 0,
      "name": "Deco_Salty_Bone_Full"
    },
    {
      "x": -11,
      "y": 5,
      "z": 0,
      "name": "Deco_Salty_Bone_Full"
    },
    {
      "x": -11,
      "y": 6,
      "z": 0,
      "name": "Deco_Salty_Bone_Full"
    },
    {
      "x": -11,
      "y": 7,
      "z": 0,
      "name": "Deco_Salty_Bone_Full"
    },
    {
      "x": -11,
      "y": 8,
      "z": 0,
      "name": "Deco_Salty_Bone_Full"
    },
    {
      "x": -11,
      "y": 9,
      "z": 0,
      "name": "Deco_Salty_Bone_Full"
    },
    {
      "x": -11,
      "y": 10,
      "z": 0,
      "name": "Deco_Salty_Bone_Full"
    },
    {
      "x": -11,
      "y": 11,
      "z": 0,
      "name": "Deco_Salty_Bone_Full"
    },
    {
      "x": -11,
      "y": 12,
      "z": 0,
      "name": "Deco_Salty_Bone_Full"
    },
    {
      "x": -11,
      "y": 13,
      "z": 0,
      "name": "Deco_Salty_Bone_Full"
    },
    {
      "x": -11,
      "y": 16,
      "z": 7,
      "name": "Deco_Salty_Bone_Full"
    },
    {
      "x": -11,
      "y": 16,
      "z": 8,
      "name": "Deco_Salty_Bone_Full"
    },
    {
      "x": -11,
      "y": 17,
      "z": 8,
      "name": "Deco_Salty_Bone_Full"
    },
    {
      "x": -11,
      "y": 16,
      "z": 9,
      "name": "Deco_Salty_Bone_Full"
    },
    {
      "x": -11,
      "y": 17,
      "z": 9,
      "name": "Deco_Salty_Bone_Full"
    },
    {
      "x": -11,
      "y": 17,
      "z": 11,
      "name": "Deco_Salty_Bone_Full"
    },
    {
      "x": -11,
      "y": 17,
      "z": 12,
      "name": "Deco_Salty_Bone_Full"
    },
    {
      "x": -11,
      "y": 18,
      "z": 12,
      "name": "Deco_Salty_Bone_Full"
    },
    {
      "x": -11,
      "y": 17,
      "z": 13,
      "name": "Deco_Salty_Bone_Full"
    },
    {
      "x": -11,
      "y": 16,
      "z": 14,
      "name": "Deco_Salty_Bone_Full"
    },
    {
      "x": -11,
      "y": 15,
      "z": 15,
      "name": "Deco_Salty_Bone_Full"
    },
    {
      "x": -11,
      "y": 16,
      "z": 15,
      "name": "Deco_Salty_Bone_Full"
    },
    {
      "x": -11,
      "y": 15,
      "z": 16,
      "name": "Deco_Salty_Bone_Full"
    },
    {
      "x": -11,
      "y": 16,
      "z": 16,
      "name": "Deco_Salty_Bone_Full"
    },
    {
      "x": -11,
      "y": 15,
      "z": 17,
      "name": "Deco_Salty_Bone_Full"
    },
    {
      "x": -10,
      "y": 2,
      "z": 1,
      "name": "Deco_Salty_Bone_Full"
    },
    {
      "x": -10,
      "y": 3,
      "z": 1,
      "name": "Deco_Salty_Bone_Full"
    },
    {
      "x": -10,
      "y": 4,
      "z": 1,
      "name": "Deco_Salty_Bone_Full"
    },
    {
      "x": -10,
      "y": 13,
      "z": 1,
      "name": "Deco_Salty_Bone_Full"
    },
    {
      "x": -10,
      "y": 14,
      "z": 1,
      "name": "Deco_Salty_Bone_Full"
    },
    {
      "x": -10,
      "y": 15,
      "z": 1,
      "name": "Deco_Salty_Bone_Full"
    },
    {
      "x": -10,
      "y": 15,
      "z": 2,
      "name": "Deco_Salty_Bone_Full"
    },
    {
      "x": -10,
      "y": 16,
      "z": 8,
      "name": "Deco_Salty_Bone_Full"
    },
    {
      "x": -10,
      "y": 17,
      "z": 8,
      "name": "Deco_Salty_Bone_Full"
    },
    {
      "x": -10,
      "y": 16,
      "z": 9,
      "name": "Deco_Salty_Bone_Full"
    },
    {
      "x": -10,
      "y": 17,
      "z": 9,
      "name": "Deco_Salty_Bone_Full"
    },
    {
      "x": -10,
      "y": 18,
      "z": 9,
      "name": "Deco_Salty_Bone_Full"
    },
    {
      "x": -10,
      "y": 16,
      "z": 10,
      "name": "Deco_Salty_Bone_Full"
    },
    {
      "x": -10,
      "y": 17,
      "z": 10,
      "name": "Deco_Salty_Bone_Full"
    },
    {
      "x": -10,
      "y": 18,
      "z": 10,
      "name": "Deco_Salty_Bone_Full"
    },
    {
      "x": -10,
      "y": 19,
      "z": 10,
      "name": "Deco_Salty_Bone_Full"
    },
    {
      "x": -10,
      "y": 16,
      "z": 11,
      "name": "Deco_Salty_Bone_Full"
    },
    {
      "x": -10,
      "y": 17,
      "z": 11,
      "name": "Deco_Salty_Bone_Full"
    },
    {
      "x": -10,
      "y": 18,
      "z": 11,
      "name": "Deco_Salty_Bone_Full"
    },
    {
      "x": -10,
      "y": 19,
      "z": 11,
      "name": "Deco_Salty_Bone_Full"
    },
    {
      "x": -10,
      "y": 20,
      "z": 11,
      "name": "Deco_Salty_Bone_Full"
    },
    {
      "x": -10,
      "y": 21,
      "z": 11,
      "name": "Deco_Salty_Bone_Spike"
    },
    {
      "x": -10,
      "y": 17,
      "z": 12,
      "name": "Deco_Salty_Bone_Full"
    },
    {
      "x": -10,
      "y": 15,
      "z": 16,
      "name": "Deco_Salty_Bone_Full"
    },
    {
      "x": -10,
      "y": 14,
      "z": 17,
      "name": "Deco_Salty_Bone_Full"
    },
    {
      "x": -10,
      "y": 15,
      "z": 17,
      "name": "Deco_Salty_Bone_Full"
    },
    {
      "x": -10,
      "y": 14,
      "z": 18,
      "name": "Deco_Salty_Bone_Full"
    },
    {
      "x": -9,
      "y": 15,
      "z": 1,
      "name": "Deco_Salty_Bone_Full"
    },
    {
      "x": -9,
      "y": 1,
      "z": 2,
      "name": "Deco_Salty_Bone_Full"
    },
    {
      "x": -9,
      "y": 2,
      "z": 2,
      "name": "Deco_Salty_Bone_Full"
    },
    {
      "x": -9,
      "y": 15,
      "z": 2,
      "name": "Deco_Salty_Bone_Full"
    },
    {
      "x": -9,
      "y": 16,
      "z": 2,
      "name": "Deco_Salty_Bone_Full"
    },
    {
      "x": -9,
      "y": 16,
      "z": 3,
      "name": "Deco_Salty_Bone_Full"
    },
    {
      "x": -9,
      "y": 17,
      "z": 8,
      "name": "Deco_Salty_Bone_Full"
    },
    {
      "x": -9,
      "y": 18,
      "z": 8,
      "name": "Deco_Salty_Bone_Full"
    },
    {
      "x": -9,
      "y": 16,
      "z": 9,
      "name": "Deco_Salty_Bone_Full"
    },
    {
      "x": -9,
      "y": 17,
      "z": 9,
      "name": "Deco_Salty_Bone_Full"
    },
    {
      "x": -9,
      "y": 18,
      "z": 9,
      "name": "Deco_Salty_Bone_Full"
    },
    {
      "x": -9,
      "y": 15,
      "z": 10,
      "name": "Deco_Salty_Bone_Full"
    },
    {
      "x": -9,
      "y": 16,
      "z": 10,
      "name": "Deco_Salty_Bone_Full"
    },
    {
      "x": -9,
      "y": 17,
      "z": 10,
      "name": "Deco_Salty_Bone_Full"
    },
    {
      "x": -9,
      "y": 18,
      "z": 10,
      "name": "Deco_Salty_Bone_Full"
    },
    {
      "x": -9,
      "y": 19,
      "z": 10,
      "name": "Deco_Salty_Bone_Full"
    },
    {
      "x": -9,
      "y": 16,
      "z": 11,
      "name": "Deco_Salty_Bone_Full"
    },
    {
      "x": -9,
      "y": 17,
      "z": 11,
      "name": "Deco_Salty_Bone_Full"
    },
    {
      "x": -9,
      "y": 18,
      "z": 11,
      "name": "Deco_Salty_Bone_Full"
    },
    {
      "x": -9,
      "y": 19,
      "z": 11,
      "name": "Deco_Salty_Bone_Full"
    },
    {
      "x": -9,
      "y": 14,
      "z": 17,
      "name": "Deco_Salty_Bone_Full"
    },
    {
      "x": -9,
      "y": 13,
      "z": 18,
      "name": "Deco_Salty_Bone_Full"
    },
    {
      "x": -9,
      "y": 14,
      "z": 18,
      "name": "Deco_Salty_Bone_Full"
    },
    {
      "x": -9,
      "y": 13,
      "z": 19,
      "name": "Deco_Salty_Bone_Full"
    },
    {
      "x": -8,
      "y": 16,
      "z": 2,
      "name": "Deco_Salty_Bone_Full"
    },
    {
      "x": -8,
      "y": 1,
      "z": 3,
      "name": "Deco_Salty_Bone_Full"
    },
    {
      "x": -8,
      "y": 16,
      "z": 3,
      "name": "Deco_Salty_Bone_Full"
    },
    {
      "x": -8,
      "y": 17,
      "z": 3,
      "name": "Deco_Salty_Bone_Full"
    },
    {
      "x": -8,
      "y": 16,
      "z": 4,
      "name": "Deco_Salty_Bone_Full"
    },
    {
      "x": -8,
      "y": 17,
      "z": 8,
      "name": "Deco_Salty_Bone_Full"
    },
    {
      "x": -8,
      "y": 17,
      "z": 9,
      "name": "Deco_Salty_Bone_Full"
    },
    {
      "x": -8,
      "y": 18,
      "z": 9,
      "name": "Deco_Salty_Bone_Full"
    },
    {
      "x": -8,
      "y": 19,
      "z": 9,
      "name": "Deco_Salty_Bone_Full"
    },
    {
      "x": -8,
      "y": 20,
      "z": 9,
      "name": "Deco_Salty_Bone_Full"
    },
    {
      "x": -8,
      "y": 16,
      "z": 10,
      "name": "Deco_Salty_Bone_Full"
    },
    {
      "x": -8,
      "y": 17,
      "z": 10,
      "name": "Deco_Salty_Bone_Full"
    },
    {
      "x": -8,
      "y": 18,
      "z": 10,
      "name": "Deco_Salty_Bone_Full"
    },
    {
      "x": -8,
      "y": 16,
      "z": 11,
      "name": "Deco_Salty_Bone_Full"
    },
    {
      "x": -8,
      "y": 17,
      "z": 11,
      "name": "Deco_Salty_Bone_Full"
    },
    {
      "x": -8,
      "y": 18,
      "z": 11,
      "name": "Deco_Salty_Bone_Full"
    },
    {
      "x": -8,
      "y": 16,
      "z": 12,
      "name": "Deco_Salty_Bone_Full"
    },
    {
      "x": -8,
      "y": 17,
      "z": 12,
      "name": "Deco_Salty_Bone_Full"
    },
    {
      "x": -8,
      "y": 13,
      "z": 18,
      "name": "Deco_Salty_Bone_Full"
    },
    {
      "x": -8,
      "y": 11,
      "z": 19,
      "name": "Deco_Salty_Bone_Full"
    },
    {
      "x": -8,
      "y": 12,
      "z": 19,
      "name": "Deco_Salty_Bone_Full"
    },
    {
      "x": -8,
      "y": 13,
      "z": 19,
      "name": "Deco_Salty_Bone_Full"
    },
    {
      "x": -7,
      "y": 16,
      "z": 3,
      "name": "Deco_Salty_Bone_Full"
    },
    {
      "x": -7,
      "y": 0,
      "z": 4,
      "name": "Deco_Salty_Bone_Full"
    },
    {
      "x": -7,
      "y": 1,
      "z": 4,
      "name": "Deco_Salty_Bone_Full"
    },
    {
      "x": -7,
      "y": 17,
      "z": 4,
      "name": "Deco_Salty_Bone_Full"
    },
    {
      "x": -7,
      "y": 17,
      "z": 5,
      "name": "Deco_Salty_Bone_Full"
    },
    {
      "x": -7,
      "y": 18,
      "z": 5,
      "name": "Deco_Salty_Bone_Full"
    },
    {
      "x": -7,
      "y": 18,
      "z": 7,
      "name": "Deco_Salty_Bone_Full"
    },
    {
      "x": -7,
      "y": 17,
      "z": 8,
      "name": "Deco_Salty_Bone_Full"
    },
    {
      "x": -7,
      "y": 18,
      "z": 8,
      "name": "Deco_Salty_Bone_Full"
    },
    {
      "x": -7,
      "y": 17,
      "z": 9,
      "name": "Deco_Salty_Bone_Full"
    },
    {
      "x": -7,
      "y": 17,
      "z": 10,
      "name": "Deco_Salty_Bone_Full"
    },
    {
      "x": -7,
      "y": 18,
      "z": 10,
      "name": "Deco_Salty_Bone_Full"
    },
    {
      "x": -7,
      "y": 16,
      "z": 11,
      "name": "Deco_Salty_Bone_Full"
    },
    {
      "x": -7,
      "y": 17,
      "z": 11,
      "name": "Deco_Salty_Bone_Full"
    },
    {
      "x": -7,
      "y": 16,
      "z": 12,
      "name": "Deco_Salty_Bone_Full"
    },
    {
      "x": -7,
      "y": 17,
      "z": 12,
      "name": "Deco_Salty_Bone_Full"
    },
    {
      "x": -7,
      "y": 16,
      "z": 13,
      "name": "Deco_Salty_Bone_Full"
    },
    {
      "x": -7,
      "y": 4,
      "z": 20,
      "name": "Deco_Salty_Bone_Full"
    },
    {
      "x": -7,
      "y": 5,
      "z": 20,
      "name": "Deco_Salty_Bone_Full"
    },
    {
      "x": -7,
      "y": 6,
      "z": 20,
      "name": "Deco_Salty_Bone_Full"
    },
    {
      "x": -7,
      "y": 7,
      "z": 20,
      "name": "Deco_Salty_Bone_Full"
    },
    {
      "x": -7,
      "y": 8,
      "z": 20,
      "name": "Deco_Salty_Bone_Full"
    },
    {
      "x": -7,
      "y": 9,
      "z": 20,
      "name": "Deco_Salty_Bone_Full"
    },
    {
      "x": -7,
      "y": 10,
      "z": 20,
      "name": "Deco_Salty_Bone_Full"
    },
    {
      "x": -7,
      "y": 11,
      "z": 20,
      "name": "Deco_Salty_Bone_Full"
    },
    {
      "x": -6,
      "y": 12,
      "z": -5,
      "name": "Deco_Salty_Bone_Full"
    },
    {
      "x": -6,
      "y": 13,
      "z": -5,
      "name": "Deco_Salty_Bone_Full"
    },
    {
      "x": -6,
      "y": 17,
      "z": 4,
      "name": "Deco_Salty_Bone_Full"
    },
    {
      "x": -6,
      "y": 18,
      "z": 4,
      "name": "Deco_Salty_Bone_Full"
    },
    {
      "x": -6,
      "y": 17,
      "z": 5,
      "name": "Deco_Salty_Bone_Full"
    },
    {
      "x": -6,
      "y": 18,
      "z": 5,
      "name": "Deco_Salty_Bone_Full"
    },
    {
      "x": -6,
      "y": 17,
      "z": 6,
      "name": "Deco_Salty_Bone_Full"
    },
    {
      "x": -6,
      "y": 18,
      "z": 6,
      "name": "Deco_Salty_Bone_Full"
    },
    {
      "x": -6,
      "y": 19,
      "z": 6,
      "name": "Deco_Salty_Bone_Full"
    },
    {
      "x": -6,
      "y": 20,
      "z": 6,
      "name": "Deco_Salty_Bone_Full"
    },
    {
      "x": -6,
      "y": 17,
      "z": 7,
      "name": "Deco_Salty_Bone_Full"
    },
    {
      "x": -6,
      "y": 18,
      "z": 7,
      "name": "Deco_Salty_Bone_Full"
    },
    {
      "x": -6,
      "y": 19,
      "z": 7,
      "name": "Deco_Salty_Bone_Full"
    },
    {
      "x": -6,
      "y": 20,
      "z": 7,
      "name": "Deco_Salty_Bone_Full"
    },
    {
      "x": -6,
      "y": 21,
      "z": 7,
      "name": "Deco_Salty_Bone_Full"
    },
    {
      "x": -6,
      "y": 18,
      "z": 8,
      "name": "Deco_Salty_Bone_Full"
    },
    {
      "x": -6,
      "y": 16,
      "z": 12,
      "name": "Deco_Salty_Bone_Full"
    },
    {
      "x": -6,
      "y": 15,
      "z": 13,
      "name": "Deco_Salty_Bone_Full"
    },
    {
      "x": -6,
      "y": 16,
      "z": 13,
      "name": "Deco_Salty_Bone_Full"
    },
    {
      "x": -6,
      "y": 15,
      "z": 14,
      "name": "Deco_Salty_Bone_Full"
    },
    {
      "x": -5,
      "y": 13,
      "z": -4,
      "name": "Deco_Salty_Bone_Full"
    },
    {
      "x": -5,
      "y": 14,
      "z": -4,
      "name": "Deco_Salty_Bone_Full"
    },
    {
      "x": -5,
      "y": 15,
      "z": -4,
      "name": "Deco_Salty_Bone_Full"
    },
    {
      "x": -5,
      "y": 15,
      "z": -3,
      "name": "Deco_Salty_Bone_Full"
    },
    {
      "x": -5,
      "y": 18,
      "z": 4,
      "name": "Deco_Salty_Bone_Full"
    },
    {
      "x": -5,
      "y": 17,
      "z": 5,
      "name": "Deco_Salty_Bone_Full"
    },
    {
      "x": -5,
      "y": 18,
      "z": 5,
      "name": "Deco_Salty_Bone_Full"
    },
    {
      "x": -5,
      "y": 19,
      "z": 5,
      "name": "Deco_Salty_Bone_Full"
    },
    {
      "x": -5,
      "y": 16,
      "z": 6,
      "name": "Deco_Salty_Bone_Full"
    },
    {
      "x": -5,
      "y": 17,
      "z": 6,
      "name": "Deco_Salty_Bone_Full"
    },
    {
      "x": -5,
      "y": 18,
      "z": 6,
      "name": "Deco_Salty_Bone_Full"
    },
    {
      "x": -5,
      "y": 19,
      "z": 6,
      "name": "Deco_Salty_Bone_Full"
    },
    {
      "x": -5,
      "y": 20,
      "z": 6,
      "name": "Deco_Salty_Bone_Full"
    },
    {
      "x": -5,
      "y": 21,
      "z": 6,
      "name": "Deco_Salty_Bone_Full"
    },
    {
      "x": -5,
      "y": 22,
      "z": 6,
      "name": "Deco_Salty_Bone_Full"
    },
    {
      "x": -5,
      "y": 23,
      "z": 6,
      "name": "Deco_Salty_Bone_Full"
    },
    {
      "x": -5,
      "y": 17,
      "z": 7,
      "name": "Deco_Salty_Bone_Full"
    },
    {
      "x": -5,
      "y": 18,
      "z": 7,
      "name": "Deco_Salty_Bone_Full"
    },
    {
      "x": -5,
      "y": 19,
      "z": 7,
      "name": "Deco_Salty_Bone_Full"
    },
    {
      "x": -5,
      "y": 20,
      "z": 7,
      "name": "Deco_Salty_Bone_Full"
    },
    {
      "x": -5,
      "y": 15,
      "z": 13,
      "name": "Deco_Salty_Bone_Full"
    },
    {
      "x": -5,
      "y": 14,
      "z": 14,
      "name": "Deco_Salty_Bone_Full"
    },
    {
      "x": -5,
      "y": 15,
      "z": 14,
      "name": "Deco_Salty_Bone_Full"
    },
    {
      "x": -5,
      "y": 14,
      "z": 15,
      "name": "Deco_Salty_Bone_Full"
    },
    {
      "x": -4,
      "y": 15,
      "z": -4,
      "name": "Deco_Salty_Bone_Full"
    },
    {
      "x": -4,
      "y": 15,
      "z": -3,
      "name": "Deco_Salty_Bone_Full"
    },
    {
      "x": -4,
      "y": 16,
      "z": -3,
      "name": "Deco_Salty_Bone_Full"
    },
    {
      "x": -4,
      "y": 15,
      "z": -2,
      "name": "Deco_Salty_Bone_Full"
    },
    {
      "x": -4,
      "y": 18,
      "z": 4,
      "name": "Deco_Salty_Bone_Full"
    },
    {
      "x": -4,
      "y": 18,
      "z": 5,
      "name": "Deco_Salty_Bone_Full"
    },
    {
      "x": -4,
      "y": 19,
      "z": 5,
      "name": "Deco_Salty_Bone_Full"
    },
    {
      "x": -4,
      "y": 20,
      "z": 5,
      "name": "Deco_Salty_Bone_Full"
    },
    {
      "x": -4,
      "y": 21,
      "z": 5,
      "name": "Deco_Salty_Bone_Full"
    },
    {
      "x": -4,
      "y": 22,
      "z": 5,
      "name": "Deco_Salty_Bone_Full"
    },
    {
      "x": -4,
      "y": 23,
      "z": 5,
      "name": "Deco_Salty_Bone_Full"
    },
    {
      "x": -4,
      "y": 24,
      "z": 5,
      "name": "Deco_Salty_Bone_Full"
    },
    {
      "x": -4,
      "y": 17,
      "z": 6,
      "name": "Deco_Salty_Bone_Full"
    },
    {
      "x": -4,
      "y": 18,
      "z": 6,
      "name": "Deco_Salty_Bone_Full"
    },
    {
      "x": -4,
      "y": 19,
      "z": 6,
      "name": "Deco_Salty_Bone_Full"
    },
    {
      "x": -4,
      "y": 17,
      "z": 7,
      "name": "Deco_Salty_Bone_Full"
    },
    {
      "x": -4,
      "y": 18,
      "z": 7,
      "name": "Deco_Salty_Bone_Full"
    },
    {
      "x": -4,
      "y": 17,
      "z": 8,
      "name": "Deco_Salty_Bone_Full"
    },
    {
      "x": -4,
      "y": 18,
      "z": 8,
      "name": "Deco_Salty_Bone_Full"
    },
    {
      "x": -4,
      "y": 14,
      "z": 14,
      "name": "Deco_Salty_Bone_Full"
    },
    {
      "x": -4,
      "y": 12,
      "z": 15,
      "name": "Deco_Salty_Bone_Full"
    },
    {
      "x": -4,
      "y": 13,
      "z": 15,
      "name": "Deco_Salty_Bone_Full"
    },
    {
      "x": -4,
      "y": 14,
      "z": 15,
      "name": "Deco_Salty_Bone_Full"
    },
    {
      "x": -3,
      "y": 15,
      "z": -3,
      "name": "Deco_Salty_Bone_Full"
    },
    {
      "x": -3,
      "y": 16,
      "z": -2,
      "name": "Deco_Salty_Bone_Full"
    },
    {
      "x": -3,
      "y": 17,
      "z": -2,
      "name": "Deco_Salty_Bone_Full"
    },
    {
      "x": -3,
      "y": 16,
      "z": -1,
      "name": "Deco_Salty_Bone_Full"
    },
    {
      "x": -3,
      "y": 18,
      "z": 3,
      "name": "Deco_Salty_Bone_Full"
    },
    {
      "x": -3,
      "y": 18,
      "z": 4,
      "name": "Deco_Salty_Bone_Full"
    },
    {
      "x": -3,
      "y": 19,
      "z": 4,
      "name": "Deco_Salty_Bone_Full"
    },
    {
      "x": -3,
      "y": 18,
      "z": 5,
      "name": "Deco_Salty_Bone_Full"
    },
    {
      "x": -3,
      "y": 18,
      "z": 6,
      "name": "Deco_Salty_Bone_Full"
    },
    {
      "x": -3,
      "y": 17,
      "z": 7,
      "name": "Deco_Salty_Bone_Full"
    },
    {
      "x": -3,
      "y": 18,
      "z": 7,
      "name": "Deco_Salty_Bone_Full"
    },
    {
      "x": -3,
      "y": 0,
      "z": 8,
      "name": "Deco_Salty_Bone_Full"
    },
    {
      "x": -3,
      "y": 1,
      "z": 8,
      "name": "Deco_Salty_Bone_Full"
    },
    {
      "x": -3,
      "y": 17,
      "z": 8,
      "name": "Deco_Salty_Bone_Full"
    },
    {
      "x": -3,
      "y": 16,
      "z": 9,
      "name": "Deco_Salty_Bone_Full"
    },
    {
      "x": -3,
      "y": 9,
      "z": 16,
      "name": "Deco_Salty_Bone_Full"
    },
    {
      "x": -3,
      "y": 10,
      "z": 16,
      "name": "Deco_Salty_Bone_Full"
    },
    {
      "x": -3,
      "y": 11,
      "z": 16,
      "name": "Deco_Salty_Bone_Full"
    },
    {
      "x": -3,
      "y": 12,
      "z": 16,
      "name": "Deco_Salty_Bone_Full"
    },
    {
      "x": -2,
      "y": 16,
      "z": -2,
      "name": "Deco_Salty_Bone_Full"
    },
    {
      "x": -2,
      "y": 17,
      "z": -1,
      "name": "Deco_Salty_Bone_Full"
    },
    {
      "x": -2,
      "y": 17,
      "z": 0,
      "name": "Deco_Salty_Bone_Full"
    },
    {
      "x": -2,
      "y": 18,
      "z": 0,
      "name": "Deco_Salty_Bone_Full"
    },
    {
      "x": -2,
      "y": 18,
      "z": 2,
      "name": "Deco_Salty_Bone_Full"
    },
    {
      "x": -2,
      "y": 18,
      "z": 3,
      "name": "Deco_Salty_Bone_Full"
    },
    {
      "x": -2,
      "y": 19,
      "z": 3,
      "name": "Deco_Salty_Bone_Full"
    },
    {
      "x": -2,
      "y": 18,
      "z": 4,
      "name": "Deco_Salty_Bone_Full"
    },
    {
      "x": -2,
      "y": 16,
      "z": 8,
      "name": "Deco_Salty_Bone_Full"
    },
    {
      "x": -2,
      "y": 1,
      "z": 9,
      "name": "Deco_Salty_Bone_Full"
    },
    {
      "x": -2,
      "y": 16,
      "z": 9,
      "name": "Deco_Salty_Bone_Full"
    },
    {
      "x": -2,
      "y": 17,
      "z": 9,
      "name": "Deco_Salty_Bone_Full"
    },
    {
      "x": -2,
      "y": 16,
      "z": 10,
      "name": "Deco_Salty_Bone_Full"
    },
    {
      "x": -1,
      "y": 17,
      "z": -1,
      "name": "Deco_Salty_Bone_Full"
    },
    {
      "x": -1,
      "y": 18,
      "z": -1,
      "name": "Deco_Salty_Bone_Full"
    },
    {
      "x": -1,
      "y": 17,
      "z": 0,
      "name": "Deco_Salty_Bone_Full"
    },
    {
      "x": -1,
      "y": 18,
      "z": 0,
      "name": "Deco_Salty_Bone_Full"
    },
    {
      "x": -1,
      "y": 17,
      "z": 1,
      "name": "Deco_Salty_Bone_Full"
    },
    {
      "x": -1,
      "y": 18,
      "z": 1,
      "name": "Deco_Salty_Bone_Full"
    },
    {
      "x": -1,
      "y": 19,
      "z": 1,
      "name": "Deco_Salty_Bone_Full"
    },
    {
      "x": -1,
      "y": 20,
      "z": 1,
      "name": "Deco_Salty_Bone_Full"
    },
    {
      "x": -1,
      "y": 17,
      "z": 2,
      "name": "Deco_Salty_Bone_Full"
    },
    {
      "x": -1,
      "y": 18,
      "z": 2,
      "name": "Deco_Salty_Bone_Full"
    },
    {
      "x": -1,
      "y": 19,
      "z": 2,
      "name": "Deco_Salty_Bone_Full"
    },
    {
      "x": -1,
      "y": 20,
      "z": 2,
      "name": "Deco_Salty_Bone_Full"
    },
    {
      "x": -1,
      "y": 21,
      "z": 2,
      "name": "Deco_Salty_Bone_Full"
    },
    {
      "x": -1,
      "y": 18,
      "z": 3,
      "name": "Deco_Salty_Bone_Full"
    },
    {
      "x": -1,
      "y": 16,
      "z": 9,
      "name": "Deco_Salty_Bone_Full"
    },
    {
      "x": -1,
      "y": 1,
      "z": 10,
      "name": "Deco_Salty_Bone_Full"
    },
    {
      "x": -1,
      "y": 2,
      "z": 10,
      "name": "Deco_Salty_Bone_Full"
    },
    {
      "x": -1,
      "y": 15,
      "z": 10,
      "name": "Deco_Salty_Bone_Full"
    },
    {
      "x": -1,
      "y": 16,
      "z": 10,
      "name": "Deco_Salty_Bone_Full"
    },
    {
      "x": -1,
      "y": 15,
      "z": 11,
      "name": "Deco_Salty_Bone_Full"
    },
    {
      "x": 0,
      "y": 18,
      "z": -1,
      "name": "Deco_Salty_Bone_Full"
    },
    {
      "x": 0,
      "y": 17,
      "z": 0,
      "name": "Deco_Salty_Bone_Full"
    },
    {
      "x": 0,
      "y": 18,
      "z": 0,
      "name": "Deco_Salty_Bone_Full"
    },
    {
      "x": 0,
      "y": 19,
      "z": 0,
      "name": "Deco_Salty_Bone_Full"
    },
    {
      "x": 0,
      "y": 16,
      "z": 1,
      "name": "Deco_Salty_Bone_Full"
    },
    {
      "x": 0,
      "y": 17,
      "z": 1,
      "name": "Deco_Salty_Bone_Full"
    },
    {
      "x": 0,
      "y": 18,
      "z": 1,
      "name": "Deco_Salty_Bone_Full"
    },
    {
      "x": 0,
      "y": 19,
      "z": 1,
      "name": "Deco_Salty_Bone_Full"
    },
    {
      "x": 0,
      "y": 20,
      "z": 1,
      "name": "Deco_Salty_Bone_Full"
    },
    {
      "x": 0,
      "y": 21,
      "z": 1,
      "name": "Deco_Salty_Bone_Full"
    },
    {
      "x": 0,
      "y": 22,
      "z": 1,
      "name": "Deco_Salty_Bone_Full"
    },
    {
      "x": 0,
      "y": 23,
      "z": 1,
      "name": "Deco_Salty_Bone_Full"
    },
    {
      "x": 0,
      "y": 17,
      "z": 2,
      "name": "Deco_Salty_Bone_Full"
    },
    {
      "x": 0,
      "y": 18,
      "z": 2,
      "name": "Deco_Salty_Bone_Full"
    },
    {
      "x": 0,
      "y": 19,
      "z": 2,
      "name": "Deco_Salty_Bone_Full"
    },
    {
      "x": 0,
      "y": 20,
      "z": 2,
      "name": "Deco_Salty_Bone_Full"
    },
    {
      "x": 0,
      "y": 15,
      "z": 10,
      "name": "Deco_Salty_Bone_Full"
    },
    {
      "x": 0,
      "y": 2,
      "z": 11,
      "name": "Deco_Salty_Bone_Full"
    },
    {
      "x": 0,
      "y": 3,
      "z": 11,
      "name": "Deco_Salty_Bone_Full"
    },
    {
      "x": 0,
      "y": 4,
      "z": 11,
      "name": "Deco_Salty_Bone_Full"
    },
    {
      "x": 0,
      "y": 13,
      "z": 11,
      "name": "Deco_Salty_Bone_Full"
    },
    {
      "x": 0,
      "y": 14,
      "z": 11,
      "name": "Deco_Salty_Bone_Full"
    },
    {
      "x": 0,
      "y": 15,
      "z": 11,
      "name": "Deco_Salty_Bone_Full"
    },
    {
      "x": 1,
      "y": 10,
      "z": -8,
      "name": "Deco_Salty_Bone_Full"
    },
    {
      "x": 1,
      "y": 11,
      "z": -8,
      "name": "Deco_Salty_Bone_Full"
    },
    {
      "x": 1,
      "y": 12,
      "z": -8,
      "name": "Deco_Salty_Bone_Full"
    },
    {
      "x": 1,
      "y": 13,
      "z": -8,
      "name": "Deco_Salty_Bone_Full"
    },
    {
      "x": 1,
      "y": 14,
      "z": -8,
      "name": "Deco_Salty_Bone_Full"
    },
    {
      "x": 1,
      "y": 15,
      "z": -8,
      "name": "Deco_Salty_Bone_Full"
    },
    {
      "x": 1,
      "y": 15,
      "z": -7,
      "name": "Deco_Salty_Bone_Full"
    },
    {
      "x": 1,
      "y": 18,
      "z": -1,
      "name": "Deco_Salty_Bone_Full"
    },
    {
      "x": 1,
      "y": 18,
      "z": 0,
      "name": "Deco_Salty_Bone_Full"
    },
    {
      "x": 1,
      "y": 19,
      "z": 0,
      "name": "Deco_Salty_Bone_Full"
    },
    {
      "x": 1,
      "y": 20,
      "z": 0,
      "name": "Deco_Salty_Bone_Full"
    },
    {
      "x": 1,
      "y": 21,
      "z": 0,
      "name": "Deco_Salty_Bone_Full"
    },
    {
      "x": 1,
      "y": 22,
      "z": 0,
      "name": "Deco_Salty_Bone_Full"
    },
    {
      "x": 1,
      "y": 23,
      "z": 0,
      "name": "Deco_Salty_Bone_Full"
    },
    {
      "x": 1,
      "y": 24,
      "z": 0,
      "name": "Deco_Salty_Bone_Full"
    },
    {
      "x": 1,
      "y": 17,
      "z": 1,
      "name": "Deco_Salty_Bone_Full"
    },
    {
      "x": 1,
      "y": 18,
      "z": 1,
      "name": "Deco_Salty_Bone_Full"
    },
    {
      "x": 1,
      "y": 19,
      "z": 1,
      "name": "Deco_Salty_Bone_Full"
    },
    {
      "x": 1,
      "y": 17,
      "z": 2,
      "name": "Deco_Salty_Bone_Full"
    },
    {
      "x": 1,
      "y": 18,
      "z": 2,
      "name": "Deco_Salty_Bone_Full"
    },
    {
      "x": 1,
      "y": 17,
      "z": 3,
      "name": "Deco_Salty_Bone_Full"
    },
    {
      "x": 1,
      "y": 18,
      "z": 3,
      "name": "Deco_Salty_Bone_Full"
    },
    {
      "x": 1,
      "y": 4,
      "z": 12,
      "name": "Deco_Salty_Bone_Full"
    },
    {
      "x": 1,
      "y": 5,
      "z": 12,
      "name": "Deco_Salty_Bone_Full"
    },
    {
      "x": 1,
      "y": 6,
      "z": 12,
      "name": "Deco_Salty_Bone_Full"
    },
    {
      "x": 1,
      "y": 7,
      "z": 12,
      "name": "Deco_Salty_Bone_Full"
    },
    {
      "x": 1,
      "y": 8,
      "z": 12,
      "name": "Deco_Salty_Bone_Full"
    },
    {
      "x": 1,
      "y": 9,
      "z": 12,
      "name": "Deco_Salty_Bone_Full"
    },
    {
      "x": 1,
      "y": 10,
      "z": 12,
      "name": "Deco_Salty_Bone_Full"
    },
    {
      "x": 1,
      "y": 11,
      "z": 12,
      "name": "Deco_Salty_Bone_Full"
    },
    {
      "x": 1,
      "y": 12,
      "z": 12,
      "name": "Deco_Salty_Bone_Full"
    },
    {
      "x": 1,
      "y": 13,
      "z": 12,
      "name": "Deco_Salty_Bone_Full"
    },
    {
      "x": 2,
      "y": 15,
      "z": -8,
      "name": "Deco_Salty_Bone_Full"
    },
    {
      "x": 2,
      "y": 7,
      "z": -7,
      "name": "Deco_Salty_Bone_Full"
    },
    {
      "x": 2,
      "y": 8,
      "z": -7,
      "name": "Deco_Salty_Bone_Full"
    },
    {
      "x": 2,
      "y": 9,
      "z": -7,
      "name": "Deco_Salty_Bone_Full"
    },
    {
      "x": 2,
      "y": 10,
      "z": -7,
      "name": "Deco_Salty_Bone_Full"
    },
    {
      "x": 2,
      "y": 15,
      "z": -7,
      "name": "Deco_Salty_Bone_Full"
    },
    {
      "x": 2,
      "y": 16,
      "z": -7,
      "name": "Deco_Salty_Bone_Full"
    },
    {
      "x": 2,
      "y": 17,
      "z": -7,
      "name": "Deco_Salty_Bone_Full"
    },
    {
      "x": 2,
      "y": 16,
      "z": -6,
      "name": "Deco_Salty_Bone_Full"
    },
    {
      "x": 2,
      "y": 18,
      "z": -2,
      "name": "Deco_Salty_Bone_Full"
    },
    {
      "x": 2,
      "y": 18,
      "z": -1,
      "name": "Deco_Salty_Bone_Full"
    },
    {
      "x": 2,
      "y": 19,
      "z": -1,
      "name": "Deco_Salty_Bone_Full"
    },
    {
      "x": 2,
      "y": 18,
      "z": 0,
      "name": "Deco_Salty_Bone_Full"
    },
    {
      "x": 2,
      "y": 18,
      "z": 1,
      "name": "Deco_Salty_Bone_Full"
    },
    {
      "x": 2,
      "y": 17,
      "z": 2,
      "name": "Deco_Salty_Bone_Full"
    },
    {
      "x": 2,
      "y": 18,
      "z": 2,
      "name": "Deco_Salty_Bone_Full"
    },
    {
      "x": 2,
      "y": 17,
      "z": 3,
      "name": "Deco_Salty_Bone_Full"
    },
    {
      "x": 2,
      "y": 16,
      "z": 4,
      "name": "Deco_Salty_Bone_Full"
    },
    {
      "x": 3,
      "y": 16,
      "z": -7,
      "name": "Deco_Salty_Bone_Full"
    },
    {
      "x": 3,
      "y": 6,
      "z": -6,
      "name": "Deco_Salty_Bone_Full"
    },
    {
      "x": 3,
      "y": 7,
      "z": -6,
      "name": "Deco_Salty_Bone_Full"
    },
    {
      "x": 3,
      "y": 16,
      "z": -6,
      "name": "Deco_Salty_Bone_Full"
    },
    {
      "x": 3,
      "y": 17,
      "z": -6,
      "name": "Deco_Salty_Bone_Full"
    },
    {
      "x": 3,
      "y": 18,
      "z": -6,
      "name": "Deco_Salty_Bone_Full"
    },
    {
      "x": 3,
      "y": 17,
      "z": -5,
      "name": "Deco_Salty_Bone_Full"
    },
    {
      "x": 3,
      "y": 18,
      "z": -5,
      "name": "Deco_Salty_Bone_Full"
    },
    {
      "x": 3,
      "y": 18,
      "z": -3,
      "name": "Deco_Salty_Bone_Full"
    },
    {
      "x": 3,
      "y": 18,
      "z": -2,
      "name": "Deco_Salty_Bone_Full"
    },
    {
      "x": 3,
      "y": 19,
      "z": -2,
      "name": "Deco_Salty_Bone_Full"
    },
    {
      "x": 3,
      "y": 18,
      "z": -1,
      "name": "Deco_Salty_Bone_Full"
    },
    {
      "x": 3,
      "y": 16,
      "z": 3,
      "name": "Deco_Salty_Bone_Full"
    },
    {
      "x": 3,
      "y": 16,
      "z": 4,
      "name": "Deco_Salty_Bone_Full"
    },
    {
      "x": 3,
      "y": 17,
      "z": 4,
      "name": "Deco_Salty_Bone_Full"
    },
    {
      "x": 3,
      "y": 15,
      "z": 5,
      "name": "Deco_Salty_Bone_Full"
    },
    {
      "x": 4,
      "y": 17,
      "z": -6,
      "name": "Deco_Salty_Bone_Full"
    },
    {
      "x": 4,
      "y": 18,
      "z": -6,
      "name": "Deco_Salty_Bone_Full"
    },
    {
      "x": 4,
      "y": 17,
      "z": -5,
      "name": "Deco_Salty_Bone_Full"
    },
    {
      "x": 4,
      "y": 18,
      "z": -5,
      "name": "Deco_Salty_Bone_Full"
    },
    {
      "x": 4,
      "y": 17,
      "z": -4,
      "name": "Deco_Salty_Bone_Full"
    },
    {
      "x": 4,
      "y": 18,
      "z": -4,
      "name": "Deco_Salty_Bone_Full"
    },
    {
      "x": 4,
      "y": 19,
      "z": -4,
      "name": "Deco_Salty_Bone_Full"
    },
    {
      "x": 4,
      "y": 20,
      "z": -4,
      "name": "Deco_Salty_Bone_Full"
    },
    {
      "x": 4,
      "y": 17,
      "z": -3,
      "name": "Deco_Salty_Bone_Full"
    },
    {
      "x": 4,
      "y": 18,
      "z": -3,
      "name": "Deco_Salty_Bone_Full"
    },
    {
      "x": 4,
      "y": 19,
      "z": -3,
      "name": "Deco_Salty_Bone_Full"
    },
    {
      "x": 4,
      "y": 20,
      "z": -3,
      "name": "Deco_Salty_Bone_Full"
    },
    {
      "x": 4,
      "y": 21,
      "z": -3,
      "name": "Deco_Salty_Bone_Full"
    },
    {
      "x": 4,
      "y": 18,
      "z": -2,
      "name": "Deco_Salty_Bone_Full"
    },
    {
      "x": 4,
      "y": 15,
      "z": 4,
      "name": "Deco_Salty_Bone_Full"
    },
    {
      "x": 4,
      "y": 3,
      "z": 5,
      "name": "Deco_Salty_Bone_Full"
    },
    {
      "x": 4,
      "y": 4,
      "z": 5,
      "name": "Deco_Salty_Bone_Full"
    },
    {
      "x": 4,
      "y": 5,
      "z": 5,
      "name": "Deco_Salty_Bone_Full"
    },
    {
      "x": 4,
      "y": 15,
      "z": 5,
      "name": "Deco_Salty_Bone_Full"
    },
    {
      "x": 4,
      "y": 16,
      "z": 5,
      "name": "Deco_Salty_Bone_Full"
    },
    {
      "x": 4,
      "y": 15,
      "z": 6,
      "name": "Deco_Salty_Bone_Full"
    },
    {
      "x": 5,
      "y": 18,
      "z": -6,
      "name": "Deco_Salty_Bone_Full"
    },
    {
      "x": 5,
      "y": 17,
      "z": -5,
      "name": "Deco_Salty_Bone_Full"
    },
    {
      "x": 5,
      "y": 18,
      "z": -5,
      "name": "Deco_Salty_Bone_Full"
    },
    {
      "x": 5,
      "y": 19,
      "z": -5,
      "name": "Deco_Salty_Bone_Full"
    },
    {
      "x": 5,
      "y": 16,
      "z": -4,
      "name": "Deco_Salty_Bone_Full"
    },
    {
      "x": 5,
      "y": 17,
      "z": -4,
      "name": "Deco_Salty_Bone_Full"
    },
    {
      "x": 5,
      "y": 18,
      "z": -4,
      "name": "Deco_Salty_Bone_Full"
    },
    {
      "x": 5,
      "y": 19,
      "z": -4,
      "name": "Deco_Salty_Bone_Full"
    },
    {
      "x": 5,
      "y": 20,
      "z": -4,
      "name": "Deco_Salty_Bone_Full"
    },
    {
      "x": 5,
      "y": 21,
      "z": -4,
      "name": "Deco_Salty_Bone_Full"
    },
    {
      "x": 5,
      "y": 22,
      "z": -4,
      "name": "Deco_Salty_Bone_Spike_Large"
    },
    {
      "x": 5,
      "y": 17,
      "z": -3,
      "name": "Deco_Salty_Bone_Full"
    },
    {
      "x": 5,
      "y": 18,
      "z": -3,
      "name": "Deco_Salty_Bone_Full"
    },
    {
      "x": 5,
      "y": 19,
      "z": -3,
      "name": "Deco_Salty_Bone_Full"
    },
    {
      "x": 5,
      "y": 20,
      "z": -3,
      "name": "Deco_Salty_Bone_Full"
    },
    {
      "x": 5,
      "y": 15,
      "z": 5,
      "name": "Deco_Salty_Bone_Full"
    },
    {
      "x": 5,
      "y": 5,
      "z": 6,
      "name": "Deco_Salty_Bone_Full"
    },
    {
      "x": 5,
      "y": 6,
      "z": 6,
      "name": "Deco_Salty_Bone_Full"
    },
    {
      "x": 5,
      "y": 7,
      "z": 6,
      "name": "Deco_Salty_Bone_Full"
    },
    {
      "x": 5,
      "y": 13,
      "z": 6,
      "name": "Deco_Salty_Bone_Full"
    },
    {
      "x": 5,
      "y": 14,
      "z": 6,
      "name": "Deco_Salty_Bone_Full"
    },
    {
      "x": 5,
      "y": 15,
      "z": 6,
      "name": "Deco_Salty_Bone_Full"
    },
    {
      "x": 6,
      "y": 18,
      "z": -6,
      "name": "Deco_Salty_Bone_Full"
    },
    {
      "x": 6,
      "y": 18,
      "z": -5,
      "name": "Deco_Salty_Bone_Full"
    },
    {
      "x": 6,
      "y": 19,
      "z": -5,
      "name": "Deco_Salty_Bone_Full"
    },
    {
      "x": 6,
      "y": 20,
      "z": -5,
      "name": "Deco_Salty_Bone_Full"
    },
    {
      "x": 6,
      "y": 17,
      "z": -4,
      "name": "Deco_Salty_Bone_Full"
    },
    {
      "x": 6,
      "y": 18,
      "z": -4,
      "name": "Deco_Salty_Bone_Full"
    },
    {
      "x": 6,
      "y": 19,
      "z": -4,
      "name": "Deco_Salty_Bone_Full"
    },
    {
      "x": 6,
      "y": 17,
      "z": -3,
      "name": "Deco_Salty_Bone_Full"
    },
    {
      "x": 6,
      "y": 18,
      "z": -3,
      "name": "Deco_Salty_Bone_Full"
    },
    {
      "x": 6,
      "y": 17,
      "z": -2,
      "name": "Deco_Salty_Bone_Full"
    },
    {
      "x": 6,
      "y": 18,
      "z": -2,
      "name": "Deco_Salty_Bone_Full"
    },
    {
      "x": 6,
      "y": 7,
      "z": 7,
      "name": "Deco_Salty_Bone_Full"
    },
    {
      "x": 6,
      "y": 8,
      "z": 7,
      "name": "Deco_Salty_Bone_Full"
    },
    {
      "x": 6,
      "y": 9,
      "z": 7,
      "name": "Deco_Salty_Bone_Full"
    },
    {
      "x": 6,
      "y": 10,
      "z": 7,
      "name": "Deco_Salty_Bone_Full"
    },
    {
      "x": 6,
      "y": 11,
      "z": 7,
      "name": "Deco_Salty_Bone_Full"
    },
    {
      "x": 6,
      "y": 12,
      "z": 7,
      "name": "Deco_Salty_Bone_Full"
    },
    {
      "x": 6,
      "y": 13,
      "z": 7,
      "name": "Deco_Salty_Bone_Full"
    },
    {
      "x": 7,
      "y": 9,
      "z": -12,
      "name": "Deco_Salty_Bone_Full"
    },
    {
      "x": 7,
      "y": 10,
      "z": -12,
      "name": "Deco_Salty_Bone_Full"
    },
    {
      "x": 7,
      "y": 11,
      "z": -12,
      "name": "Deco_Salty_Bone_Full"
    },
    {
      "x": 7,
      "y": 12,
      "z": -12,
      "name": "Deco_Salty_Bone_Full"
    },
    {
      "x": 7,
      "y": 13,
      "z": -12,
      "name": "Deco_Salty_Bone_Full"
    },
    {
      "x": 7,
      "y": 14,
      "z": -12,
      "name": "Deco_Salty_Bone_Full"
    },
    {
      "x": 7,
      "y": 15,
      "z": -12,
      "name": "Deco_Salty_Bone_Full"
    },
    {
      "x": 7,
      "y": 15,
      "z": -11,
      "name": "Deco_Salty_Bone_Full"
    },
    {
      "x": 7,
      "y": 18,
      "z": -7,
      "name": "Deco_Salty_Bone_Full"
    },
    {
      "x": 7,
      "y": 18,
      "z": -6,
      "name": "Deco_Salty_Bone_Full"
    },
    {
      "x": 7,
      "y": 19,
      "z": -6,
      "name": "Deco_Salty_Bone_Full"
    },
    {
      "x": 7,
      "y": 18,
      "z": -5,
      "name": "Deco_Salty_Bone_Full"
    },
    {
      "x": 7,
      "y": 18,
      "z": -4,
      "name": "Deco_Salty_Bone_Full"
    },
    {
      "x": 7,
      "y": 17,
      "z": -3,
      "name": "Deco_Salty_Bone_Full"
    },
    {
      "x": 7,
      "y": 18,
      "z": -3,
      "name": "Deco_Salty_Bone_Full"
    },
    {
      "x": 7,
      "y": 16,
      "z": -2,
      "name": "Deco_Salty_Bone_Full"
    },
    {
      "x": 7,
      "y": 17,
      "z": -2,
      "name": "Deco_Salty_Bone_Full"
    },
    {
      "x": 7,
      "y": 18,
      "z": -2,
      "name": "Deco_Salty_Bone_Full"
    },
    {
      "x": 7,
      "y": 16,
      "z": -1,
      "name": "Deco_Salty_Bone_Full"
    },
    {
      "x": 8,
      "y": 15,
      "z": -12,
      "name": "Deco_Salty_Bone_Full"
    },
    {
      "x": 8,
      "y": 8,
      "z": -11,
      "name": "Deco_Salty_Bone_Full"
    },
    {
      "x": 8,
      "y": 9,
      "z": -11,
      "name": "Deco_Salty_Bone_Full"
    },
    {
      "x": 8,
      "y": 15,
      "z": -11,
      "name": "Deco_Salty_Bone_Full"
    },
    {
      "x": 8,
      "y": 16,
      "z": -11,
      "name": "Deco_Salty_Bone_Full"
    },
    {
      "x": 8,
      "y": 16,
      "z": -10,
      "name": "Deco_Salty_Bone_Full"
    },
    {
      "x": 8,
      "y": 17,
      "z": -10,
      "name": "Deco_Salty_Bone_Full"
    },
    {
      "x": 8,
      "y": 17,
      "z": -8,
      "name": "Deco_Salty_Bone_Full"
    },
    {
      "x": 8,
      "y": 17,
      "z": -7,
      "name": "Deco_Salty_Bone_Full"
    },
    {
      "x": 8,
      "y": 18,
      "z": -7,
      "name": "Deco_Salty_Bone_Full"
    },
    {
      "x": 8,
      "y": 18,
      "z": -6,
      "name": "Deco_Salty_Bone_Full"
    },
    {
      "x": 8,
      "y": 16,
      "z": -2,
      "name": "Deco_Salty_Bone_Full"
    },
    {
      "x": 8,
      "y": 15,
      "z": -1,
      "name": "Deco_Salty_Bone_Full"
    },
    {
      "x": 8,
      "y": 16,
      "z": -1,
      "name": "Deco_Salty_Bone_Full"
    },
    {
      "x": 8,
      "y": 17,
      "z": -1,
      "name": "Deco_Salty_Bone_Full"
    },
    {
      "x": 8,
      "y": 15,
      "z": 0,
      "name": "Deco_Salty_Bone_Full"
    },
    {
      "x": 9,
      "y": 16,
      "z": -11,
      "name": "Deco_Salty_Bone_Full"
    },
    {
      "x": 9,
      "y": 17,
      "z": -11,
      "name": "Deco_Salty_Bone_Full"
    },
    {
      "x": 9,
      "y": 16,
      "z": -10,
      "name": "Deco_Salty_Bone_Full"
    },
    {
      "x": 9,
      "y": 17,
      "z": -10,
      "name": "Deco_Salty_Bone_Full"
    },
    {
      "x": 9,
      "y": 16,
      "z": -9,
      "name": "Deco_Salty_Bone_Full"
    },
    {
      "x": 9,
      "y": 17,
      "z": -9,
      "name": "Deco_Salty_Bone_Full"
    },
    {
      "x": 9,
      "y": 18,
      "z": -9,
      "name": "Deco_Salty_Bone_Full"
    },
    {
      "x": 9,
      "y": 19,
      "z": -9,
      "name": "Deco_Salty_Bone_Full"
    },
    {
      "x": 9,
      "y": 16,
      "z": -8,
      "name": "Deco_Salty_Bone_Full"
    },
    {
      "x": 9,
      "y": 17,
      "z": -8,
      "name": "Deco_Salty_Bone_Full"
    },
    {
      "x": 9,
      "y": 18,
      "z": -8,
      "name": "Deco_Salty_Bone_Full"
    },
    {
      "x": 9,
      "y": 19,
      "z": -8,
      "name": "Deco_Salty_Bone_Full"
    },
    {
      "x": 9,
      "y": 20,
      "z": -8,
      "name": "Deco_Salty_Bone_Full"
    },
    {
      "x": 9,
      "y": 17,
      "z": -7,
      "name": "Deco_Salty_Bone_Full"
    },
    {
      "x": 9,
      "y": 15,
      "z": -1,
      "name": "Deco_Salty_Bone_Full"
    },
    {
      "x": 9,
      "y": 11,
      "z": 0,
      "name": "Deco_Salty_Bone_Full"
    },
    {
      "x": 9,
      "y": 12,
      "z": 0,
      "name": "Deco_Salty_Bone_Full"
    },
    {
      "x": 9,
      "y": 13,
      "z": 0,
      "name": "Deco_Salty_Bone_Full"
    },
    {
      "x": 9,
      "y": 14,
      "z": 0,
      "name": "Deco_Salty_Bone_Full"
    },
    {
      "x": 9,
      "y": 15,
      "z": 0,
      "name": "Deco_Salty_Bone_Full"
    },
    {
      "x": 10,
      "y": 17,
      "z": -11,
      "name": "Deco_Salty_Bone_Full"
    },
    {
      "x": 10,
      "y": 16,
      "z": -10,
      "name": "Deco_Salty_Bone_Full"
    },
    {
      "x": 10,
      "y": 17,
      "z": -10,
      "name": "Deco_Salty_Bone_Full"
    },
    {
      "x": 10,
      "y": 18,
      "z": -10,
      "name": "Deco_Salty_Bone_Full"
    },
    {
      "x": 10,
      "y": 15,
      "z": -9,
      "name": "Deco_Salty_Bone_Full"
    },
    {
      "x": 10,
      "y": 16,
      "z": -9,
      "name": "Deco_Salty_Bone_Full"
    },
    {
      "x": 10,
      "y": 17,
      "z": -9,
      "name": "Deco_Salty_Bone_Full"
    },
    {
      "x": 10,
      "y": 18,
      "z": -9,
      "name": "Deco_Salty_Bone_Full"
    },
    {
      "x": 10,
      "y": 19,
      "z": -9,
      "name": "Deco_Salty_Bone_Full"
    },
    {
      "x": 10,
      "y": 20,
      "z": -9,
      "name": "Deco_Salty_Bone_Full"
    },
    {
      "x": 10,
      "y": 21,
      "z": -9,
      "name": "Deco_Salty_Bone_Full"
    },
    {
      "x": 10,
      "y": 22,
      "z": -9,
      "name": "Deco_Salty_Bone_Full"
    },
    {
      "x": 10,
      "y": 16,
      "z": -8,
      "name": "Deco_Salty_Bone_Full"
    },
    {
      "x": 10,
      "y": 17,
      "z": -8,
      "name": "Deco_Salty_Bone_Full"
    },
    {
      "x": 10,
      "y": 18,
      "z": -8,
      "name": "Deco_Salty_Bone_Full"
    },
    {
      "x": 10,
      "y": 19,
      "z": -8,
      "name": "Deco_Salty_Bone_Full"
    },
    {
      "x": 11,
      "y": 17,
      "z": -11,
      "name": "Deco_Salty_Bone_Full"
    },
    {
      "x": 11,
      "y": 17,
      "z": -10,
      "name": "Deco_Salty_Bone_Full"
    },
    {
      "x": 11,
      "y": 18,
      "z": -10,
      "name": "Deco_Salty_Bone_Full"
    },
    {
      "x": 11,
      "y": 19,
      "z": -10,
      "name": "Deco_Salty_Bone_Full"
    },
    {
      "x": 11,
      "y": 20,
      "z": -10,
      "name": "Deco_Salty_Bone_Full"
    },
    {
      "x": 11,
      "y": 21,
      "z": -10,
      "name": "Deco_Salty_Bone_Full"
    },
    {
      "x": 11,
      "y": 22,
      "z": -10,
      "name": "Deco_Salty_Bone_Full"
    },
    {
      "x": 11,
      "y": 23,
      "z": -10,
      "name": "Deco_Salty_Bone_Full"
    },
    {
      "x": 11,
      "y": 24,
      "z": -10,
      "name": "Deco_Salty_Bone_Spike_Large"
    },
    {
      "x": 11,
      "y": 16,
      "z": -9,
      "name": "Deco_Salty_Bone_Full"
    },
    {
      "x": 11,
      "y": 17,
      "z": -9,
      "name": "Deco_Salty_Bone_Full"
    },
    {
      "x": 11,
      "y": 18,
      "z": -9,
      "name": "Deco_Salty_Bone_Full"
    },
    {
      "x": 11,
      "y": 16,
      "z": -8,
      "name": "Deco_Salty_Bone_Full"
    },
    {
      "x": 11,
      "y": 17,
      "z": -8,
      "name": "Deco_Salty_Bone_Full"
    },
    {
      "x": 11,
      "y": 16,
      "z": -7,
      "name": "Deco_Salty_Bone_Full"
    },
    {
      "x": 11,
      "y": 17,
      "z": -7,
      "name": "Deco_Salty_Bone_Full"
    },
    {
      "x": 12,
      "y": 11,
      "z": -17,
      "name": "Deco_Salty_Bone_Full"
    },
    {
      "x": 12,
      "y": 12,
      "z": -17,
      "name": "Deco_Salty_Bone_Full"
    },
    {
      "x": 12,
      "y": 13,
      "z": -17,
      "name": "Deco_Salty_Bone_Full"
    },
    {
      "x": 12,
      "y": 14,
      "z": -17,
      "name": "Deco_Salty_Bone_Full"
    },
    {
      "x": 12,
      "y": 14,
      "z": -16,
      "name": "Deco_Salty_Bone_Full"
    },
    {
      "x": 12,
      "y": 17,
      "z": -12,
      "name": "Deco_Salty_Bone_Full"
    },
    {
      "x": 12,
      "y": 17,
      "z": -11,
      "name": "Deco_Salty_Bone_Full"
    },
    {
      "x": 12,
      "y": 18,
      "z": -11,
      "name": "Deco_Salty_Bone_Full"
    },
    {
      "x": 12,
      "y": 17,
      "z": -10,
      "name": "Deco_Salty_Bone_Full"
    },
    {
      "x": 12,
      "y": 17,
      "z": -9,
      "name": "Deco_Salty_Bone_Full"
    },
    {
      "x": 12,
      "y": 16,
      "z": -8,
      "name": "Deco_Salty_Bone_Full"
    },
    {
      "x": 12,
      "y": 17,
      "z": -8,
      "name": "Deco_Salty_Bone_Full"
    },
    {
      "x": 12,
      "y": 8,
      "z": -7,
      "name": "Deco_Salty_Bone_Full"
    },
    {
      "x": 12,
      "y": 9,
      "z": -7,
      "name": "Deco_Salty_Bone_Full"
    },
    {
      "x": 12,
      "y": 15,
      "z": -7,
      "name": "Deco_Salty_Bone_Full"
    },
    {
      "x": 12,
      "y": 16,
      "z": -7,
      "name": "Deco_Salty_Bone_Full"
    },
    {
      "x": 12,
      "y": 15,
      "z": -6,
      "name": "Deco_Salty_Bone_Full"
    },
    {
      "x": 13,
      "y": 14,
      "z": -17,
      "name": "Deco_Salty_Bone_Full"
    },
    {
      "x": 13,
      "y": 14,
      "z": -16,
      "name": "Deco_Salty_Bone_Full"
    },
    {
      "x": 13,
      "y": 15,
      "z": -16,
      "name": "Deco_Salty_Bone_Full"
    },
    {
      "x": 13,
      "y": 15,
      "z": -15,
      "name": "Deco_Salty_Bone_Full"
    },
    {
      "x": 13,
      "y": 16,
      "z": -15,
      "name": "Deco_Salty_Bone_Full"
    },
    {
      "x": 13,
      "y": 16,
      "z": -13,
      "name": "Deco_Salty_Bone_Full"
    },
    {
      "x": 13,
      "y": 16,
      "z": -12,
      "name": "Deco_Salty_Bone_Full"
    },
    {
      "x": 13,
      "y": 17,
      "z": -12,
      "name": "Deco_Salty_Bone_Full"
    },
    {
      "x": 13,
      "y": 17,
      "z": -11,
      "name": "Deco_Salty_Bone_Full"
    },
    {
      "x": 13,
      "y": 15,
      "z": -7,
      "name": "Deco_Salty_Bone_Full"
    },
    {
      "x": 13,
      "y": 9,
      "z": -6,
      "name": "Deco_Salty_Bone_Full"
    },
    {
      "x": 13,
      "y": 10,
      "z": -6,
      "name": "Deco_Salty_Bone_Full"
    },
    {
      "x": 13,
      "y": 11,
      "z": -6,
      "name": "Deco_Salty_Bone_Full"
    },
    {
      "x": 13,
      "y": 12,
      "z": -6,
      "name": "Deco_Salty_Bone_Full"
    },
    {
      "x": 13,
      "y": 13,
      "z": -6,
      "name": "Deco_Salty_Bone_Full"
    },
    {
      "x": 13,
      "y": 14,
      "z": -6,
      "name": "Deco_Salty_Bone_Full"
    },
    {
      "x": 13,
      "y": 15,
      "z": -6,
      "name": "Deco_Salty_Bone_Full"
    },
    {
      "x": 14,
      "y": 15,
      "z": -16,
      "name": "Deco_Salty_Bone_Full"
    },
    {
      "x": 14,
      "y": 16,
      "z": -16,
      "name": "Deco_Salty_Bone_Full"
    },
    {
      "x": 14,
      "y": 15,
      "z": -15,
      "name": "Deco_Salty_Bone_Full"
    },
    {
      "x": 14,
      "y": 16,
      "z": -15,
      "name": "Deco_Salty_Bone_Full"
    },
    {
      "x": 14,
      "y": 15,
      "z": -14,
      "name": "Deco_Salty_Bone_Full"
    },
    {
      "x": 14,
      "y": 16,
      "z": -14,
      "name": "Deco_Salty_Bone_Full"
    },
    {
      "x": 14,
      "y": 17,
      "z": -14,
      "name": "Deco_Salty_Bone_Full"
    },
    {
      "x": 14,
      "y": 18,
      "z": -14,
      "name": "Deco_Salty_Bone_Full"
    },
    {
      "x": 14,
      "y": 15,
      "z": -13,
      "name": "Deco_Salty_Bone_Full"
    },
    {
      "x": 14,
      "y": 16,
      "z": -13,
      "name": "Deco_Salty_Bone_Full"
    },
    {
      "x": 14,
      "y": 17,
      "z": -13,
      "name": "Deco_Salty_Bone_Full"
    },
    {
      "x": 14,
      "y": 18,
      "z": -13,
      "name": "Deco_Salty_Bone_Full"
    },
    {
      "x": 14,
      "y": 19,
      "z": -13,
      "name": "Deco_Salty_Bone_Full"
    },
    {
      "x": 14,
      "y": 16,
      "z": -12,
      "name": "Deco_Salty_Bone_Full"
    },
    {
      "x": 15,
      "y": 16,
      "z": -16,
      "name": "Deco_Salty_Bone_Full"
    },
    {
      "x": 15,
      "y": 15,
      "z": -15,
      "name": "Deco_Salty_Bone_Full"
    },
    {
      "x": 15,
      "y": 16,
      "z": -15,
      "name": "Deco_Salty_Bone_Full"
    },
    {
      "x": 15,
      "y": 17,
      "z": -15,
      "name": "Deco_Salty_Bone_Full"
    },
    {
      "x": 15,
      "y": 14,
      "z": -14,
      "name": "Deco_Salty_Bone_Full"
    },
    {
      "x": 15,
      "y": 15,
      "z": -14,
      "name": "Deco_Salty_Bone_Full"
    },
    {
      "x": 15,
      "y": 16,
      "z": -14,
      "name": "Deco_Salty_Bone_Full"
    },
    {
      "x": 15,
      "y": 17,
      "z": -14,
      "name": "Deco_Salty_Bone_Full"
    },
    {
      "x": 15,
      "y": 18,
      "z": -14,
      "name": "Deco_Salty_Bone_Full"
    },
    {
      "x": 15,
      "y": 19,
      "z": -14,
      "name": "Deco_Salty_Bone_Full"
    },
    {
      "x": 15,
      "y": 20,
      "z": -14,
      "name": "Deco_Salty_Bone_Spike"
    },
    {
      "x": 15,
      "y": 15,
      "z": -13,
      "name": "Deco_Salty_Bone_Full"
    },
    {
      "x": 15,
      "y": 16,
      "z": -13,
      "name": "Deco_Salty_Bone_Full"
    },
    {
      "x": 15,
      "y": 17,
      "z": -13,
      "name": "Deco_Salty_Bone_Full"
    },
    {
      "x": 15,
      "y": 18,
      "z": -13,
      "name": "Deco_Salty_Bone_Full"
    },
    {
      "x": 16,
      "y": 16,
      "z": -16,
      "name": "Deco_Salty_Bone_Full"
    },
    {
      "x": 16,
      "y": 16,
      "z": -15,
      "name": "Deco_Salty_Bone_Full"
    },
    {
      "x": 16,
      "y": 17,
      "z": -15,
      "name": "Deco_Salty_Bone_Full"
    },
    {
      "x": 16,
      "y": 18,
      "z": -15,
      "name": "Deco_Salty_Bone_Full"
    },
    {
      "x": 16,
      "y": 15,
      "z": -14,
      "name": "Deco_Salty_Bone_Full"
    },
    {
      "x": 16,
      "y": 16,
      "z": -14,
      "name": "Deco_Salty_Bone_Full"
    },
    {
      "x": 16,
      "y": 17,
      "z": -14,
      "name": "Deco_Salty_Bone_Full"
    },
    {
      "x": 16,
      "y": 15,
      "z": -13,
      "name": "Deco_Salty_Bone_Full"
    },
    {
      "x": 16,
      "y": 16,
      "z": -13,
      "name": "Deco_Salty_Bone_Full"
    },
    {
      "x": 16,
      "y": 15,
      "z": -12,
      "name": "Deco_Salty_Bone_Full"
    },
    {
      "x": 16,
      "y": 16,
      "z": -12,
      "name": "Deco_Salty_Bone_Full"
    },
    {
      "x": 17,
      "y": 9,
      "z": -22,
      "name": "Deco_Salty_Bone_Full"
    },
    {
      "x": 17,
      "y": 10,
      "z": -22,
      "name": "Deco_Salty_Bone_Full"
    },
    {
      "x": 17,
      "y": 11,
      "z": -22,
      "name": "Deco_Salty_Bone_Full"
    },
    {
      "x": 17,
      "y": 12,
      "z": -22,
      "name": "Deco_Salty_Bone_Full"
    },
    {
      "x": 17,
      "y": 13,
      "z": -22,
      "name": "Deco_Salty_Bone_Full"
    },
    {
      "x": 17,
      "y": 13,
      "z": -21,
      "name": "Deco_Salty_Bone_Full"
    },
    {
      "x": 17,
      "y": 15,
      "z": -17,
      "name": "Deco_Salty_Bone_Full"
    },
    {
      "x": 17,
      "y": 15,
      "z": -16,
      "name": "Deco_Salty_Bone_Full"
    },
    {
      "x": 17,
      "y": 16,
      "z": -16,
      "name": "Deco_Salty_Bone_Full"
    },
    {
      "x": 17,
      "y": 16,
      "z": -15,
      "name": "Deco_Salty_Bone_Full"
    },
    {
      "x": 17,
      "y": 16,
      "z": -14,
      "name": "Deco_Salty_Bone_Full"
    },
    {
      "x": 17,
      "y": 15,
      "z": -13,
      "name": "Deco_Salty_Bone_Full"
    },
    {
      "x": 17,
      "y": 16,
      "z": -13,
      "name": "Deco_Salty_Bone_Full"
    },
    {
      "x": 17,
      "y": 8,
      "z": -12,
      "name": "Deco_Salty_Bone_Full"
    },
    {
      "x": 17,
      "y": 9,
      "z": -12,
      "name": "Deco_Salty_Bone_Full"
    },
    {
      "x": 17,
      "y": 14,
      "z": -12,
      "name": "Deco_Salty_Bone_Full"
    },
    {
      "x": 17,
      "y": 15,
      "z": -12,
      "name": "Deco_Salty_Bone_Full"
    },
    {
      "x": 17,
      "y": 14,
      "z": -11,
      "name": "Deco_Salty_Bone_Full"
    },
    {
      "x": 18,
      "y": 13,
      "z": -22,
      "name": "Deco_Salty_Bone_Full"
    },
    {
      "x": 18,
      "y": 8,
      "z": -21,
      "name": "Deco_Salty_Bone_Full"
    },
    {
      "x": 18,
      "y": 9,
      "z": -21,
      "name": "Deco_Salty_Bone_Full"
    },
    {
      "x": 18,
      "y": 13,
      "z": -21,
      "name": "Deco_Salty_Bone_Full"
    },
    {
      "x": 18,
      "y": 14,
      "z": -21,
      "name": "Deco_Salty_Bone_Full"
    },
    {
      "x": 18,
      "y": 14,
      "z": -20,
      "name": "Deco_Salty_Bone_Full"
    },
    {
      "x": 18,
      "y": 15,
      "z": -20,
      "name": "Deco_Salty_Bone_Full"
    },
    {
      "x": 18,
      "y": 15,
      "z": -18,
      "name": "Deco_Salty_Bone_Full"
    },
    {
      "x": 18,
      "y": 15,
      "z": -17,
      "name": "Deco_Salty_Bone_Full"
    },
    {
      "x": 18,
      "y": 16,
      "z": -17,
      "name": "Deco_Salty_Bone_Full"
    },
    {
      "x": 18,
      "y": 15,
      "z": -16,
      "name": "Deco_Salty_Bone_Full"
    },
    {
      "x": 18,
      "y": 14,
      "z": -12,
      "name": "Deco_Salty_Bone_Full"
    },
    {
      "x": 18,
      "y": 9,
      "z": -11,
      "name": "Deco_Salty_Bone_Full"
    },
    {
      "x": 18,
      "y": 10,
      "z": -11,
      "name": "Deco_Salty_Bone_Full"
    },
    {
      "x": 18,
      "y": 11,
      "z": -11,
      "name": "Deco_Salty_Bone_Full"
    },
    {
      "x": 18,
      "y": 12,
      "z": -11,
      "name": "Deco_Salty_Bone_Full"
    },
    {
      "x": 18,
      "y": 13,
      "z": -11,
      "name": "Deco_Salty_Bone_Full"
    },
    {
      "x": 18,
      "y": 14,
      "z": -11,
      "name": "Deco_Salty_Bone_Full"
    },
    {
      "x": 19,
      "y": 14,
      "z": -21,
      "name": "Deco_Salty_Bone_Full"
    },
    {
      "x": 19,
      "y": 15,
      "z": -21,
      "name": "Deco_Salty_Bone_Full"
    },
    {
      "x": 19,
      "y": 14,
      "z": -20,
      "name": "Deco_Salty_Bone_Full"
    },
    {
      "x": 19,
      "y": 15,
      "z": -20,
      "name": "Deco_Salty_Bone_Full"
    },
    {
      "x": 19,
      "y": 14,
      "z": -19,
      "name": "Deco_Salty_Bone_Full"
    },
    {
      "x": 19,
      "y": 15,
      "z": -19,
      "name": "Deco_Salty_Bone_Full"
    },
    {
      "x": 19,
      "y": 16,
      "z": -19,
      "name": "Deco_Salty_Bone_Full"
    },
    {
      "x": 19,
      "y": 17,
      "z": -19,
      "name": "Deco_Salty_Bone_Full"
    },
    {
      "x": 19,
      "y": 14,
      "z": -18,
      "name": "Deco_Salty_Bone_Full"
    },
    {
      "x": 19,
      "y": 15,
      "z": -18,
      "name": "Deco_Salty_Bone_Full"
    },
    {
      "x": 19,
      "y": 16,
      "z": -18,
      "name": "Deco_Salty_Bone_Full"
    },
    {
      "x": 19,
      "y": 17,
      "z": -18,
      "name": "Deco_Salty_Bone_Full"
    },
    {
      "x": 19,
      "y": 18,
      "z": -18,
      "name": "Deco_Salty_Bone_Full"
    },
    {
      "x": 19,
      "y": 15,
      "z": -17,
      "name": "Deco_Salty_Bone_Full"
    },
    {
      "x": 20,
      "y": 15,
      "z": -21,
      "name": "Deco_Salty_Bone_Full"
    },
    {
      "x": 20,
      "y": 14,
      "z": -20,
      "name": "Deco_Salty_Bone_Full"
    },
    {
      "x": 20,
      "y": 15,
      "z": -20,
      "name": "Deco_Salty_Bone_Full"
    },
    {
      "x": 20,
      "y": 16,
      "z": -20,
      "name": "Deco_Salty_Bone_Full"
    },
    {
      "x": 20,
      "y": 13,
      "z": -19,
      "name": "Deco_Salty_Bone_Full"
    },
    {
      "x": 20,
      "y": 14,
      "z": -19,
      "name": "Deco_Salty_Bone_Full"
    },
    {
      "x": 20,
      "y": 15,
      "z": -19,
      "name": "Deco_Salty_Bone_Full"
    },
    {
      "x": 20,
      "y": 16,
      "z": -19,
      "name": "Deco_Salty_Bone_Full"
    },
    {
      "x": 20,
      "y": 17,
      "z": -19,
      "name": "Deco_Salty_Bone_Full"
    },
    {
      "x": 20,
      "y": 18,
      "z": -19,
      "name": "Deco_Salty_Bone_Full"
    },
    {
      "x": 20,
      "y": 19,
      "z": -19,
      "name": "Deco_Salty_Bone_Full"
    },
    {
      "x": 20,
      "y": 20,
      "z": -19,
      "name": "Deco_Salty_Bone_Spike"
    },
    {
      "x": 20,
      "y": 14,
      "z": -18,
      "name": "Deco_Salty_Bone_Full"
    },
    {
      "x": 20,
      "y": 15,
      "z": -18,
      "name": "Deco_Salty_Bone_Full"
    },
    {
      "x": 20,
      "y": 16,
      "z": -18,
      "name": "Deco_Salty_Bone_Full"
    },
    {
      "x": 20,
      "y": 17,
      "z": -18,
      "name": "Deco_Salty_Bone_Full"
    },
    {
      "x": 21,
      "y": 14,
      "z": -21,
      "name": "Deco_Salty_Bone_Full"
    },
    {
      "x": 21,
      "y": 14,
      "z": -20,
      "name": "Deco_Salty_Bone_Full"
    },
    {
      "x": 21,
      "y": 15,
      "z": -20,
      "name": "Deco_Salty_Bone_Full"
    },
    {
      "x": 21,
      "y": 16,
      "z": -20,
      "name": "Deco_Salty_Bone_Full"
    },
    {
      "x": 21,
      "y": 17,
      "z": -20,
      "name": "Deco_Salty_Bone_Full"
    },
    {
      "x": 21,
      "y": 18,
      "z": -20,
      "name": "Deco_Salty_Bone_Full"
    },
    {
      "x": 21,
      "y": 19,
      "z": -20,
      "name": "Deco_Salty_Bone_Full"
    },
    {
      "x": 21,
      "y": 14,
      "z": -19,
      "name": "Deco_Salty_Bone_Full"
    },
    {
      "x": 21,
      "y": 15,
      "z": -19,
      "name": "Deco_Salty_Bone_Full"
    },
    {
      "x": 21,
      "y": 16,
      "z": -19,
      "name": "Deco_Salty_Bone_Full"
    },
    {
      "x": 21,
      "y": 14,
      "z": -18,
      "name": "Deco_Salty_Bone_Full"
    },
    {
      "x": 21,
      "y": 15,
      "z": -18,
      "name": "Deco_Salty_Bone_Full"
    },
    {
      "x": 21,
      "y": 14,
      "z": -17,
      "name": "Deco_Salty_Bone_Full"
    },
    {
      "x": 21,
      "y": 15,
      "z": -17,
      "name": "Deco_Salty_Bone_Full"
    },
    {
      "x": 22,
      "y": 14,
      "z": -22,
      "name": "Deco_Salty_Bone_Full"
    },
    {
      "x": 22,
      "y": 14,
      "z": -21,
      "name": "Deco_Salty_Bone_Full"
    },
    {
      "x": 22,
      "y": 15,
      "z": -21,
      "name": "Deco_Salty_Bone_Full"
    },
    {
      "x": 22,
      "y": 14,
      "z": -20,
      "name": "Deco_Salty_Bone_Full"
    },
    {
      "x": 22,
      "y": 15,
      "z": -19,
      "name": "Deco_Salty_Bone_Full"
    },
    {
      "x": 22,
      "y": 14,
      "z": -18,
      "name": "Deco_Salty_Bone_Full"
    },
    {
      "x": 22,
      "y": 15,
      "z": -18,
      "name": "Deco_Salty_Bone_Full"
    },
    {
      "x": 22,
      "y": 8,
      "z": -17,
      "name": "Deco_Salty_Bone_Full"
    },
    {
      "x": 22,
      "y": 9,
      "z": -17,
      "name": "Deco_Salty_Bone_Full"
    },
    {
      "x": 22,
      "y": 13,
      "z": -17,
      "name": "Deco_Salty_Bone_Full"
    },
    {
      "x": 22,
      "y": 14,
      "z": -17,
      "name": "Deco_Salty_Bone_Full"
    },
    {
      "x": 22,
      "y": 13,
      "z": -16,
      "name": "Deco_Salty_Bone_Full"
    },
    {
      "x": 23,
      "y": 14,
      "z": -23,
      "name": "Deco_Salty_Bone_Full"
    },
    {
      "x": 23,
      "y": 14,
      "z": -22,
      "name": "Deco_Salty_Bone_Full"
    },
    {
      "x": 23,
      "y": 15,
      "z": -22,
      "name": "Deco_Salty_Bone_Full"
    },
    {
      "x": 23,
      "y": 16,
      "z": -22,
      "name": "Deco_Salty_Bone_Spike"
    },
    {
      "x": 23,
      "y": 14,
      "z": -21,
      "name": "Deco_Salty_Bone_Full"
    },
    {
      "x": 23,
      "y": 13,
      "z": -17,
      "name": "Deco_Salty_Bone_Full"
    },
    {
      "x": 23,
      "y": 9,
      "z": -16,
      "name": "Deco_Salty_Bone_Full"
    },
    {
      "x": 23,
      "y": 10,
      "z": -16,
      "name": "Deco_Salty_Bone_Full"
    },
    {
      "x": 23,
      "y": 11,
      "z": -16,
      "name": "Deco_Salty_Bone_Full"
    },
    {
      "x": 23,
      "y": 12,
      "z": -16,
      "name": "Deco_Salty_Bone_Full"
    },
    {
      "x": 23,
      "y": 13,
      "z": -16,
      "name": "Deco_Salty_Bone_Full"
    },
    {
      "x": 24,
      "y": 13,
      "z": -24,
      "name": "Deco_Salty_Bone_Full"
    },
    {
      "x": 24,
      "y": 13,
      "z": -23,
      "name": "Deco_Salty_Bone_Full"
    },
    {
      "x": 24,
      "y": 14,
      "z": -23,
      "name": "Deco_Salty_Bone_Full"
    },
    {
      "x": 24,
      "y": 14,
      "z": -22,
      "name": "Deco_Salty_Bone_Full"
    },
    {
      "x": 25,
      "y": 13,
      "z": -25,
      "name": "Deco_Salty_Bone_Full"
    },
    {
      "x": 25,
      "y": 13,
      "z": -24,
      "name": "Deco_Salty_Bone_Full"
    },
    {
      "x": 25,
      "y": 14,
      "z": -24,
      "name": "Deco_Salty_Bone_Full"
    },
    {
      "x": 25,
      "y": 13,
      "z": -23,
      "name": "Deco_Salty_Bone_Full"
    },
    {
      "x": 26,
      "y": 13,
      "z": -25,
      "name": "Deco_Salty_Bone_Full"
    },
    {
      "x": 26,
      "y": 13,
      "z": -24,
      "name": "Deco_Salty_Bone_Full"
    }
  ]
}