{
  "version": 8,
  "blockIdVersion": 11,
  "anchorX": 0,
  "anchorY": 2,
  "anchorZ": 0,
  "blocks": [
    {
      "x": -2,
      "y": -2,
      "z": 0,
      "name": "Rock_Calcite_Cobble"
    },
    {
      "x": -2,
      "y": -1,
      "z": 0,
      "name": "Rock_Calcite_Cobble"
    },
    {
      "x": -2,
      "y": 0,
      "z": 0,
      "name": "Rock_Calcite_Cobble"
    },
    {
      "x": -2,
      "y": 1,
      "z": 0,
      "name": "Rock_Calcite_Cobble"
    },
    {
      "x": -2,
      "y": 2,
      "z": 0,
      "name": "Rock_Calcite_Brick_Decorative"
    },
    {
      "x": -2,
      "y": 3,
      "z": 0,
      "name": "Rock_Calcite_Brick"
    },
    {
      "x": -2,
      "y": 4,
      "z": 0,
      "name": "Rock_Calcite_Brick"
    },
    {
      "x": -2,
      "y": 5,
      "z": 0,
      "name": "Rock_Calcite_Brick_Half",
      "rotation": 7
    },
    {
      "x": -2,
      "y": -2,
      "z": 1,
      "name": "Rock_Calcite_Cobble"
    },
    {
      "x": -2,
      "y": -1,
      "z": 1,
      "name": "Rock_Calcite_Cobble"
    },
    {
      "x": -2,
      "y": 0,
      "z": 1,
      "name": "Rock_Calcite_Cobble"
    },
    {
      "x": -2,
      "y": 1,
      "z": 1,
      "name": "Rock_Calcite_Cobble"
    },
    {
      "x": -2,
      "y": 2,
      "z": 1,
      "name": "Rock_Calcite_Brick_Decorative"
    },
    {
      "x": -2,
      "y": 3,
      "z": 1,
      "name": "Rock_Calcite_Brick"
    },
    {
      "x": -2,
      "y": 4,
      "z": 1,
      "name": "Rock_Calcite_Brick"
    },
    {
      "x": -2,
      "y": 5,
      "z": 1,
      "name": "Rock_Calcite_Brick_Half"
    },
    {
      "x": -1,
      "y": -2,
      "z": 0,
      "name": "Rock_Calcite_Cobble"
    },
    {
      "x": -1,
      "y": -1,
      "z": 0,
      "name": "Rock_Calcite_Cobble"
    },
    {
      "x": -1,
      "y": 0,
      "z": 0,
      "name": "Rock_Calcite_Cobble"
    },
    {
      "x": -1,
      "y": 1,
      "z": 0,
      "name": "Rock_Calcite_Cobble"
    },
    {
      "x": -1,
      "y": 2,
      "z": 0,
      "name": "Rock_Calcite_Brick_Decorative"
    },
    {
      "x": -1,
      "y": 3,
      "z": 0,
      "name": "Rock_Calcite_Brick"
    },
    {
      "x": -1,
      "y": 4,
      "z": 0,
      "name": "Rock_Calcite_Brick"
    },
    {
      "x": -1,
      "y": 5,
      "z": 0,
      "name": "Rock_Calcite_Brick"
    },
    {
      "x": -1,
      "y": 6,
      "z": 0,
      "name": "Rock_Calcite_Brick_Pillar_Base"
    },
    {
      "x": -1,
      "y": -2,
      "z": 1,
      "name": "Rock_Calcite_Cobble"
    },
    {
      "x": -1,
      "y": -1,
      "z": 1,
      "name": "Rock_Calcite_Cobble"
    },
    {
      "x": -1,
      "y": 0,
      "z": 1,
      "name": "Rock_Calcite_Cobble"
    },
    {
      "x": -1,
      "y": 1,
      "z": 1,
      "name": "Rock_Calcite_Cobble"
    },
    {
      "x": -1,
      "y": 2,
      "z": 1,
      "name": "Rock_Calcite_Brick_Decorative"
    },
    {
      "x": -1,
      "y": 3,
      "z": 1,
      "name": "Rock_Calcite_Brick"
    },
    {
      "x": -1,
      "y": 4,
      "z": 1,
      "name": "Rock_Calcite_Brick"
    },
    {
      "x": -1,
      "y": 5,
      "z": 1,
      "name": "Rock_Calcite_Brick_Half",
      "rotation": 4
    },
    {
      "x": 1,
      "y": -2,
      "z": -1,
      "name": "Rock_Calcite_Cobble"
    },
    {
      "x": 1,
      "y": -1,
      "z": -1,
      "name": "Rock_Calcite_Cobble"
    },
    {
      "x": 1,
      "y": 0,
      "z": -1,
      "name": "Rock_Calcite_Cobble"
    },
    {
      "x": 1,
      "y": 1,
      "z": -1,
      "name": "Rock_Calcite_Cobble"
    },
    {
      "x": 1,
      "y": 2,
      "z": -1,
      "name": "Rock_Calcite_Brick_Decorative"
    },
    {
      "x": 1,
      "y": 3,
      "z": -1,
      "name": "Rock_Calcite_Brick_Smooth"
    },
    {
      "x": 1,
      "y": 4,
      "z": -1,
      "name": "Rock_Calcite_Brick_Smooth"
    },
    {
      "x": 1,
      "y": 5,
      "z": -1,
      "name": "Rock_Calcite_Brick_Smooth"
    },
    {
      "x": 1,
      "y": 6,
      "z": -1,
      "name": "Rock_Calcite_Brick_Pillar_Base"
    },
    {
      "x": 1,
      "y": -2,
      "z": 0,
      "name": "Rock_Calcite_Cobble"
    },
    {
      "x": 1,
      "y": -1,
      "z": 0,
      "name": "Rock_Calcite_Cobble"
    },
    {
      "x": 1,
      "y": 0,
      "z": 0,
      "name": "Rock_Calcite_Cobble"
    },
    {
      "x": 1,
      "y": 1,
      "z": 0,
      "name": "Rock_Calcite_Cobble"
    },
    {
      "x": 1,
      "y": 2,
      "z": 0,
      "name": "Rock_Calcite_Brick_Decorative"
    },
    {
      "x": 1,
      "y": 3,
      "z": 0,
      "name": "Rock_Calcite_Brick_Smooth"
    },
    {
      "x": 1,
      "y": 4,
      "z": 0,
      "name": "Rock_Calcite_Brick_Smooth"
    },
    {
      "x": 1,
      "y": 5,
      "z": 0,
      "name": "Rock_Calcite_Brick_Smooth"
    },
    {
      "x": 1,
      "y": 6,
      "z": 0,
      "name": "Rock_Calcite_Brick_Smooth"
    },
    {
      "x": 1,
      "y": 7,
      "z": 0,
      "name": "Rock_Calcite_Brick_Smooth_Half"
    },
    {
      "x": 2,
      "y": -2,
      "z": -1,
      "name": "Rock_Calcite_Cobble"
    },
    {
      "x": 2,
      "y": -1,
      "z": -1,
      "name": "Rock_Calcite_Cobble"
    },
    {
      "x": 2,
      "y": 0,
      "z": -1,
      "name": "Rock_Calcite_Cobble"
    },
    {
      "x": 2,
      "y": 1,
      "z": -1,
      "name": "Rock_Calcite_Cobble"
    },
    {
      "x": 2,
      "y": 2,
      "z": -1,
      "name": "Rock_Calcite_Brick_Decorative"
    },
    {
      "x": 2,
      "y": 3,
      "z": -1,
      "name": "Rock_Calcite_Brick_Smooth"
    },
    {
      "x": 2,
      "y": 4,
      "z": -1,
      "name": "Rock_Calcite_Brick_Smooth"
    },
    {
      "x": 2,
      "y": 5,
      "z": -1,
      "name": "Rock_Calcite_Brick_Smooth"
    },
    {
      "x": 2,
      "y": 6,
      "z": -1,
      "name": "Rock_Calcite_Brick_Smooth_Half"
    },
    {
      "x": 2,
      "y": -2,
      "z": 0,
      "name": "Rock_Calcite_Cobble"
    },
    {
      "x": 2,
      "y": -1,
      "z": 0,
      "name": "Rock_Calcite_Cobble"
    },
    {
      "x": 2,
      "y": 0,
      "z": 0,
      "name": "Rock_Calcite_Cobble"
    },
    {
      "x": 2,
      "y": 1,
      "z": 0,
      "name": "Rock_Calcite_Cobble"
    },
    {
      "x": 2,
      "y": 2,
      "z": 0,
      "name": "Rock_Calcite_Brick_Decorative"
    },
    {
      "x": 2,
      "y": 3,
      "z": 0,
      "name": "Rock_Calcite_Brick_Smooth"
    },
    {
      "x": 2,
      "y": 4,
      "z": 0,
      "name": "Rock_Calcite_Brick_Smooth"
    },
    {
      "x": 2,
      "y": 5,
      "z": 0,
      "name": "Rock_Calcite_Brick_Smooth_Half",
      "rotation": 4
    }
  ]
}